Workbook

Sheet Instrucciones
A1: Herramienta de elegibilidad y priorización de proyectos – FEAC BCS
A2: Fondo Estatal Ambiental y Climático de Baja California Sur · aplica el documento «Criterios de elegibilidad y selección de proyectos – FEAC BCS».
A4: Qué es el artículo 4
A5: El artículo 4 del Decreto por el que se constituye el Fideicomiso Público denominado Fondo Estatal Ambiental y Climático de Baja California Sur establece los fines del Fondo: 16 fracciones (I a XVI) que definen en qué puede invertir sus recursos. En esta herramienta, «fines del Fondo», «temas» y «fracciones del art. 4 del Decreto» significan lo mismo.
A7: Pasos de uso
A8: 1. Parámetros: el Comité Técnico fija pesos, montos mínimo y máximo, umbrales y categorías antes de cada convocatoria.
A9: 2. 1_Proyectos: registre cada propuesta (una fila por proyecto) con su fracción principal (el fin del Fondo que atiende, según el art. 4 del Decreto) y hasta 3 fracciones secundarias.
A10: 3. 2_Evaluación: en la misma fila, capture los 9 filtros (Sí/No) y, si el proyecto es elegible, las 14 calificaciones manuales (1 a 3). O4 y F5 se calculan solos.
A11: 4. 3_Ranking ordena la cartera; 4_Ficha genera la ficha individual de un proyecto para el expediente y la retroalimentación.
A13: Reglas de cálculo
A14: • Etapa 1 · Elegibilidad: 9 filtros. Un solo «No» = No elegible (se registra cuál). Si falta alguno y no hay «No» = Pendiente.
A15: • Etapa 2 · Calificación: 16 criterios en escala 1 (bajo) a 3 (alto). Puntaje bruto de 16 a 48.
... A25: Decreto del Fondo Estatal Ambiental y Climático de BCS (versión 1), arts. 3, 4, 5, 9, 14, 16 y 17. Estructura adaptada del Sistema de Priorización de SbN (Forest Trends, versión consolidada sept. 2026), ampliada a los 16 fines del art. 4.

Sheet Criterios
A1: Catálogo de criterios y rúbricas
A2: 9 filtros (Sí/No) y 16 criterios de calificación (1–3). En los filtros, la columna «3 / Sí» es la condición de cumplimiento y «1 / No» la de incumplimiento.
A4: Código | B4: Grupo | C4: Tipo | D4: Criterio | E4: Pregunta orientadora | F4: 3 · Alto / Sí | G4: 2 · Medio | H4: 1 · Bajo / No | I4: Medios de verificación | J4: Fundamento
A5: O1 | B5: Objetivos | C5: Filtro | D5: Alineación a planeación y respaldo institucional | E5: ¿Se alinea con la política climática estatal y con al menos un instrumento de planeación vigente, y lo respalda la autoridad competente? | F5: Sí: cita el instrumento y la línea u objetivo con que se alinea (Plan Estatal de Desarrollo 2021–2027, programa estatal de cambio climático, ordenamiento ecológico, programa de manejo, plan municipal) y presenta carta de apoyo de la autoridad con atribuciones para autorizar su implementación. | H5: No: no identifica un instrumento, la alineación es solo declarativa o no tiene respaldo de la autoridad competente. | I5: Cita del instrumento y de la línea; carta de apoyo de la autoridad competente. | J5: Arts. 3 y 4 (último párrafo)
A6: O2 | B6: Objetivos | C6: Filtro | D6: Vinculación directa con un fin del Fondo (art. 4 del Decreto) | E6: ¿El objetivo general del proyecto atiende de forma directa al menos un fin del Fondo (una fracción del art. 4 del Decreto)? | F6: Sí: registra una fracción principal y su objetivo general la atiende de forma directa. | H6: No: el beneficio ambiental o climático es solo colateral o indirecto. | I6: Marco lógico; fracción principal registrada en 1_Proyectos. | J6: Art. 4
A7: O3 | B7: Objetivos | C7: Filtro | D7: Requisito específico del tema | E7: ¿Cumple el requisito específico de su fracción principal (hoja Temas)? | F7: Sí: cumple el requisito de su fracción y lo acredita. | H7: No: no lo cumple o no lo acredita. | I7: Según la hoja Temas. | J7: Arts. 4 y 14
A8: T1 | B8: Territorio | C8: Filtro | D8: Ubicación en BCS y certeza de tenencia | E8: ¿Se ejecuta en BCS, en un área delimitada y con certeza sobre la tenencia o el derecho de uso? | F8: Sí: área de influencia o polígono en BCS y, si hay intervención física, documentos de tenencia, anuencia o convenio. | H8: No: fuera de BCS, sin delimitar o sin certeza sobre la tenencia. | I8: Mapa o polígono; títulos, acuerdos ejidales o convenios con propietarios. | J8: Art. 3
A9: T2 | B9: Territorio | C9: Filtro | D9: Sin daño significativo y cumplimiento ambiental | E9: ¿Identifica sus posibles impactos negativos, define medidas y cuenta con los permisos o una ruta para obtenerlos? | F9: Sí: identifica impactos y medidas, y tiene las autorizaciones o un programa para obtenerlas. | H9: No: impactos significativos sin medidas o efectos adversos previsibles (p. ej., especies invasoras, afectación a terceros). | I9: Análisis de impactos; autorizaciones; manifestación de impacto ambiental cuando aplique. | J9: Art. 14 (viabilidad ambiental)
A10: F1 | B10: Finanzas y gestión | C10: Filtro | D10: Monto dentro del rango de la convocatoria | E10: ¿El monto solicitado está dentro del rango definido para la convocatoria? | F10: Sí: el monto está entre el mínimo y el máximo. | H10: No: el monto está por debajo del mínimo o por encima del máximo. | I10: Presupuesto; hoja Parámetros. | J10: Art. 9, fr. III
A11: F2 | B11: Finanzas y gestión | C11: Filtro | D11: Propuesta técnico-financiera completa | E11: ¿Presenta plan de trabajo, cronograma, presupuesto desglosado y justificación frente a alternativas? | F11: Sí: presenta los cuatro elementos, con análisis costo-beneficio o costo-efectividad frente a alternativas. | H11: No: falta alguno de los cuatro elementos. | I11: Documento técnico; presupuesto; cronograma; análisis de alternativas. | J11: Art. 14 (evaluación técnica y financiera)
A12: F3 | B12: Finanzas y gestión | C12: Filtro | D12: Proponente elegible y documentación | E12: ¿El proponente es elegible, tiene documentación legal y fiscal completa, no duplica apoyos ni pide recursos para acciones ya ejecutadas, y acepta las reglas de transparencia? | F12: Sí: documentación completa, declaración de no duplicidad de apoyos, el proyecto no está ya implementado y hay carta compromiso de informes trimestrales y publicidad de datos. | H12: No: falta alguno de esos documentos o el proyecto ya está implementado. | I12: Acta constitutiva o nombramiento; RFC; opinión de cumplimiento fiscal; declaraciones firmadas. | J12: Arts. 5, 16 y 17
A13: E1 | B13: Evidencia | C13: Filtro | D13: Beneficio cuantificable | E13: ¿Define al menos un indicador de su fracción con unidad, línea base y meta? | F13: Sí: al menos un indicador con unidad, línea base (o método para establecerla) y meta. | H13: No: los beneficios se describen solo de forma cualitativa. | I13: Tabla de indicadores y metas; memoria de cálculo. | J13: Art. 4 (impacto)
A14: O4 | B14: Objetivos | C14: Calificación (automática) | D14: Contribución a varios fines del Fondo (art. 4 del Decreto) | E14: ¿A cuántos fines del Fondo (fracciones del art. 4 del Decreto) contribuye el proyecto? | F14: 3: contribuye a 3 o más fracciones. | G14: 2: contribuye a 2 fracciones. | H14: 1: contribuye a 1 fracción. | I14: Se calcula con las fracciones registradas en 1_Proyectos. | J14: Art. 4
A15: O5 | B15: Objetivos | C15: Calificación | D15: Magnitud del impacto | E15: ¿Qué tan grande es el resultado esperado en el indicador de la fracción frente al problema que atiende? | F15: 3: Alto: resultado cuantificado que atiende una parte sustantiva del problema en su ámbito (cuenca, ecosistema, municipio) o es replicable en otras ciudades o regiones del Estado. | G15: 2: Medio: resultado cuantificado con alcance local o parcial. | H15: 1: Bajo: resultado marginal o demostrativo, sin ruta de escalamiento. | I15: Memoria de cálculo; diagnóstico del problema. | J15: Arts. 3 y 4
A16: T3 | B16: Territorio | C16: Calificación | D16: Territorios y población vulnerables | E16: ¿Atiende comunidades rurales, costeras, zonas de alto riesgo o grupos en situación de vulnerabilidad? | F16: 3: Alto: se ubica en zona de riesgo o vulnerabilidad documentada (atlas de riesgos, índices oficiales) y focaliza en ella. | G16: 2: Medio: atiende zonas o grupos vulnerables sin diagnóstico específico. | H16: 1: Bajo: no focaliza en zonas ni grupos vulnerables. | I16: Atlas de riesgos; índices de marginación o vulnerabilidad; diagnóstico. | J16: Art. 3; art. 4, fr. I
A17: T4 | B17: Territorio | C17: Calificación | D17: Riesgos y barreras de implementación | E17: ¿Analiza riesgos climáticos, efectos fuera del área de intervención y barreras legales, técnicas, financieras o sociales (incluida posible controversia), y define cómo gestionarlos? | F17: 3: Alto: riesgos y barreras a escala de cuenca, ecosistema o ciudad, con escenarios climáticos y medidas concretas; las barreras son manejables. | G17: 2: Medio: identifica riesgos y barreras con medidas generales o parciales; alguna barrera es difícil de superar. | H17: 1: Bajo: solo riesgos internos o ninguno, o hay barreras muy difíciles sin medidas. | I17: Matriz de riesgos y barreras; análisis de escenarios. | J17: Art. 4, fr. III
A18: F4 | B18: Finanzas y gestión | C18: Calificación | D18: Costo-efectividad | E18: ¿Cuánto cuesta cada unidad de resultado frente a alternativas o referencias? | F18: 3: Alto: calcula el costo por unidad de resultado y es igual o menor que el de alternativas o referencias. | G18: 2: Medio: calcula el costo por unidad sin compararlo, o compara solo de forma cualitativa. | H18: 1: Bajo: no calcula el costo por unidad de resultado. | I18: Análisis de costo-efectividad o costo-beneficio. | J18: Art. 14
A19: F5 | B19: Finanzas y gestión | C19: Calificación (automática) | D19: Cofinanciamiento | E19: ¿Qué parte del costo total aportan otras fuentes? | F19: 3: 30 % o más del costo total. | G19: 2: de 10 % a menos de 30 %. | H19: 1: menos de 10 %. | I19: Se calcula con los montos de 1_Proyectos; cartas de cofinanciamiento. | J19: Art. 5
A20: F6 | B20: Finanzas y gestión | C20: Calificación | D20: Sostenibilidad posterior | E20: ¿Tiene un mecanismo para sostenerse cuando termine el apoyo del Fondo? | F20: 3: Alto: mecanismo comprometido (presupuesto institucional, ingresos propios, pago por servicios ambientales, acuerdo de mantenimiento). | G20: 2: Medio: opciones plausibles sin compromiso formal. | H20: 1: Bajo: depende totalmente del Fondo. | I20: Cartas compromiso; plan de sostenibilidad; acuerdos de mantenimiento. | J20: Art. 3
A21: F7 | B21: Finanzas y gestión | C21: Calificación | D21: Capacidad de ejecución del proponente | E21: ¿El proponente tiene experiencia y equipo para ejecutar el proyecto? | F21: 3: Alto: ejecutó proyectos similares de monto comparable y presenta equipo con perfiles definidos. | G21: 2: Medio: experiencia en proyectos menores o equipo incompleto. | H21: 1: Bajo: sin experiencia demostrable. | I21: Currículos; contratos o informes de proyectos previos. | J21: Art. 14
A22: F8 | B22: Finanzas y gestión | C22: Calificación | D22: Madurez del proyecto | E22: ¿En qué etapa de desarrollo está el proyecto? | F22: 3: Alto: proyecto ejecutivo con autorizaciones obtenidas o en trámite avanzado. | G22: 2: Medio: anteproyecto con alcances, costos y ubicación definidos. | H22: 1: Bajo: idea acotada, sin anteproyecto. | I22: Proyecto ejecutivo o anteproyecto; autorizaciones. | J22: Art. 14
A23: E2 | B23: Evidencia | C23: Calificación | D23: Evidencia de los beneficios | E23: ¿Qué tan sólida es la evidencia de los beneficios esperados? | F23: 3: Alto: datos locales, estudios, monitoreo previo o modelación verificable. | G23: 2: Medio: literatura o experiencias análogas en contextos comparables. | H23: 1: Bajo: supuestos generales sin evidencia. | I23: Estudios; datos de monitoreo; modelación; referencias. | J23: Art. 14
A24: E3 | B24: Evidencia | C24: Calificación | D24: Plan de monitoreo y evaluación | E24: ¿Tiene un plan para reportar avances frente a indicadores y metas? | F24: 3: Alto: indicadores SMART, línea base, metas, frecuencia, responsables y presupuesto asignado. | G24: 2: Medio: indicadores y metas, pero sin línea base o sin presupuesto. | H24: 1: Bajo: solo indicadores de actividad. | I24: Plan de monitoreo y evaluación; presupuesto de monitoreo. | J24: Art. 16
A25: E4 | B25: Evidencia | C25: Calificación | D25: Colaboración con academia o investigación | E25: ¿Involucra a instituciones académicas o de investigación con un rol definido? | F25: 3: Alto: convenio o carta compromiso con rol técnico definido. | G25: 2: Medio: colaboración propuesta o informal. | H25: 1: Bajo: sin colaboración. | I25: Convenios o cartas compromiso. | J25: Art. 4, fr. XI
... A29: V4 | B29: Valores | C29: Calificación | D29: Alianzas multisectoriales | E29: ¿Articula alianzas con distintos sectores (público, privado, social, académico)? | F29: 3: Alto: alianzas formales con dos o más sectores, con roles y aportes definidos. | G29: 2: Medio: alianzas con un solo sector o informales. | H29: 1: Bajo: sin alianzas. | I29: Cartas de alianza; aportes comprometidos. | J29: Art. 7 (integración multisectorial)

Sheet Temas
A1: Temas financiables: los 16 fines del Fondo (art. 4 del Decreto) y sus criterios específicos
A2: El artículo 4 del Decreto por el que se constituye el Fideicomiso Público denominado Fondo Estatal Ambiental y Climático de Baja California Sur establece los fines del Fondo: 16 fracciones (I a XVI) que definen en qué puede invertir sus recursos. En esta herramienta, «fines del Fondo», «temas» y «fracciones del art. 4 del Decreto» significan lo mismo. El requisito específico se verifica en el filtro O3; el indicador de impacto se usa en E1 y O5.
A4: Fracción | B4: Línea temática | C4: Tema | D4: Requisito específico de elegibilidad (O3) | E4: Indicador de impacto (E1 y O5)
A5: I | B5: A. Adaptación y resiliencia | C5: Adaptación y reducción de vulnerabilidad | D5: Se ubica en comunidad rural, costera o zona de alto riesgo, o atiende a un grupo vulnerable; parte de un diagnóstico de vulnerabilidad o atlas de riesgos | E5: Personas u hogares con vulnerabilidad reducida
A6: II | B6: C. Mitigación y transición energética | C6: Mitigación de emisiones | D6: Presenta línea base de emisiones y método de cálculo de la reducción | E6: tCO2e reducidas o evitadas por año
A7: III | B7: A. Adaptación y resiliencia | C7: Resiliencia territorial e infraestructura resiliente | D7: Incorpora escenarios climáticos o de riesgo en el diseño; si es obra, tiene proyecto ejecutivo o ruta para obtenerlo | E7: Población y activos protegidos
A8: IV | B8: B. Capital natural y biodiversidad | C8: Conservación y restauración de capital natural | D8: Superficie delimitada, tenencia acreditada y acuerdo con propietarios o núcleos agrarios; en un área natural protegida, alineado a su programa de manejo | E8: Hectáreas conservadas o restauradas
A9: V | B9: B. Capital natural y biodiversidad | C9: Restauración ecológica, reforestación y corredores | D9: Usa especies nativas e incluye mantenimiento y monitoreo de sobrevivencia por al menos 3 años | E9: Hectáreas restauradas, % de sobrevivencia, km de corredor
A10: VI | B10: C. Mitigación y transición energética | C10: Transición energética | D10: Diagnóstico energético o estudio de recurso; cumple la normatividad de interconexión cuando aplica | E10: MWh ahorrados o generados por año; hogares electrificados
A11: VII | B11: C. Mitigación y transición energética | C11: Electromovilidad y tecnologías limpias | D11: Beneficio público (transporte público, escuelas, hospitales, edificios públicos o vivienda social) y análisis de costo total de propiedad | E11: tCO2e evitadas; unidades o inmuebles intervenidos
A12: VIII | B12: D. Calidad ambiental urbana y residuos | C12: Calidad del aire y movilidad sustentable | D12: Se basa en datos de calidad del aire o diagnóstico de movilidad; los equipos de monitoreo cumplen la NOM aplicable | E12: Contaminantes criterio reducidos; estaciones o km de infraestructura
A13: IX | B13: D. Calidad ambiental urbana y residuos | C13: Residuos y economía circular | D13: Es congruente con el programa municipal o estatal de residuos y tiene destino final autorizado | E13: Toneladas desviadas de disposición final por año
A14: X | B14: E. Conocimiento, educación e instituciones | C14: Educación ambiental y cultura climática | D14: Define población objetivo, contenidos y una evaluación antes y después | E14: Personas con aprendizaje verificado
A15: XI | B15: E. Conocimiento, educación e instituciones | C15: Investigación, innovación y tecnología | D15: La ejecuta una institución de investigación o una alianza con ella; muestra la ruta de aplicación en BCS | E15: Tecnologías transferidas, prototipos o productos aplicados
... A20: XVI | B20: F. Acciones estratégicas | C20: Acciones estratégicas | D20: Acuerdo de la Comisión Intersectorial de Cambio Climático que la determine | E20: El que fije el acuerdo

Sheet Parámetros
A1: Parámetros del sistema
A2: Celdas amarillas editables por el Comité Técnico antes de cada convocatoria. No se modifican durante una convocatoria.
A4: 1. Pesos de los criterios de calificación
A5: Código | B5: Grupo | C5: Criterio | D5: Peso | E5: Peso relativo
A6: O4 | B6: Objetivos | C6: Contribución a varios fines del Fondo (art. 4 del Decreto) | D6: 1 | E6: =IFERROR(D6/SUM($D$6:$D$21),0) -> 0.055555556
A7: O5 | B7: Objetivos | C7: Magnitud del impacto | D7: 2 | E7: =IFERROR(D7/SUM($D$6:$D$21),0) -> 0.11111111
A8: T3 | B8: Territorio | C8: Territorios y población vulnerables | D8: 2 | E8: =IFERROR(D8/SUM($D$6:$D$21),0) -> 0.11111111
A9: T4 | B9: Territorio | C9: Riesgos y barreras de implementación | D9: 1 | E9: =IFERROR(D9/SUM($D$6:$D$21),0) -> 0.055555556
A10: F4 | B10: Finanzas y gestión | C10: Costo-efectividad | D10: 1 | E10: =IFERROR(D10/SUM($D$6:$D$21),0) -> 0.055555556
A11: F5 | B11: Finanzas y gestión | C11: Cofinanciamiento | D11: 1 | E11: =IFERROR(D11/SUM($D$6:$D$21),0) -> 0.055555556
A12: F6 | B12: Finanzas y gestión | C12: Sostenibilidad posterior | D12: 1 | E12: =IFERROR(D12/SUM($D$6:$D$21),0) -> 0.055555556
A13: F7 | B13: Finanzas y gestión | C13: Capacidad de ejecución del proponente | D13: 1 | E13: =IFERROR(D13/SUM($D$6:$D$21),0) -> 0.055555556
A14: F8 | B14: Finanzas y gestión | C14: Madurez del proyecto | D14: 1 | E14: =IFERROR(D14/SUM($D$6:$D$21),0) -> 0.055555556
A15: E2 | B15: Evidencia | C15: Evidencia de los beneficios | D15: 1 | E15: =IFERROR(D15/SUM($D$6:$D$21),0) -> 0.055555556
A16: E3 | B16: Evidencia | C16: Plan de monitoreo y evaluación | D16: 1 | E16: =IFERROR(D16/SUM($D$6:$D$21),0) -> 0.055555556
A17: E4 | B17: Evidencia | C17: Colaboración con academia o investigación | D17: 1 | E17: =IFERROR(D17/SUM($D$6:$D$21),0) -> 0.055555556
... A21: V4 | B21: Valores | C21: Alianzas multisectoriales | D21: 1 | E21: =IFERROR(D21/SUM($D$6:$D$21),0) -> 0.055555556
C22: Total | D22: =SUM(D6:D21) -> 18 | E22: =SUM(E6:E21) -> 1
A23: Peso 2 duplica la influencia de un criterio; peso 0 lo excluye del índice (sigue en el puntaje bruto). Por defecto, O5 y T3 pesan 2 por la «especial atención» a impacto y vulnerabilidad del art. 3.
A25: 2. Peso efectivo por grupo
A26: Grupo | C26: N.º de criterios | D26: Peso efectivo
A27: Objetivos | C27: =COUNTIF($B$6:$B$21,A27) -> 2 | D27: =IFERROR(SUMIF($B$6:$B$21,A27,$D$6:$D$21)/$D$22,0) -> 0.16666667
A28: Territorio | C28: =COUNTIF($B$6:$B$21,A28) -> 2 | D28: =IFERROR(SUMIF($B$6:$B$21,A28,$D$6:$D$21)/$D$22,0) -> 0.16666667
A29: Finanzas y gestión | C29: =COUNTIF($B$6:$B$21,A29) -> 5 | D29: =IFERROR(SUMIF($B$6:$B$21,A29,$D$6:$D$21)/$D$22,0) -> 0.27777778
A30: Evidencia | C30: =COUNTIF($B$6:$B$21,A30) -> 3 | D30: =IFERROR(SUMIF($B$6:$B$21,A30,$D$6:$D$21)/$D$22,0) -> 0.16666667
A31: Valores | C31: =COUNTIF($B$6:$B$21,A31) -> 4 | D31: =IFERROR(SUMIF($B$6:$B$21,A31,$D$6:$D$21)/$D$22,0) -> 0.22222222
A33: 3. Umbrales y reglas
A34: Parámetro | D34: Valor
A35: Monto mínimo por proyecto (MXN), criterio F1. Vacío si no está definido.
A36: Monto máximo por proyecto (MXN), criterio F1. Vacío si no está definido.
A37: O4: número de fracciones para 3 puntos. | D37: 3
A38: O4: número de fracciones para 2 puntos. | D38: 2
A39: F5: cofinanciamiento mínimo para 3 puntos. | D39: 0.3
A40: F5: cofinanciamiento mínimo para 2 puntos. | D40: 0.1
A41: Índice mínimo para prioridad ALTA (referencial). | D41: 75
A42: Índice mínimo para prioridad MEDIA (por debajo: BAJA). | D42: 50
A44: 4. Tipos de proponente (lista)
A45: Público - dependencia estatal
A46: Público - municipio
A47: Público - paraestatal
...

Sheet 1_Proyectos
A1: 1. Registro de proyectos
A2: Una fila por proyecto (filas 9 a 58). La fila de cada proyecto es la misma en 2_Evaluación. Las fracciones son los fines del Fondo del art. 4 del Decreto (hoja Temas).
A8: ID | B8: Proyecto | C8: Proponente (entidad líder) | D8: Tipo de proponente | E8: Municipio(s) | F8: Fracción principal | G8: Fracción secundaria 1 | H8: Fracción secundaria 2 | I8: Fracción secundaria 3 | J8: Línea temática | K8: N.º de fracciones | L8: Monto solicitado (MXN) | M8: Costo total del proyecto (MXN) | N8: Cofinanciamiento (%) | O8: Indicador principal (unidad) | P8: Línea base | Q8: Meta | R8: Evaluador(es) | S8: Fecha de evaluación
A9: EJ-01 | B9: Restauración de manglar y humedal costero (ejemplo) | C9: OSC local (ejemplo) | D9: Privado - OSC | E9: La Paz | F9: IV | G9: V | H9: I | J9: =IF(F9="","",IFERROR(INDEX(Temas!$B$5:$B$20,MATCH(F9,Temas!$A$5:$A$20,0)),"Fracción no válida")) -> B. Capital natural y biodiversidad | K9: =IF(F9="","",1+(G9<>"")*(G9<>F9)+(H9<>"")*(H9<>F9)*(H9<>G9)+(I9<>"")*(I9<>F9)*(I9<>G9)*(I9<>H9)) -> 3 | L9: 2500000 | M9: 3600000 | N9: =IF(OR(L9="",M9="",N(M9)=0),"",MAX(0,1-L9/M9)) -> 0.30555556 | O9: Hectáreas restauradas | P9: 0 ha | Q9: 45 ha | R9: Evaluador 1 y 2 (ejemplo)
A10: EJ-02 | B10: Sistemas fotovoltaicos en escuelas rurales (ejemplo) | C10: Dependencia estatal (ejemplo) | D10: Público - dependencia estatal | E10: Comondú | F10: VI | G10: VII | J10: =IF(F10="","",IFERROR(INDEX(Temas!$B$5:$B$20,MATCH(F10,Temas!$A$5:$A$20,0)),"Fracción no válida")) -> C. Mitigación y transición energética | K10: =IF(F10="","",1+(G10<>"")*(G10<>F10)+(H10<>"")*(H10<>F10)*(H10<>G10)+(I10<>"")*(I10<>F10)*(I10<>G10)*(I10<>H10)) -> 2 | L10: 4000000 | M10: 4400000 | N10: =IF(OR(L10="",M10="",N(M10)=0),"",MAX(0,1-L10/M10)) -> 0.090909091 | O10: MWh generados por año | P10: 0 MWh | Q10: 520 MWh/año | R10: Evaluador 1 y 2 (ejemplo)
A11: EJ-03 | B11: Campaña de cultura climática en redes sociales (ejemplo) | C11: OSC (ejemplo) | D11: Privado - OSC | E11: Los Cabos | F11: X | J11: =IF(F11="","",IFERROR(INDEX(Temas!$B$5:$B$20,MATCH(F11,Temas!$A$5:$A$20,0)),"Fracción no válida")) -> E. Conocimiento, educación e instituciones | K11: =IF(F11="","",1+(G11<>"")*(G11<>F11)+(H11<>"")*(H11<>F11)*(H11<>G11)+(I11<>"")*(I11<>F11)*(I11<>G11)*(I11<>H11)) -> 1 | L11: 600000 | M11: 600000 | N11: =IF(OR(L11="",M11="",N(M11)=0),"",MAX(0,1-L11/M11)) -> 0 | R11: Evaluador 1 y 2 (ejemplo)
A12: EJ-04 | B12: Planta municipal de compostaje (ejemplo) | C12: Municipio (ejemplo) | D12: Público - municipio | E12: Mulegé | F12: IX | G12: II | J12: =IF(F12="","",IFERROR(INDEX(Temas!$B$5:$B$20,MATCH(F12,Temas!$A$5:$A$20,0)),"Fracción no válida")) -> D. Calidad ambiental urbana y residuos | K12: =IF(F12="","",1+(G12<>"")*(G12<>F12)+(H12<>"")*(H12<>F12)*(H12<>G12)+(I12<>"")*(I12<>F12)*(I12<>G12)*(I12<>H12)) -> 2 | L12: 3000000 | M12: 5000000 | N12: =IF(OR(L12="",M12="",N(M12)=0),"",MAX(0,1-L12/M12)) -> 0.4 | O12: Toneladas desviadas por año | P12: 0 t | Q12: 1,800 t/año | R12: Evaluador 1 y 2 (ejemplo)
J13: =IF(F13="","",IFERROR(INDEX(Temas!$B$5:$B$20,MATCH(F13,Temas!$A$5:$A$20,0)),"Fracción no válida")) | K13: =IF(F13="","",1+(G13<>"")*(G13<>F13)+(H13<>"")*(H13<>F13)*(H13<>G13)+(I13<>"")*(I13<>F13)*(I13<>G13)*(I13<>H13)) | N13: =IF(OR(L13="",M13="",N(M13)=0),"",MAX(0,1-L13/M13))
J14: =IF(F14="","",IFERROR(INDEX(Temas!$B$5:$B$20,MATCH(F14,Temas!$A$5:$A$20,0)),"Fracción no válida")) | K14: =IF(F14="","",1+(G14<>"")*(G14<>F14)+(H14<>"")*(H14<>F14)*(H14<>G14)+(I14<>"")*(I14<>F14)*(I14<>G14)*(I14<>H14)) | N14: =IF(OR(L14="",M14="",N(M14)=0),"",MAX(0,1-L14/M14))
J15: =IF(F15="","",IFERROR(INDEX(Temas!$B$5:$B$20,MATCH(F15,Temas!$A$5:$A$20,0)),"Fracción no válida")) | K15: =IF(F15="","",1+(G15<>"")*(G15<>F15)+(H15<>"")*(H15<>F15)*(H15<>G15)+(I15<>"")*(I15<>F15)*(I15<>G15)*(I15<>H15)) | N15: =IF(OR(L15="",M15="",N(M15)=0),"",MAX(0,1-L15/M15))
J16: =IF(F16="","",IFERROR(INDEX(Temas!$B$5:$B$20,MATCH(F16,Temas!$A$5:$A$20,0)),"Fracción no válida")) | K16: =IF(F16="","",1+(G16<>"")*(G16<>F16)+(H16<>"")*(H16<>F16)*(H16<>G16)+(I16<>"")*(I16<>F16)*(I16<>G16)*(I16<>H16)) | N16: =IF(OR(L16="",M16="",N(M16)=0),"",MAX(0,1-L16/M16))
J17: =IF(F17="","",IFERROR(INDEX(Temas!$B$5:$B$20,MATCH(F17,Temas!$A$5:$A$20,0)),"Fracción no válida")) | K17: =IF(F17="","",1+(G17<>"")*(G17<>F17)+(H17<>"")*(H17<>F17)*(H17<>G17)+(I17<>"")*(I17<>F17)*(I17<>G17)*(I17<>H17)) | N17: =IF(OR(L17="",M17="",N(M17)=0),"",MAX(0,1-L17/M17))
J18: =IF(F18="","",IFERROR(INDEX(Temas!$B$5:$B$20,MATCH(F18,Temas!$A$5:$A$20,0)),"Fracción no válida")) | K18: =IF(F18="","",1+(G18<>"")*(G18<>F18)+(H18<>"")*(H18<>F18)*(H18<>G18)+(I18<>"")*(I18<>F18)*(I18<>G18)*(I18<>H18)) | N18: =IF(OR(L18="",M18="",N(M18)=0),"",MAX(0,1-L18/M18))
J19: =IF(F19="","",IFERROR(INDEX(Temas!$B$5:$B$20,MATCH(F19,Temas!$A$5:$A$20,0)),"Fracción no válida")) | K19: =IF(F19="","",1+(G19<>"")*(G19<>F19)+(H19<>"")*(H19<>F19)*(H19<>G19)+(I19<>"")*(I19<>F19)*(I19<>G19)*(I19<>H19)) | N19: =IF(OR(L19="",M19="",N(M19)=0),"",MAX(0,1-L19/M19))
J20: =IF(F20="","",IFERROR(INDEX(Temas!$B$5:$B$20,MATCH(F20,Temas!$A$5:$A$20,0)),"Fracción no válida")) | K20: =IF(F20="","",1+(G20<>"")*(G20<>F20)+(H20<>"")*(H20<>F20)*(H20<>G20)+(I20<>"")*(I20<>F20)*(I20<>G20)*(I20<>H20)) | N20: =IF(OR(L20="",M20="",N(M20)=0),"",MAX(0,1-L20/M20))
J21: =IF(F21="","",IFERROR(INDEX(Temas!$B$5:$B$20,MATCH(F21,Temas!$A$5:$A$20,0)),"Fracción no válida")) | K21: =IF(F21="","",1+(G21<>"")*(G21<>F21)+(H21<>"")*(H21<>F21)*(H21<>G21)+(I21<>"")*(I21<>F21)*(I21<>G21)*(I21<>H21)) | N21: =IF(OR(L21="",M21="",N(M21)=0),"",MAX(0,1-L21/M21))
J22: =IF(F22="","",IFERROR(INDEX(Temas!$B$5:$B$20,MATCH(F22,Temas!$A$5:$A$20,0)),"Fracción no válida")) | K22: =IF(F22="","",1+(G22<>"")*(G22<>F22)+(H22<>"")*(H22<>F22)*(H22<>G22)+(I22<>"")*(I22<>F22)*(I22<>G22)*(I22<>H22)) | N22: =IF(OR(L22="",M22="",N(M22)=0),"",MAX(0,1-L22/M22))
J23: =IF(F23="","",IFERROR(INDEX(Temas!$B$5:$B$20,MATCH(F23,Temas!$A$5:$A$20,0)),"Fracción no válida")) | K23: =IF(F23="","",1+(G23<>"")*(G23<>F23)+(H23<>"")*(H23<>F23)*(H23<>G23)+(I23<>"")*(I23<>F23)*(I23<>G23)*(I23<>H23)) | N23: =IF(OR(L23="",M23="",N(M23)=0),"",MAX(0,1-L23/M23))
J24: =IF(F24="","",IFERROR(INDEX(Temas!$B$5:$B$20,MATCH(F24,Temas!$A$5:$A$20,0)),"Fracción no válida")) | K24: =IF(F24="","",1+(G24<>"")*(G24<>F24)+(H24<>"")*(H24<>F24)*(H24<>G24)+(I24<>"")*(I24<>F24)*(I24<>G24)*(I24<>H24)) | N24: =IF(OR(L24="",M24="",N(M24)=0),"",MAX(0,1-L24/M24))
... J58: =IF(F58="","",IFERROR(INDEX(Temas!$B$5:$B$20,MATCH(F58,Temas!$A$5:$A$20,0)),"Fracción no válida")) | K58: =IF(F58="","",1+(G58<>"")*(G58<>F58)+(H58<>"")*(H58<>F58)*(H58<>G58)+(I58<>"")*(I58<>F58)*(I58<>G58)*(I58<>H58)) | N58: =IF(OR(L58="",M58="",N(M58)=0),"",MAX(0,1-L58/M58))

Sheet 2_Evaluación
A1: 2. Matriz de evaluación
A2: Filtros: Sí / No. Calificaciones: 1 (bajo), 2 (medio), 3 (alto) según la rúbrica de la hoja Criterios. O4 y F5 se calculan solos.
M3: Fila 8 = peso de cada criterio (viene de Parámetros)
D4: Etapa 1 · Filtros de elegibilidad (Sí / No) | M4: Etapa 2 · Calificación (1 · 2 · 3) | AC4: Resultados (cálculo automático)
A5: ID | B5: Proyecto | C5: Fracción principal | D5: O1 | E5: O2 | F5: O3 | G5: T1 | H5: T2 | I5: F1 | J5: F2 | K5: F3 | L5: E1 | M5: O4 | N5: O5 | O5: T3 | P5: T4 | Q5: F4 | R5: F5 | S5: F6 | T5: F7 | U5: F8 | V5: E2 | W5: E3 | X5: E4 | Y5: V1 | Z5: V2 | AA5: V3 | AB5: V4 | AC5: Filtros cumplidos (/9) | AD5: Elegibilidad | AE5: Filtros no cumplidos | AF5: Subtotal Objetivos | AG5: Subtotal Territorio | AH5: Subtotal Finanzas y gestión | AI5: Subtotal Evidencia | AJ5: Subtotal Valores | AK5: Puntaje bruto (/48) | AL5: Índice de prioridad (0–100) | AM5: Categoría de prioridad | AN5: Posición en ranking | AO5: Alertas de consistencia | AP5: Observaciones / justificación | AQ5: Aux: clave de orden | AR5: Aux: orden
D6: Alineación a planeación y respaldo institucional | E6: Vinculación directa con un fin del Fondo (art. 4 del Decreto) | F6: Requisito específico del tema | G6: Ubicación en BCS y certeza de tenencia | H6: Sin daño significativo y cumplimiento ambiental | I6: Monto dentro del rango de la convocatoria | J6: Propuesta técnico-financiera completa | K6: Proponente elegible y documentación | L6: Beneficio cuantificable | M6: Contribución a varios fines del Fondo (art. 4 del Decreto) | N6: Magnitud del impacto | O6: Territorios y población vulnerables | P6: Riesgos y barreras de implementación | Q6: Costo-efectividad | R6: Cofinanciamiento | S6: Sostenibilidad posterior | T6: Capacidad de ejecución del proponente | U6: Madurez del proyecto | V6: Evidencia de los beneficios | W6: Plan de monitoreo y evaluación | X6: Colaboración con academia o investigación | Y6: Personas beneficiadas y focalización social | Z6: Género e inclusión | AA6: Participación social | AB6: Alianzas multisectoriales
D7: Filtro Sí / No | E7: Filtro Sí / No | F7: Filtro Sí / No | G7: Filtro Sí / No | H7: Filtro Sí / No | I7: Filtro Sí / No | J7: Filtro Sí / No | K7: Filtro Sí / No | L7: Filtro Sí / No | M7: Automática | N7: 1 · 2 · 3 | O7: 1 · 2 · 3 | P7: 1 · 2 · 3 | Q7: 1 · 2 · 3 | R7: Automática | S7: 1 · 2 · 3 | T7: 1 · 2 · 3 | U7: 1 · 2 · 3 | V7: 1 · 2 · 3 | W7: 1 · 2 · 3 | X7: 1 · 2 · 3 | Y7: 1 · 2 · 3 | Z7: 1 · 2 · 3 | AA7: 1 · 2 · 3 | AB7: 1 · 2 · 3
D8: — | E8: — | F8: — | G8: — | H8: — | I8: — | J8: — | K8: — | L8: — | M8: =Parámetros!$D$6 -> 1 | N8: =Parámetros!$D$7 -> 2 | O8: =Parámetros!$D$8 -> 2 | P8: =Parámetros!$D$9 -> 1 | Q8: =Parámetros!$D$10 -> 1 | R8: =Parámetros!$D$11 -> 1 | S8: =Parámetros!$D$12 -> 1 | T8: =Parámetros!$D$13 -> 1 | U8: =Parámetros!$D$14 -> 1 | V8: =Parámetros!$D$15 -> 1 | W8: =Parámetros!$D$16 -> 1 | X8: =Parámetros!$D$17 -> 1 | Y8: =Parámetros!$D$18 -> 1 | Z8: =Parámetros!$D$19 -> 1 | AA8: =Parámetros!$D$20 -> 1 | AB8: =Parámetros!$D$21 -> 1
A9: =IF(1_Proyectos!A9="","",1_Proyectos!A9) -> EJ-01 | B9: =IF(1_Proyectos!B9="","",1_Proyectos!B9) -> Restauración de manglar y humedal costero (ejemplo) | C9: =IF(1_Proyectos!F9="","",1_Proyectos!F9) -> IV | D9: Sí | E9: Sí | F9: Sí | G9: Sí | H9: Sí | I9: Sí | J9: Sí | K9: Sí | L9: Sí | M9: =IF(1_Proyectos!K9="","",IF(1_Proyectos!K9>=Parámetros!$D$37,3,IF(1_Proyectos!K9>=Parámetros!$D$38,2,1))) -> 3 | N9: 3 | O9: 3 | P9: 2 | Q9: 2 | R9: =IF(1_Proyectos!N9="","",IF(1_Proyectos!N9>=Parámetros!$D$39,3,IF(1_Proyectos!N9>=Parámetros!$D$40,2,1))) -> 3 | S9: 2 | T9: 3 | U9: 3 | V9: 3 | W9: 3 | X9: 3 | Y9: 2 | Z9: 2 | AA9: 3 | AB9: 3 | AC9: =IF(A9="","",COUNTIF(D9:L9,"Sí")) -> 9 | AD9: =IF(A9="","",IF(COUNTIF(D9:L9,"No")>0,"No elegible",IF(COUNTIF(D9:L9,"Sí")=9,"Elegible","Pendiente"))) -> Elegible | AE9: =TRIM(IF(D9="No","O1 ","")&IF(E9="No","O2 ","")&IF(F9="No","O3 ","")&IF(G9="No","T1 ","")&IF(H9="No","T2 ","")&IF(I9="No","F1 ","")&IF(J9="No","F2 ","")&IF(K9="No","F3 ","")&IF(L9="No","E1 ","")) | AF9: =IF(AD9="Elegible",SUM(M9,N9),"") -> 6 | AG9: =IF(AD9="Elegible",SUM(O9,P9),"") -> 5 | AH9: =IF(AD9="Elegible",SUM(Q9,R9,S9,T9,U9),"") -> 13 | AI9: =IF(AD9="Elegible",SUM(V9,W9,X9),"") -> 9 | AJ9: =IF(AD9="Elegible",SUM(Y9,Z9,AA9,AB9),"") -> 10 | AK9: =IF(AND(AD9="Elegible",COUNT(M9:AB9)=16),SUM(M9:AB9),"") -> 43 | AL9: =IF(AK9="","",ROUND(SUMPRODUCT($M$8:$AB$8,M9:AB9)/(3*SUM($M$8:$AB$8))*100,1)) -> 90.7 | AM9: =IF(AL9="","",IF(AL9>=Parámetros!$D$41,"Alta",IF(AL9>=Parámetros!$D$42,"Media","Baja"))) -> Alta | AN9: =IF(AL9="","",AR9) -> 1 | AO9: =IF(A9="","",TRIM(IF(AND(I9="Sí",1_Proyectos!L9<>"",OR(AND(Parámetros!$D$35<>"",1_Proyectos!L9<Parámetros!$D$35),AND(Parámetros!$D$36<>"",1_Proyectos!L9>Parámetros!$D$36))),"F1 en Sí con monto fuera de rango. ","")&IF(AND(E9="Sí",1_Proyectos!F9=""),"O2 en Sí sin fracción principal. ","")&IF(AND(AD9="Elegible",COUNT(M9:AB9)<16),"Elegible con calificaciones incompletas. ","")&IF(AND(1_Proyectos!F9<>"",COUNTA(1_Proyectos!F9:I9)>N(1_Proyectos!K9)),"Fracción repetida en el registro. ","")&IF(AND(AD9="Elegible",R9=""),"Falta monto o costo total para calcular F5. ","")&IF(AND(A9<>"",1_Proyectos!D9=""),"Falta tipo de proponente. ",""))) | AP9: Ejemplo: candidato prioritario; reforzar sostenibilidad posterior (F6). | AQ9: =IF(A9="","",IF(AL9<>"",AL9*1000000+N9*10000+O9*100+AI9-ROW()/1000,-ROW())) -> 90730309 | AR9: =IF(AQ9="","",COUNTIF($AQ$9:$AQ$58,">"&AQ9)+1) -> 1
A10: =IF(1_Proyectos!A10="","",1_Proyectos!A10) -> EJ-02 | B10: =IF(1_Proyectos!B10="","",1_Proyectos!B10) -> Sistemas fotovoltaicos en escuelas rurales (ejemplo) | C10: =IF(1_Proyectos!F10="","",1_Proyectos!F10) -> VI | D10: Sí | E10: Sí | F10: Sí | G10: Sí | H10: Sí | I10: Sí | J10: Sí | K10: Sí | L10: Sí | M10: =IF(1_Proyectos!K10="","",IF(1_Proyectos!K10>=Parámetros!$D$37,3,IF(1_Proyectos!K10>=Parámetros!$D$38,2,1))) -> 2 | N10: 2 | O10: 2 | P10: 1 | Q10: 3 | R10: =IF(1_Proyectos!N10="","",IF(1_Proyectos!N10>=Parámetros!$D$39,3,IF(1_Proyectos!N10>=Parámetros!$D$40,2,1))) -> 1 | S10: 3 | T10: 2 | U10: 2 | V10: 2 | W10: 2 | X10: 1 | Y10: 2 | Z10: 1 | AA10: 1 | AB10: 2 | AC10: =IF(A10="","",COUNTIF(D10:L10,"Sí")) -> 9 | AD10: =IF(A10="","",IF(COUNTIF(D10:L10,"No")>0,"No elegible",IF(COUNTIF(D10:L10,"Sí")=9,"Elegible","Pendiente"))) -> Elegible | AE10: =TRIM(IF(D10="No","O1 ","")&IF(E10="No","O2 ","")&IF(F10="No","O3 ","")&IF(G10="No","T1 ","")&IF(H10="No","T2 ","")&IF(I10="No","F1 ","")&IF(J10="No","F2 ","")&IF(K10="No","F3 ","")&IF(L10="No","E1 ","")) | AF10: =IF(AD10="Elegible",SUM(M10,N10),"") -> 4 | AG10: =IF(AD10="Elegible",SUM(O10,P10),"") -> 3 | AH10: =IF(AD10="Elegible",SUM(Q10,R10,S10,T10,U10),"") -> 11 | AI10: =IF(AD10="Elegible",SUM(V10,W10,X10),"") -> 5 | AJ10: =IF(AD10="Elegible",SUM(Y10,Z10,AA10,AB10),"") -> 6 | AK10: =IF(AND(AD10="Elegible",COUNT(M10:AB10)=16),SUM(M10:AB10),"") -> 29 | AL10: =IF(AK10="","",ROUND(SUMPRODUCT($M$8:$AB$8,M10:AB10)/(3*SUM($M$8:$AB$8))*100,1)) -> 61.1 | AM10: =IF(AL10="","",IF(AL10>=Parámetros!$D$41,"Alta",IF(AL10>=Parámetros!$D$42,"Media","Baja"))) -> Media | AN10: =IF(AL10="","",AR10) -> 2 | AO10: =IF(A10="","",TRIM(IF(AND(I10="Sí",1_Proyectos!L10<>"",OR(AND(Parámetros!$D$35<>"",1_Proyectos!L10<Parámetros!$D$35),AND(Parámetros!$D$36<>"",1_Proyectos!L10>Parámetros!$D$36))),"F1 en Sí con monto fuera de rango. ","")&IF(AND(E10="Sí",1_Proyectos!F10=""),"O2 en Sí sin fracción principal. ","")&IF(AND(AD10="Elegible",COUNT(M10:AB10)<16),"Elegible con calificaciones incompletas. ","")&IF(AND(1_Proyectos!F10<>"",COUNTA(1_Proyectos!F10:I10)>N(1_Proyectos!K10)),"Fracción repetida en el registro. ","")&IF(AND(AD10="Elegible",R10=""),"Falta monto o costo total para calcular F5. ","")&IF(AND(A10<>"",1_Proyectos!D10=""),"Falta tipo de proponente. ",""))) | AP10: Ejemplo: elegible con áreas de mejora en participación e inclusión. | AQ10: =IF(A10="","",IF(AL10<>"",AL10*1000000+N10*10000+O10*100+AI10-ROW()/1000,-ROW())) -> 61120205 | AR10: =IF(AQ10="","",COUNTIF($AQ$9:$AQ$58,">"&AQ10)+1) -> 2
A11: =IF(1_Proyectos!A11="","",1_Proyectos!A11) -> EJ-03 | B11: =IF(1_Proyectos!B11="","",1_Proyectos!B11) -> Campaña de cultura climática en redes sociales (ejemplo) | C11: =IF(1_Proyectos!F11="","",1_Proyectos!F11) -> X | D11: Sí | E11: Sí | F11: No | G11: Sí | H11: Sí | I11: Sí | J11: Sí | K11: Sí | L11: No | M11: =IF(1_Proyectos!K11="","",IF(1_Proyectos!K11>=Parámetros!$D$37,3,IF(1_Proyectos!K11>=Parámetros!$D$38,2,1))) -> 1 | R11: =IF(1_Proyectos!N11="","",IF(1_Proyectos!N11>=Parámetros!$D$39,3,IF(1_Proyectos!N11>=Parámetros!$D$40,2,1))) -> 1 | AC11: =IF(A11="","",COUNTIF(D11:L11,"Sí")) -> 7 | AD11: =IF(A11="","",IF(COUNTIF(D11:L11,"No")>0,"No elegible",IF(COUNTIF(D11:L11,"Sí")=9,"Elegible","Pendiente"))) -> No elegible | AE11: =TRIM(IF(D11="No","O1 ","")&IF(E11="No","O2 ","")&IF(F11="No","O3 ","")&IF(G11="No","T1 ","")&IF(H11="No","T2 ","")&IF(I11="No","F1 ","")&IF(J11="No","F2 ","")&IF(K11="No","F3 ","")&IF(L11="No","E1 ","")) -> O3 E1 | AF11: =IF(AD11="Elegible",SUM(M11,N11),"") | AG11: =IF(AD11="Elegible",SUM(O11,P11),"") | AH11: =IF(AD11="Elegible",SUM(Q11,R11,S11,T11,U11),"") | AI11: =IF(AD11="Elegible",SUM(V11,W11,X11),"") | AJ11: =IF(AD11="Elegible",SUM(Y11,Z11,AA11,AB11),"") | AK11: =IF(AND(AD11="Elegible",COUNT(M11:AB11)=16),SUM(M11:AB11),"") | AL11: =IF(AK11="","",ROUND(SUMPRODUCT($M$8:$AB$8,M11:AB11)/(3*SUM($M$8:$AB$8))*100,1)) | AM11: =IF(AL11="","",IF(AL11>=Parámetros!$D$41,"Alta",IF(AL11>=Parámetros!$D$42,"Media","Baja"))) | AN11: =IF(AL11="","",AR11) | AO11: =IF(A11="","",TRIM(IF(AND(I11="Sí",1_Proyectos!L11<>"",OR(AND(Parámetros!$D$35<>"",1_Proyectos!L11<Parámetros!$D$35),AND(Parámetros!$D$36<>"",1_Proyectos!L11>Parámetros!$D$36))),"F1 en Sí con monto fuera de rango. ","")&IF(AND(E11="Sí",1_Proyectos!F11=""),"O2 en Sí sin fracción principal. ","")&IF(AND(AD11="Elegible",COUNT(M11:AB11)<16),"Elegible con calificaciones incompletas. ","")&IF(AND(1_Proyectos!F11<>"",COUNTA(1_Proyectos!F11:I11)>N(1_Proyectos!K11)),"Fracción repetida en el registro. ","")&IF(AND(AD11="Elegible",R11=""),"Falta monto o costo total para calcular F5. ","")&IF(AND(A11<>"",1_Proyectos!D11=""),"Falta tipo de proponente. ",""))) | AP11: Ejemplo: no define evaluación antes y después (O3) ni indicador con línea base y meta (E1). | AQ11: =IF(A11="","",IF(AL11<>"",AL11*1000000+N11*10000+O11*100+AI11-ROW()/1000,-ROW())) -> -11 | AR11: =IF(AQ11="","",COUNTIF($AQ$9:$AQ$58,">"&AQ11)+1) -> 3
A12: =IF(1_Proyectos!A12="","",1_Proyectos!A12) -> EJ-04 | B12: =IF(1_Proyectos!B12="","",1_Proyectos!B12) -> Planta municipal de compostaje (ejemplo) | C12: =IF(1_Proyectos!F12="","",1_Proyectos!F12) -> IX | D12: Sí | E12: Sí | F12: Sí | G12: Sí | I12: Sí | J12: Sí | K12: Sí | L12: Sí | M12: =IF(1_Proyectos!K12="","",IF(1_Proyectos!K12>=Parámetros!$D$37,3,IF(1_Proyectos!K12>=Parámetros!$D$38,2,1))) -> 2 | R12: =IF(1_Proyectos!N12="","",IF(1_Proyectos!N12>=Parámetros!$D$39,3,IF(1_Proyectos!N12>=Parámetros!$D$40,2,1))) -> 3 | AC12: =IF(A12="","",COUNTIF(D12:L12,"Sí")) -> 8 | AD12: =IF(A12="","",IF(COUNTIF(D12:L12,"No")>0,"No elegible",IF(COUNTIF(D12:L12,"Sí")=9,"Elegible","Pendiente"))) -> Pendiente | AE12: =TRIM(IF(D12="No","O1 ","")&IF(E12="No","O2 ","")&IF(F12="No","O3 ","")&IF(G12="No","T1 ","")&IF(H12="No","T2 ","")&IF(I12="No","F1 ","")&IF(J12="No","F2 ","")&IF(K12="No","F3 ","")&IF(L12="No","E1 ","")) | AF12: =IF(AD12="Elegible",SUM(M12,N12),"") | AG12: =IF(AD12="Elegible",SUM(O12,P12),"") | AH12: =IF(AD12="Elegible",SUM(Q12,R12,S12,T12,U12),"") | AI12: =IF(AD12="Elegible",SUM(V12,W12,X12),"") | AJ12: =IF(AD12="Elegible",SUM(Y12,Z12,AA12,AB12),"") | AK12: =IF(AND(AD12="Elegible",COUNT(M12:AB12)=16),SUM(M12:AB12),"") | AL12: =IF(AK12="","",ROUND(SUMPRODUCT($M$8:$AB$8,M12:AB12)/(3*SUM($M$8:$AB$8))*100,1)) | AM12: =IF(AL12="","",IF(AL12>=Parámetros!$D$41,"Alta",IF(AL12>=Parámetros!$D$42,"Media","Baja"))) | AN12: =IF(AL12="","",AR12) | AO12: =IF(A12="","",TRIM(IF(AND(I12="Sí",1_Proyectos!L12<>"",OR(AND(Parámetros!$D$35<>"",1_Proyectos!L12<Parámetros!$D$35),AND(Parámetros!$D$36<>"",1_Proyectos!L12>Parámetros!$D$36))),"F1 en Sí con monto fuera de rango. ","")&IF(AND(E12="Sí",1_Proyectos!F12=""),"O2 en Sí sin fracción principal. ","")&IF(AND(AD12="Elegible",COUNT(M12:AB12)<16),"Elegible con calificaciones incompletas. ","")&IF(AND(1_Proyectos!F12<>"",COUNTA(1_Proyectos!F12:I12)>N(1_Proyectos!K12)),"Fracción repetida en el registro. ","")&IF(AND(AD12="Elegible",R12=""),"Falta monto o costo total para calcular F5. ","")&IF(AND(A12<>"",1_Proyectos!D12=""),"Falta tipo de proponente. ",""))) | AP12: Ejemplo: pendiente de acreditar autorizaciones ambientales (T2). | AQ12: =IF(A12="","",IF(AL12<>"",AL12*1000000+N12*10000+O12*100+AI12-ROW()/1000,-ROW())) -> -12 | AR12: =IF(AQ12="","",COUNTIF($AQ$9:$AQ$58,">"&AQ12)+1) -> 4
A13: =IF(1_Proyectos!A13="","",1_Proyectos!A13) | B13: =IF(1_Proyectos!B13="","",1_Proyectos!B13) | C13: =IF(1_Proyectos!F13="","",1_Proyectos!F13) | M13: =IF(1_Proyectos!K13="","",IF(1_Proyectos!K13>=Parámetros!$D$37,3,IF(1_Proyectos!K13>=Parámetros!$D$38,2,1))) | R13: =IF(1_Proyectos!N13="","",IF(1_Proyectos!N13>=Parámetros!$D$39,3,IF(1_Proyectos!N13>=Parámetros!$D$40,2,1))) | AC13: =IF(A13="","",COUNTIF(D13:L13,"Sí")) | AD13: =IF(A13="","",IF(COUNTIF(D13:L13,"No")>0,"No elegible",IF(COUNTIF(D13:L13,"Sí")=9,"Elegible","Pendiente"))) | AE13: =TRIM(IF(D13="No","O1 ","")&IF(E13="No","O2 ","")&IF(F13="No","O3 ","")&IF(G13="No","T1 ","")&IF(H13="No","T2 ","")&IF(I13="No","F1 ","")&IF(J13="No","F2 ","")&IF(K13="No","F3 ","")&IF(L13="No","E1 ","")) | AF13: =IF(AD13="Elegible",SUM(M13,N13),"") | AG13: =IF(AD13="Elegible",SUM(O13,P13),"") | AH13: =IF(AD13="Elegible",SUM(Q13,R13,S13,T13,U13),"") | AI13: =IF(AD13="Elegible",SUM(V13,W13,X13),"") | AJ13: =IF(AD13="Elegible",SUM(Y13,Z13,AA13,AB13),"") | AK13: =IF(AND(AD13="Elegible",COUNT(M13:AB13)=16),SUM(M13:AB13),"") | AL13: =IF(AK13="","",ROUND(SUMPRODUCT($M$8:$AB$8,M13:AB13)/(3*SUM($M$8:$AB$8))*100,1)) | AM13: =IF(AL13="","",IF(AL13>=Parámetros!$D$41,"Alta",IF(AL13>=Parámetros!$D$42,"Media","Baja"))) | AN13: =IF(AL13="","",AR13) | AO13: =IF(A13="","",TRIM(IF(AND(I13="Sí",1_Proyectos!L13<>"",OR(AND(Parámetros!$D$35<>"",1_Proyectos!L13<Parámetros!$D$35),AND(Parámetros!$D$36<>"",1_Proyectos!L13>Parámetros!$D$36))),"F1 en Sí con monto fuera de rango. ","")&IF(AND(E13="Sí",1_Proyectos!F13=""),"O2 en Sí sin fracción principal. ","")&IF(AND(AD13="Elegible",COUNT(M13:AB13)<16),"Elegible con calificaciones incompletas. ","")&IF(AND(1_Proyectos!F13<>"",COUNTA(1_Proyectos!F13:I13)>N(1_Proyectos!K13)),"Fracción repetida en el registro. ","")&IF(AND(AD13="Elegible",R13=""),"Falta monto o costo total para calcular F5. ","")&IF(AND(A13<>"",1_Proyectos!D13=""),"Falta tipo de proponente. ",""))) | AQ13: =IF(A13="","",IF(AL13<>"",AL13*1000000+N13*10000+O13*100+AI13-ROW()/1000,-ROW())) | AR13: =IF(AQ13="","",COUNTIF($AQ$9:$AQ$58,">"&AQ13)+1)
A14: =IF(1_Proyectos!A14="","",1_Proyectos!A14) | B14: =IF(1_Proyectos!B14="","",1_Proyectos!B14) | C14: =IF(1_Proyectos!F14="","",1_Proyectos!F14) | M14: =IF(1_Proyectos!K14="","",IF(1_Proyectos!K14>=Parámetros!$D$37,3,IF(1_Proyectos!K14>=Parámetros!$D$38,2,1))) | R14: =IF(1_Proyectos!N14="","",IF(1_Proyectos!N14>=Parámetros!$D$39,3,IF(1_Proyectos!N14>=Parámetros!$D$40,2,1))) | AC14: =IF(A14="","",COUNTIF(D14:L14,"Sí")) | AD14: =IF(A14="","",IF(COUNTIF(D14:L14,"No")>0,"No elegible",IF(COUNTIF(D14:L14,"Sí")=9,"Elegible","Pendiente"))) | AE14: =TRIM(IF(D14="No","O1 ","")&IF(E14="No","O2 ","")&IF(F14="No","O3 ","")&IF(G14="No","T1 ","")&IF(H14="No","T2 ","")&IF(I14="No","F1 ","")&IF(J14="No","F2 ","")&IF(K14="No","F3 ","")&IF(L14="No","E1 ","")) | AF14: =IF(AD14="Elegible",SUM(M14,N14),"") | AG14: =IF(AD14="Elegible",SUM(O14,P14),"") | AH14: =IF(AD14="Elegible",SUM(Q14,R14,S14,T14,U14),"") | AI14: =IF(AD14="Elegible",SUM(V14,W14,X14),"") | AJ14: =IF(AD14="Elegible",SUM(Y14,Z14,AA14,AB14),"") | AK14: =IF(AND(AD14="Elegible",COUNT(M14:AB14)=16),SUM(M14:AB14),"") | AL14: =IF(AK14="","",ROUND(SUMPRODUCT($M$8:$AB$8,M14:AB14)/(3*SUM($M$8:$AB$8))*100,1)) | AM14: =IF(AL14="","",IF(AL14>=Parámetros!$D$41,"Alta",IF(AL14>=Parámetros!$D$42,"Media","Baja"))) | AN14: =IF(AL14="","",AR14) | AO14: =IF(A14="","",TRIM(IF(AND(I14="Sí",1_Proyectos!L14<>"",OR(AND(Parámetros!$D$35<>"",1_Proyectos!L14<Parámetros!$D$35),AND(Parámetros!$D$36<>"",1_Proyectos!L14>Parámetros!$D$36))),"F1 en Sí con monto fuera de rango. ","")&IF(AND(E14="Sí",1_Proyectos!F14=""),"O2 en Sí sin fracción principal. ","")&IF(AND(AD14="Elegible",COUNT(M14:AB14)<16),"Elegible con calificaciones incompletas. ","")&IF(AND(1_Proyectos!F14<>"",COUNTA(1_Proyectos!F14:I14)>N(1_Proyectos!K14)),"Fracción repetida en el registro. ","")&IF(AND(AD14="Elegible",R14=""),"Falta monto o costo total para calcular F5. ","")&IF(AND(A14<>"",1_Proyectos!D14=""),"Falta tipo de proponente. ",""))) | AQ14: =IF(A14="","",IF(AL14<>"",AL14*1000000+N14*10000+O14*100+AI14-ROW()/1000,-ROW())) | AR14: =IF(AQ14="","",COUNTIF($AQ$9:$AQ$58,">"&AQ14)+1)
A15: =IF(1_Proyectos!A15="","",1_Proyectos!A15) | B15: =IF(1_Proyectos!B15="","",1_Proyectos!B15) | C15: =IF(1_Proyectos!F15="","",1_Proyectos!F15) | M15: =IF(1_Proyectos!K15="","",IF(1_Proyectos!K15>=Parámetros!$D$37,3,IF(1_Proyectos!K15>=Parámetros!$D$38,2,1))) | R15: =IF(1_Proyectos!N15="","",IF(1_Proyectos!N15>=Parámetros!$D$39,3,IF(1_Proyectos!N15>=Parámetros!$D$40,2,1))) | AC15: =IF(A15="","",COUNTIF(D15:L15,"Sí")) | AD15: =IF(A15="","",IF(COUNTIF(D15:L15,"No")>0,"No elegible",IF(COUNTIF(D15:L15,"Sí")=9,"Elegible","Pendiente"))) | AE15: =TRIM(IF(D15="No","O1 ","")&IF(E15="No","O2 ","")&IF(F15="No","O3 ","")&IF(G15="No","T1 ","")&IF(H15="No","T2 ","")&IF(I15="No","F1 ","")&IF(J15="No","F2 ","")&IF(K15="No","F3 ","")&IF(L15="No","E1 ","")) | AF15: =IF(AD15="Elegible",SUM(M15,N15),"") | AG15: =IF(AD15="Elegible",SUM(O15,P15),"") | AH15: =IF(AD15="Elegible",SUM(Q15,R15,S15,T15,U15),"") | AI15: =IF(AD15="Elegible",SUM(V15,W15,X15),"") | AJ15: =IF(AD15="Elegible",SUM(Y15,Z15,AA15,AB15),"") | AK15: =IF(AND(AD15="Elegible",COUNT(M15:AB15)=16),SUM(M15:AB15),"") | AL15: =IF(AK15="","",ROUND(SUMPRODUCT($M$8:$AB$8,M15:AB15)/(3*SUM($M$8:$AB$8))*100,1)) | AM15: =IF(AL15="","",IF(AL15>=Parámetros!$D$41,"Alta",IF(AL15>=Parámetros!$D$42,"Media","Baja"))) | AN15: =IF(AL15="","",AR15) | AO15: =IF(A15="","",TRIM(IF(AND(I15="Sí",1_Proyectos!L15<>"",OR(AND(Parámetros!$D$35<>"",1_Proyectos!L15<Parámetros!$D$35),AND(Parámetros!$D$36<>"",1_Proyectos!L15>Parámetros!$D$36))),"F1 en Sí con monto fuera de rango. ","")&IF(AND(E15="Sí",1_Proyectos!F15=""),"O2 en Sí sin fracción principal. ","")&IF(AND(AD15="Elegible",COUNT(M15:AB15)<16),"Elegible con calificaciones incompletas. ","")&IF(AND(1_Proyectos!F15<>"",COUNTA(1_Proyectos!F15:I15)>N(1_Proyectos!K15)),"Fracción repetida en el registro. ","")&IF(AND(AD15="Elegible",R15=""),"Falta monto o costo total para calcular F5. ","")&IF(AND(A15<>"",1_Proyectos!D15=""),"Falta tipo de proponente. ",""))) | AQ15: =IF(A15="","",IF(AL15<>"",AL15*1000000+N15*10000+O15*100+AI15-ROW()/1000,-ROW())) | AR15: =IF(AQ15="","",COUNTIF($AQ$9:$AQ$58,">"&AQ15)+1)
A16: =IF(1_Proyectos!A16="","",1_Proyectos!A16) | B16: =IF(1_Proyectos!B16="","",1_Proyectos!B16) | C16: =IF(1_Proyectos!F16="","",1_Proyectos!F16) | M16: =IF(1_Proyectos!K16="","",IF(1_Proyectos!K16>=Parámetros!$D$37,3,IF(1_Proyectos!K16>=Parámetros!$D$38,2,1))) | R16: =IF(1_Proyectos!N16="","",IF(1_Proyectos!N16>=Parámetros!$D$39,3,IF(1_Proyectos!N16>=Parámetros!$D$40,2,1))) | AC16: =IF(A16="","",COUNTIF(D16:L16,"Sí")) | AD16: =IF(A16="","",IF(COUNTIF(D16:L16,"No")>0,"No elegible",IF(COUNTIF(D16:L16,"Sí")=9,"Elegible","Pendiente"))) | AE16: =TRIM(IF(D16="No","O1 ","")&IF(E16="No","O2 ","")&IF(F16="No","O3 ","")&IF(G16="No","T1 ","")&IF(H16="No","T2 ","")&IF(I16="No","F1 ","")&IF(J16="No","F2 ","")&IF(K16="No","F3 ","")&IF(L16="No","E1 ","")) | AF16: =IF(AD16="Elegible",SUM(M16,N16),"") | AG16: =IF(AD16="Elegible",SUM(O16,P16),"") | AH16: =IF(AD16="Elegible",SUM(Q16,R16,S16,T16,U16),"") | AI16: =IF(AD16="Elegible",SUM(V16,W16,X16),"") | AJ16: =IF(AD16="Elegible",SUM(Y16,Z16,AA16,AB16),"") | AK16: =IF(AND(AD16="Elegible",COUNT(M16:AB16)=16),SUM(M16:AB16),"") | AL16: =IF(AK16="","",ROUND(SUMPRODUCT($M$8:$AB$8,M16:AB16)/(3*SUM($M$8:$AB$8))*100,1)) | AM16: =IF(AL16="","",IF(AL16>=Parámetros!$D$41,"Alta",IF(AL16>=Parámetros!$D$42,"Media","Baja"))) | AN16: =IF(AL16="","",AR16) | AO16: =IF(A16="","",TRIM(IF(AND(I16="Sí",1_Proyectos!L16<>"",OR(AND(Parámetros!$D$35<>"",1_Proyectos!L16<Parámetros!$D$35),AND(Parámetros!$D$36<>"",1_Proyectos!L16>Parámetros!$D$36))),"F1 en Sí con monto fuera de rango. ","")&IF(AND(E16="Sí",1_Proyectos!F16=""),"O2 en Sí sin fracción principal. ","")&IF(AND(AD16="Elegible",COUNT(M16:AB16)<16),"Elegible con calificaciones incompletas. ","")&IF(AND(1_Proyectos!F16<>"",COUNTA(1_Proyectos!F16:I16)>N(1_Proyectos!K16)),"Fracción repetida en el registro. ","")&IF(AND(AD16="Elegible",R16=""),"Falta monto o costo total para calcular F5. ","")&IF(AND(A16<>"",1_Proyectos!D16=""),"Falta tipo de proponente. ",""))) | AQ16: =IF(A16="","",IF(AL16<>"",AL16*1000000+N16*10000+O16*100+AI16-ROW()/1000,-ROW())) | AR16: =IF(AQ16="","",COUNTIF($AQ$9:$AQ$58,">"&AQ16)+1)
A17: =IF(1_Proyectos!A17="","",1_Proyectos!A17) | B17: =IF(1_Proyectos!B17="","",1_Proyectos!B17) | C17: =IF(1_Proyectos!F17="","",1_Proyectos!F17) | M17: =IF(1_Proyectos!K17="","",IF(1_Proyectos!K17>=Parámetros!$D$37,3,IF(1_Proyectos!K17>=Parámetros!$D$38,2,1))) | R17: =IF(1_Proyectos!N17="","",IF(1_Proyectos!N17>=Parámetros!$D$39,3,IF(1_Proyectos!N17>=Parámetros!$D$40,2,1))) | AC17: =IF(A17="","",COUNTIF(D17:L17,"Sí")) | AD17: =IF(A17="","",IF(COUNTIF(D17:L17,"No")>0,"No elegible",IF(COUNTIF(D17:L17,"Sí")=9,"Elegible","Pendiente"))) | AE17: =TRIM(IF(D17="No","O1 ","")&IF(E17="No","O2 ","")&IF(F17="No","O3 ","")&IF(G17="No","T1 ","")&IF(H17="No","T2 ","")&IF(I17="No","F1 ","")&IF(J17="No","F2 ","")&IF(K17="No","F3 ","")&IF(L17="No","E1 ","")) | AF17: =IF(AD17="Elegible",SUM(M17,N17),"") | AG17: =IF(AD17="Elegible",SUM(O17,P17),"") | AH17: =IF(AD17="Elegible",SUM(Q17,R17,S17,T17,U17),"") | AI17: =IF(AD17="Elegible",SUM(V17,W17,X17),"") | AJ17: =IF(AD17="Elegible",SUM(Y17,Z17,AA17,AB17),"") | AK17: =IF(AND(AD17="Elegible",COUNT(M17:AB17)=16),SUM(M17:AB17),"") | AL17: =IF(AK17="","",ROUND(SUMPRODUCT($M$8:$AB$8,M17:AB17)/(3*SUM($M$8:$AB$8))*100,1)) | AM17: =IF(AL17="","",IF(AL17>=Parámetros!$D$41,"Alta",IF(AL17>=Parámetros!$D$42,"Media","Baja"))) | AN17: =IF(AL17="","",AR17) | AO17: =IF(A17="","",TRIM(IF(AND(I17="Sí",1_Proyectos!L17<>"",OR(AND(Parámetros!$D$35<>"",1_Proyectos!L17<Parámetros!$D$35),AND(Parámetros!$D$36<>"",1_Proyectos!L17>Parámetros!$D$36))),"F1 en Sí con monto fuera de rango. ","")&IF(AND(E17="Sí",1_Proyectos!F17=""),"O2 en Sí sin fracción principal. ","")&IF(AND(AD17="Elegible",COUNT(M17:AB17)<16),"Elegible con calificaciones incompletas. ","")&IF(AND(1_Proyectos!F17<>"",COUNTA(1_Proyectos!F17:I17)>N(1_Proyectos!K17)),"Fracción repetida en el registro. ","")&IF(AND(AD17="Elegible",R17=""),"Falta monto o costo total para calcular F5. ","")&IF(AND(A17<>"",1_Proyectos!D17=""),"Falta tipo de proponente. ",""))) | AQ17: =IF(A17="","",IF(AL17<>"",AL17*1000000+N17*10000+O17*100+AI17-ROW()/1000,-ROW())) | AR17: =IF(AQ17="","",COUNTIF($AQ$9:$AQ$58,">"&AQ17)+1)
A18: =IF(1_Proyectos!A18="","",1_Proyectos!A18) | B18: =IF(1_Proyectos!B18="","",1_Proyectos!B18) | C18: =IF(1_Proyectos!F18="","",1_Proyectos!F18) | M18: =IF(1_Proyectos!K18="","",IF(1_Proyectos!K18>=Parámetros!$D$37,3,IF(1_Proyectos!K18>=Parámetros!$D$38,2,1))) | R18: =IF(1_Proyectos!N18="","",IF(1_Proyectos!N18>=Parámetros!$D$39,3,IF(1_Proyectos!N18>=Parámetros!$D$40,2,1))) | AC18: =IF(A18="","",COUNTIF(D18:L18,"Sí")) | AD18: =IF(A18="","",IF(COUNTIF(D18:L18,"No")>0,"No elegible",IF(COUNTIF(D18:L18,"Sí")=9,"Elegible","Pendiente"))) | AE18: =TRIM(IF(D18="No","O1 ","")&IF(E18="No","O2 ","")&IF(F18="No","O3 ","")&IF(G18="No","T1 ","")&IF(H18="No","T2 ","")&IF(I18="No","F1 ","")&IF(J18="No","F2 ","")&IF(K18="No","F3 ","")&IF(L18="No","E1 ","")) | AF18: =IF(AD18="Elegible",SUM(M18,N18),"") | AG18: =IF(AD18="Elegible",SUM(O18,P18),"") | AH18: =IF(AD18="Elegible",SUM(Q18,R18,S18,T18,U18),"") | AI18: =IF(AD18="Elegible",SUM(V18,W18,X18),"") | AJ18: =IF(AD18="Elegible",SUM(Y18,Z18,AA18,AB18),"") | AK18: =IF(AND(AD18="Elegible",COUNT(M18:AB18)=16),SUM(M18:AB18),"") | AL18: =IF(AK18="","",ROUND(SUMPRODUCT($M$8:$AB$8,M18:AB18)/(3*SUM($M$8:$AB$8))*100,1)) | AM18: =IF(AL18="","",IF(AL18>=Parámetros!$D$41,"Alta",IF(AL18>=Parámetros!$D$42,"Media","Baja"))) | AN18: =IF(AL18="","",AR18) | AO18: =IF(A18="","",TRIM(IF(AND(I18="Sí",1_Proyectos!L18<>"",OR(AND(Parámetros!$D$35<>"",1_Proyectos!L18<Parámetros!$D$35),AND(Parámetros!$D$36<>"",1_Proyectos!L18>Parámetros!$D$36))),"F1 en Sí con monto fuera de rango. ","")&IF(AND(E18="Sí",1_Proyectos!F18=""),"O2 en Sí sin fracción principal. ","")&IF(AND(AD18="Elegible",COUNT(M18:AB18)<16),"Elegible con calificaciones incompletas. ","")&IF(AND(1_Proyectos!F18<>"",COUNTA(1_Proyectos!F18:I18)>N(1_Proyectos!K18)),"Fracción repetida en el registro. ","")&IF(AND(AD18="Elegible",R18=""),"Falta monto o costo total para calcular F5. ","")&IF(AND(A18<>"",1_Proyectos!D18=""),"Falta tipo de proponente. ",""))) | AQ18: =IF(A18="","",IF(AL18<>"",AL18*1000000+N18*10000+O18*100+AI18-ROW()/1000,-ROW())) | AR18: =IF(AQ18="","",COUNTIF($AQ$9:$AQ$58,">"&AQ18)+1)
A19: =IF(1_Proyectos!A19="","",1_Proyectos!A19) | B19: =IF(1_Proyectos!B19="","",1_Proyectos!B19) | C19: =IF(1_Proyectos!F19="","",1_Proyectos!F19) | M19: =IF(1_Proyectos!K19="","",IF(1_Proyectos!K19>=Parámetros!$D$37,3,IF(1_Proyectos!K19>=Parámetros!$D$38,2,1))) | R19: =IF(1_Proyectos!N19="","",IF(1_Proyectos!N19>=Parámetros!$D$39,3,IF(1_Proyectos!N19>=Parámetros!$D$40,2,1))) | AC19: =IF(A19="","",COUNTIF(D19:L19,"Sí")) | AD19: =IF(A19="","",IF(COUNTIF(D19:L19,"No")>0,"No elegible",IF(COUNTIF(D19:L19,"Sí")=9,"Elegible","Pendiente"))) | AE19: =TRIM(IF(D19="No","O1 ","")&IF(E19="No","O2 ","")&IF(F19="No","O3 ","")&IF(G19="No","T1 ","")&IF(H19="No","T2 ","")&IF(I19="No","F1 ","")&IF(J19="No","F2 ","")&IF(K19="No","F3 ","")&IF(L19="No","E1 ","")) | AF19: =IF(AD19="Elegible",SUM(M19,N19),"") | AG19: =IF(AD19="Elegible",SUM(O19,P19),"") | AH19: =IF(AD19="Elegible",SUM(Q19,R19,S19,T19,U19),"") | AI19: =IF(AD19="Elegible",SUM(V19,W19,X19),"") | AJ19: =IF(AD19="Elegible",SUM(Y19,Z19,AA19,AB19),"") | AK19: =IF(AND(AD19="Elegible",COUNT(M19:AB19)=16),SUM(M19:AB19),"") | AL19: =IF(AK19="","",ROUND(SUMPRODUCT($M$8:$AB$8,M19:AB19)/(3*SUM($M$8:$AB$8))*100,1)) | AM19: =IF(AL19="","",IF(AL19>=Parámetros!$D$41,"Alta",IF(AL19>=Parámetros!$D$42,"Media","Baja"))) | AN19: =IF(AL19="","",AR19) | AO19: =IF(A19="","",TRIM(IF(AND(I19="Sí",1_Proyectos!L19<>"",OR(AND(Parámetros!$D$35<>"",1_Proyectos!L19<Parámetros!$D$35),AND(Parámetros!$D$36<>"",1_Proyectos!L19>Parámetros!$D$36))),"F1 en Sí con monto fuera de rango. ","")&IF(AND(E19="Sí",1_Proyectos!F19=""),"O2 en Sí sin fracción principal. ","")&IF(AND(AD19="Elegible",COUNT(M19:AB19)<16),"Elegible con calificaciones incompletas. ","")&IF(AND(1_Proyectos!F19<>"",COUNTA(1_Proyectos!F19:I19)>N(1_Proyectos!K19)),"Fracción repetida en el registro. ","")&IF(AND(AD19="Elegible",R19=""),"Falta monto o costo total para calcular F5. ","")&IF(AND(A19<>"",1_Proyectos!D19=""),"Falta tipo de proponente. ",""))) | AQ19: =IF(A19="","",IF(AL19<>"",AL19*1000000+N19*10000+O19*100+AI19-ROW()/1000,-ROW())) | AR19: =IF(AQ19="","",COUNTIF($AQ$9:$AQ$58,">"&AQ19)+1)
A20: =IF(1_Proyectos!A20="","",1_Proyectos!A20) | B20: =IF(1_Proyectos!B20="","",1_Proyectos!B20) | C20: =IF(1_Proyectos!F20="","",1_Proyectos!F20) | M20: =IF(1_Proyectos!K20="","",IF(1_Proyectos!K20>=Parámetros!$D$37,3,IF(1_Proyectos!K20>=Parámetros!$D$38,2,1))) | R20: =IF(1_Proyectos!N20="","",IF(1_Proyectos!N20>=Parámetros!$D$39,3,IF(1_Proyectos!N20>=Parámetros!$D$40,2,1))) | AC20: =IF(A20="","",COUNTIF(D20:L20,"Sí")) | AD20: =IF(A20="","",IF(COUNTIF(D20:L20,"No")>0,"No elegible",IF(COUNTIF(D20:L20,"Sí")=9,"Elegible","Pendiente"))) | AE20: =TRIM(IF(D20="No","O1 ","")&IF(E20="No","O2 ","")&IF(F20="No","O3 ","")&IF(G20="No","T1 ","")&IF(H20="No","T2 ","")&IF(I20="No","F1 ","")&IF(J20="No","F2 ","")&IF(K20="No","F3 ","")&IF(L20="No","E1 ","")) | AF20: =IF(AD20="Elegible",SUM(M20,N20),"") | AG20: =IF(AD20="Elegible",SUM(O20,P20),"") | AH20: =IF(AD20="Elegible",SUM(Q20,R20,S20,T20,U20),"") | AI20: =IF(AD20="Elegible",SUM(V20,W20,X20),"") | AJ20: =IF(AD20="Elegible",SUM(Y20,Z20,AA20,AB20),"") | AK20: =IF(AND(AD20="Elegible",COUNT(M20:AB20)=16),SUM(M20:AB20),"") | AL20: =IF(AK20="","",ROUND(SUMPRODUCT($M$8:$AB$8,M20:AB20)/(3*SUM($M$8:$AB$8))*100,1)) | AM20: =IF(AL20="","",IF(AL20>=Parámetros!$D$41,"Alta",IF(AL20>=Parámetros!$D$42,"Media","Baja"))) | AN20: =IF(AL20="","",AR20) | AO20: =IF(A20="","",TRIM(IF(AND(I20="Sí",1_Proyectos!L20<>"",OR(AND(Parámetros!$D$35<>"",1_Proyectos!L20<Parámetros!$D$35),AND(Parámetros!$D$36<>"",1_Proyectos!L20>Parámetros!$D$36))),"F1 en Sí con monto fuera de rango. ","")&IF(AND(E20="Sí",1_Proyectos!F20=""),"O2 en Sí sin fracción principal. ","")&IF(AND(AD20="Elegible",COUNT(M20:AB20)<16),"Elegible con calificaciones incompletas. ","")&IF(AND(1_Proyectos!F20<>"",COUNTA(1_Proyectos!F20:I20)>N(1_Proyectos!K20)),"Fracción repetida en el registro. ","")&IF(AND(AD20="Elegible",R20=""),"Falta monto o costo total para calcular F5. ","")&IF(AND(A20<>"",1_Proyectos!D20=""),"Falta tipo de proponente. ",""))) | AQ20: =IF(A20="","",IF(AL20<>"",AL20*1000000+N20*10000+O20*100+AI20-ROW()/1000,-ROW())) | AR20: =IF(AQ20="","",COUNTIF($AQ$9:$AQ$58,">"&AQ20)+1)
A21: =IF(1_Proyectos!A21="","",1_Proyectos!A21) | B21: =IF(1_Proyectos!B21="","",1_Proyectos!B21) | C21: =IF(1_Proyectos!F21="","",1_Proyectos!F21) | M21: =IF(1_Proyectos!K21="","",IF(1_Proyectos!K21>=Parámetros!$D$37,3,IF(1_Proyectos!K21>=Parámetros!$D$38,2,1))) | R21: =IF(1_Proyectos!N21="","",IF(1_Proyectos!N21>=Parámetros!$D$39,3,IF(1_Proyectos!N21>=Parámetros!$D$40,2,1))) | AC21: =IF(A21="","",COUNTIF(D21:L21,"Sí")) | AD21: =IF(A21="","",IF(COUNTIF(D21:L21,"No")>0,"No elegible",IF(COUNTIF(D21:L21,"Sí")=9,"Elegible","Pendiente"))) | AE21: =TRIM(IF(D21="No","O1 ","")&IF(E21="No","O2 ","")&IF(F21="No","O3 ","")&IF(G21="No","T1 ","")&IF(H21="No","T2 ","")&IF(I21="No","F1 ","")&IF(J21="No","F2 ","")&IF(K21="No","F3 ","")&IF(L21="No","E1 ","")) | AF21: =IF(AD21="Elegible",SUM(M21,N21),"") | AG21: =IF(AD21="Elegible",SUM(O21,P21),"") | AH21: =IF(AD21="Elegible",SUM(Q21,R21,S21,T21,U21),"") | AI21: =IF(AD21="Elegible",SUM(V21,W21,X21),"") | AJ21: =IF(AD21="Elegible",SUM(Y21,Z21,AA21,AB21),"") | AK21: =IF(AND(AD21="Elegible",COUNT(M21:AB21)=16),SUM(M21:AB21),"") | AL21: =IF(AK21="","",ROUND(SUMPRODUCT($M$8:$AB$8,M21:AB21)/(3*SUM($M$8:$AB$8))*100,1)) | AM21: =IF(AL21="","",IF(AL21>=Parámetros!$D$41,"Alta",IF(AL21>=Parámetros!$D$42,"Media","Baja"))) | AN21: =IF(AL21="","",AR21) | AO21: =IF(A21="","",TRIM(IF(AND(I21="Sí",1_Proyectos!L21<>"",OR(AND(Parámetros!$D$35<>"",1_Proyectos!L21<Parámetros!$D$35),AND(Parámetros!$D$36<>"",1_Proyectos!L21>Parámetros!$D$36))),"F1 en Sí con monto fuera de rango. ","")&IF(AND(E21="Sí",1_Proyectos!F21=""),"O2 en Sí sin fracción principal. ","")&IF(AND(AD21="Elegible",COUNT(M21:AB21)<16),"Elegible con calificaciones incompletas. ","")&IF(AND(1_Proyectos!F21<>"",COUNTA(1_Proyectos!F21:I21)>N(1_Proyectos!K21)),"Fracción repetida en el registro. ","")&IF(AND(AD21="Elegible",R21=""),"Falta monto o costo total para calcular F5. ","")&IF(AND(A21<>"",1_Proyectos!D21=""),"Falta tipo de proponente. ",""))) | AQ21: =IF(A21="","",IF(AL21<>"",AL21*1000000+N21*10000+O21*100+AI21-ROW()/1000,-ROW())) | AR21: =IF(AQ21="","",COUNTIF($AQ$9:$AQ$58,">"&AQ21)+1)
