Workbook

Sheet Guía
A1: Guía para seleccionar los proyectos que financia el Fondo
A2: Fondo Estatal Ambiental y Climático de Baja California Sur (FEAC BCS). Se aplica igual a proyectos del Estado, de los municipios y de la sociedad civil. Basada en los Criterios de elegibilidad de proyectos y en el Decreto del Fondo.
A4: Cómo usar esta herramienta
A5: 1. En la hoja «Evaluación», escriba una fila por proyecto (celdas amarillas).
A6: 2. Paso 1 · Requisitos mínimos: marque Sí o No en cada uno de los 6 requisitos. Si falla uno solo, el proyecto no puede participar.
A7: 3. Paso 2 · Criterios de calificación: si puede participar, califique los 8 criterios de 1 a 3 con la tabla de abajo. Los puntos y la prioridad se calculan solos.
A8: 4. Paso 3: la hoja «Ranking» ordena los proyectos por puntos. El Comité de Evaluación y Seguimiento propone y el Comité Técnico decide con base en ese orden y en el presupuesto.
A9: Las filas EJ-1 a EJ-4 son ejemplos; bórrelas antes de evaluar proyectos reales.
A11: Paso 1. Requisitos mínimos (Sí / No)
A12: # | B12: Requisito | C12: Qué se revisa | D12: Se cumple cuando… | E12: Documentos
A13: 1 | B13: Pertenece a un tema del Fondo | C13: Que el proyecto atienda directamente uno de los 16 fines del Fondo (artículo 4 del Decreto). | D13: El objetivo del proyecto atiende directamente uno de los 16 temas y cumple el requisito de ese tema (ver lista de temas). | E13: Descripción del proyecto y documento que acredite el requisito del tema.
A14: 2 | B14: Beneficio ambiental y social | C14: Que el proyecto genere un beneficio ambiental positivo y medible, y que identifique a quién beneficia. | D14: Describe al menos un beneficio ambiental positivo con un indicador, su valor actual y su meta (por ejemplo, hectáreas restauradas, toneladas de residuos recicladas), y dice qué personas o comunidades se benefician. | E14: Tabla de indicadores con valor actual y meta; descripción de beneficiarios.
A15: 3 | B15: Ubicación y respaldo institucional | C15: Que se realice en BCS, con apoyo de la autoridad competente y certeza sobre el terreno. | D15: Señala su área de influencia o de aplicación dentro del Estado, tiene carta de apoyo de la autoridad con atribuciones para autorizarlo y, si hay obra o intervención física, acredita la propiedad, el permiso del dueño o un convenio. | E15: Mapa o ubicación; carta de apoyo; títulos, acuerdo ejidal o convenio.
A16: 4 | B16: Propuesta completa | C16: Que la propuesta defina su objeto, qué se hará, cuánto cuesta y en cuánto tiempo. | D16: Precisa su objeto; tiene un apartado técnico-operativo y uno técnico-financiero con análisis costo-beneficio; incluye plan de trabajo, cronograma y un esquema de prioridades y contingencias. | E16: Documento técnico, presupuesto, análisis costo-beneficio, plan de trabajo y cronograma.
A17: 5 | B17: No causa daño ambiental | C17: Que evite daños al ambiente o a terceros y cuente con los permisos necesarios o un plan para obtenerlos. | D17: Identifica posibles daños y cómo evitarlos, y tiene los permisos ambientales que necesita o un plan para obtenerlos. | E17: Análisis de impactos; permisos o plan para tramitarlos.
A18: 6 | B18: Proponente en regla | C18: Que el proponente tenga su documentación en orden, pida un monto dentro del rango y no reciba otro apoyo para lo mismo. | D18: Entrega el soporte documental de su situación legal, financiera y fiscal; el monto está dentro del rango; declara que no tiene otro apoyo para lo mismo y que el proyecto no está ya hecho; y establece cómo informará sus avances (al menos cada trimestre). | E18: Acta constitutiva o nombramiento, RFC, opinión fiscal, declaraciones firmadas.
A20: Paso 2. Criterios de calificación (1 a 3 puntos; total de 10 a 30)
A21: # | B21: Criterio | C21: Qué se evalúa | D21: Peso | E21: 3 · Alto | F21: 2 · Medio | G21: 1 · Bajo
A22: A | B22: Impacto | C22: Magnitud del beneficio ambiental y social frente al tamaño del problema que atiende. | D22: x2 | E22: Resultado grande y cuantificado frente al tamaño del problema; o atiende varios temas del Fondo a la vez; o se puede repetir en otros lugares del Estado. | F22: Resultado medible, pero local o parcial. | G22: Resultado pequeño o solo demostrativo.
A23: B | B23: Atención a población vulnerable | C23: Grado en que beneficia a población o zonas vulnerables (rurales, costeras, de alto riesgo o de bajos ingresos). | D23: x2 | E23: Se ubica en una zona rural, costera, de alto riesgo o de bajos ingresos documentada (atlas de riesgos, índices oficiales) y se enfoca en ella. | F23: Atiende zonas o grupos vulnerables, pero sin un diagnóstico que lo demuestre. | G23: No se enfoca en población ni zonas vulnerables.
A24: C | B24: Factibilidad | C24: Viabilidad técnica, administrativa y legal: madurez del proyecto, experiencia del proponente y manejo de riesgos y obstáculos. | D24: x1 | E24: Proyecto ejecutivo o muy avanzado; el proponente ya hizo proyectos parecidos; los riesgos y obstáculos están identificados y tienen solución. | F24: Anteproyecto; experiencia parcial; riesgos identificados sin soluciones claras. | G24: Es solo una idea; sin experiencia; riesgos u obstáculos serios sin atender.
A25: D | B25: Costo-efectividad | C25: Viabilidad financiera: costo de cada unidad de resultado comparado con otras opciones. | D25: x1 | E25: Calcula cuánto cuesta cada unidad de resultado (por ejemplo, pesos por hectárea) y es igual o menor que otras opciones. | F25: Calcula el costo por resultado, pero no lo compara. | G25: No calcula el costo por resultado.
A26: E | B26: Sostenibilidad | C26: Aportaciones de otras fuentes y compromiso de operar y mantener el proyecto al terminar el apoyo. | D26: x1 | E26: Otras fuentes aportan dinero y alguien se compromete por escrito a operarlo y mantenerlo. | F26: Solo una de las dos cosas. | G26: Depende totalmente del Fondo.
A27: F | B27: Medición de resultados | C27: Evidencia que respalda los beneficios y plan para medirlos y reportarlos. | D27: x1 | E27: Se basa en datos o estudios y tiene plan de monitoreo con valor actual, metas, responsables y presupuesto. | F27: Tiene indicadores y metas, pero el plan está incompleto. | G27: Solo reporta actividades realizadas.
A28: G | B28: Participación e inclusión | C28: Participación de la comunidad e inclusión de mujeres, jóvenes, pueblos indígenas y personas con discapacidad. | D28: x1 | E28: La comunidad participó en el diseño y hay acciones y metas para esos grupos. | F28: Hubo consulta puntual o la inclusión se menciona en general. | G28: Diseño sin la comunidad y sin acciones de inclusión.
A29: H | B29: Alianzas | C29: Colaboración con academia y otros sectores (gobierno, empresas, sociedad civil). | D29: x1 | E29: Convenios con academia u otros sectores (gobierno, empresas, sociedad civil) con papel definido. | F29: Alianzas informales o con un solo sector. | G29: Sin aliados.
A30: Si no hay evidencia, se califica con 1. Los criterios con peso x2 se multiplican por 2 al sumar.
A32: Prioridad según los puntos
B33: Prioridad | C33: Puntos | D33: Qué significa
B34: Alta | C34: 24 a 30 | D34: Candidato a financiarse primero
B35: Media | C35: 18 a 23 | D35: Se financia si alcanza el presupuesto o con ajustes
B36: Baja | C36: 10 a 17 | D36: Se le explica qué mejorar para otra convocatoria
A37: Empates: gana el que tiene más puntos en Impacto; si siguen empatados, el que tiene más en Atención a población vulnerable.
A39: Los 16 temas del Fondo (artículo 4 del Decreto)
A40: El artículo 4 del Decreto que crea el Fondo dice en qué puede invertir: 16 fines o temas (fracciones I a XVI).
A41: Fracción | B41: Tema | C41: Lo que pide ese tema (requisito 1) | D41: Cómo se mide el beneficio (requisito 2 y criterio Impacto)
A42: I | B42: Adaptación al cambio climático | C42: Se hace en comunidad rural, costera o zona de alto riesgo, o atiende a un grupo vulnerable, con base en un diagnóstico o atlas de riesgos | D42: Personas u hogares menos vulnerables
A43: II | B43: Reducción de emisiones | C43: Calcula las emisiones actuales y cuánto se reducirán | D43: Toneladas de CO2 evitadas por año
A44: III | B44: Resiliencia e infraestructura resiliente | C44: Considera escenarios de clima o riesgo en el diseño; si es obra, tiene proyecto ejecutivo o plan para hacerlo | D44: Población y bienes protegidos
A45: IV | B45: Conservación y restauración de ecosistemas | C45: Superficie delimitada y acuerdo con dueños o ejidos; si está en un área protegida, sigue su programa de manejo | D45: Hectáreas conservadas o restauradas
...

Sheet Evaluación
A1: Evaluación de proyectos
A2: Escriba solo en las celdas amarillas. Lo gris se calcula solo. Los requisitos, criterios y niveles completos están en la hoja «Guía».
I4: Paso 1 · Requisitos mínimos (Sí / No) | Q4: Paso 2 · Criterios de calificación (1 · 2 · 3)
A5: ID | B5: Proyecto | C5: Proponente | D5: Tipo de proponente | E5: Tipo de proyecto | F5: Tipo de apoyo | G5: Tema (fracción) | H5: Monto solicitado (MXN) | I5: R1. Pertenece a un tema del Fondo | J5: R2. Beneficio ambiental y social | K5: R3. Ubicación y respaldo institucional | L5: R4. Propuesta completa | M5: R5. No causa daño ambiental | N5: R6. Proponente en regla | O5: ¿Puede participar? | P5: Requisitos que no cumple | Q5: A. Impacto (x2) | R5: B. Atención a población vulnerable (x2) | S5: C. Factibilidad | T5: D. Costo-efectividad | U5: E. Sostenibilidad | V5: F. Medición de resultados | W5: G. Participación e inclusión | X5: H. Alianzas | Y5: Puntos (de 30) | Z5: Prioridad | AA5: Lugar | AB5: Comentarios | AC5: aux
I6: Que el proyecto atienda directamente uno de los 16 fines del Fondo (artículo 4 del Decreto). | J6: Que el proyecto genere un beneficio ambiental positivo y medible, y que identifique a quién beneficia. | K6: Que se realice en BCS, con apoyo de la autoridad competente y certeza sobre el terreno. | L6: Que la propuesta defina su objeto, qué se hará, cuánto cuesta y en cuánto tiempo. | M6: Que evite daños al ambiente o a terceros y cuente con los permisos necesarios o un plan para obtenerlos. | N6: Que el proponente tenga su documentación en orden, pida un monto dentro del rango y no reciba otro apoyo para lo mismo. | Q6: Magnitud del beneficio ambiental y social frente al tamaño del problema que atiende. | R6: Grado en que beneficia a población o zonas vulnerables (rurales, costeras, de alto riesgo o de bajos ingresos). | S6: Viabilidad técnica, administrativa y legal: madurez del proyecto, experiencia del proponente y manejo de riesgos y obstáculos. | T6: Viabilidad financiera: costo de cada unidad de resultado comparado con otras opciones. | U6: Aportaciones de otras fuentes y compromiso de operar y mantener el proyecto al terminar el apoyo. | V6: Evidencia que respalda los beneficios y plan para medirlos y reportarlos. | W6: Participación de la comunidad e inclusión de mujeres, jóvenes, pueblos indígenas y personas con discapacidad. | X6: Colaboración con academia y otros sectores (gobierno, empresas, sociedad civil).
A7: EJ-1 | B7: Restauración de manglar en laguna costera (ejemplo) | C7: OSC local (ejemplo) | D7: Sociedad civil (OSC) | E7: Obra o infraestructura | F7: Financiero: aportación a fondo perdido | G7: IV | H7: 2500000 | I7: Sí | J7: Sí | K7: Sí | L7: Sí | M7: Sí | N7: Sí | O7: =IF(A7="","",IF(COUNTIF(I7:N7,"No")>0,"No",IF(COUNTIF(I7:N7,"Sí")=6,"Sí","Falta información"))) -> Sí | P7: =TRIM(IF(I7="No","R1 ","")&IF(J7="No","R2 ","")&IF(K7="No","R3 ","")&IF(L7="No","R4 ","")&IF(M7="No","R5 ","")&IF(N7="No","R6 ","")) | Q7: 3 | R7: 3 | S7: 2 | T7: 2 | U7: 2 | V7: 3 | W7: 3 | X7: 3 | Y7: =IF(AND(O7="Sí",COUNT(Q7:X7)=8),2*Q7+2*R7+S7+T7+U7+V7+W7+X7,"") -> 27 | Z7: =IF(Y7="","",IF(Y7>=24,"Alta",IF(Y7>=18,"Media","Baja"))) -> Alta | AA7: =IF(Y7="","",COUNTIF($AC$7:$AC$56,">"&AC7)+1) -> 1 | AB7: Ejemplo: muy buen impacto; reforzar continuidad. | AC7: =IF(A7="","",IF(Y7<>"",Y7*10000+Q7*100+R7-ROW()/1000,-ROW())) -> 270302.99
A8: EJ-2 | B8: Paneles solares en escuelas rurales (ejemplo) | C8: Secretaría estatal (ejemplo) | D8: Gobierno del Estado (dependencia u órgano desconcentrado) | E8: Obra o infraestructura | F8: Financiero: cofinanciamiento | G8: VI | H8: 4000000 | I8: Sí | J8: Sí | K8: Sí | L8: Sí | M8: Sí | N8: Sí | O8: =IF(A8="","",IF(COUNTIF(I8:N8,"No")>0,"No",IF(COUNTIF(I8:N8,"Sí")=6,"Sí","Falta información"))) -> Sí | P8: =TRIM(IF(I8="No","R1 ","")&IF(J8="No","R2 ","")&IF(K8="No","R3 ","")&IF(L8="No","R4 ","")&IF(M8="No","R5 ","")&IF(N8="No","R6 ","")) | Q8: 2 | R8: 2 | S8: 3 | T8: 3 | U8: 3 | V8: 2 | W8: 1 | X8: 2 | Y8: =IF(AND(O8="Sí",COUNT(Q8:X8)=8),2*Q8+2*R8+S8+T8+U8+V8+W8+X8,"") -> 22 | Z8: =IF(Y8="","",IF(Y8>=24,"Alta",IF(Y8>=18,"Media","Baja"))) -> Media | AA8: =IF(Y8="","",COUNTIF($AC$7:$AC$56,">"&AC8)+1) -> 2 | AB8: Ejemplo: viable, pero poca participación de la comunidad. | AC8: =IF(A8="","",IF(Y8<>"",Y8*10000+Q8*100+R8-ROW()/1000,-ROW())) -> 220201.99
A9: EJ-3 | B9: Planta municipal de composta (ejemplo) | C9: Ayuntamiento (ejemplo) | D9: Municipio | E9: Obra o infraestructura | F9: Financiero: cofinanciamiento | G9: IX | H9: 3000000 | I9: Sí | J9: Sí | K9: Sí | L9: Sí | M9: Sí | N9: Sí | O9: =IF(A9="","",IF(COUNTIF(I9:N9,"No")>0,"No",IF(COUNTIF(I9:N9,"Sí")=6,"Sí","Falta información"))) -> Sí | P9: =TRIM(IF(I9="No","R1 ","")&IF(J9="No","R2 ","")&IF(K9="No","R3 ","")&IF(L9="No","R4 ","")&IF(M9="No","R5 ","")&IF(N9="No","R6 ","")) | Q9: 2 | R9: 1 | S9: 2 | T9: 2 | U9: 2 | V9: 2 | W9: 2 | X9: 1 | Y9: =IF(AND(O9="Sí",COUNT(Q9:X9)=8),2*Q9+2*R9+S9+T9+U9+V9+W9+X9,"") -> 17 | Z9: =IF(Y9="","",IF(Y9>=24,"Alta",IF(Y9>=18,"Media","Baja"))) -> Baja | AA9: =IF(Y9="","",COUNTIF($AC$7:$AC$56,">"&AC9)+1) -> 3 | AB9: Ejemplo: cumple, pero no se enfoca en zonas vulnerables. | AC9: =IF(A9="","",IF(Y9<>"",Y9*10000+Q9*100+R9-ROW()/1000,-ROW())) -> 170200.99
A10: EJ-4 | B10: Campaña en redes sociales (ejemplo) | C10: OSC (ejemplo) | D10: Sociedad civil (OSC) | E10: Capacitación o educación | F10: Financiero: aportación a fondo perdido | G10: X | H10: 600000 | I10: Sí | J10: No | K10: Sí | L10: Sí | M10: Sí | N10: Sí | O10: =IF(A10="","",IF(COUNTIF(I10:N10,"No")>0,"No",IF(COUNTIF(I10:N10,"Sí")=6,"Sí","Falta información"))) -> No | P10: =TRIM(IF(I10="No","R1 ","")&IF(J10="No","R2 ","")&IF(K10="No","R3 ","")&IF(L10="No","R4 ","")&IF(M10="No","R5 ","")&IF(N10="No","R6 ","")) -> R2 | Y10: =IF(AND(O10="Sí",COUNT(Q10:X10)=8),2*Q10+2*R10+S10+T10+U10+V10+W10+X10,"") | Z10: =IF(Y10="","",IF(Y10>=24,"Alta",IF(Y10>=18,"Media","Baja"))) | AA10: =IF(Y10="","",COUNTIF($AC$7:$AC$56,">"&AC10)+1) | AB10: Ejemplo: no define un beneficio medible (requisito 2). | AC10: =IF(A10="","",IF(Y10<>"",Y10*10000+Q10*100+R10-ROW()/1000,-ROW())) -> -10
O11: =IF(A11="","",IF(COUNTIF(I11:N11,"No")>0,"No",IF(COUNTIF(I11:N11,"Sí")=6,"Sí","Falta información"))) | P11: =TRIM(IF(I11="No","R1 ","")&IF(J11="No","R2 ","")&IF(K11="No","R3 ","")&IF(L11="No","R4 ","")&IF(M11="No","R5 ","")&IF(N11="No","R6 ","")) | Y11: =IF(AND(O11="Sí",COUNT(Q11:X11)=8),2*Q11+2*R11+S11+T11+U11+V11+W11+X11,"") | Z11: =IF(Y11="","",IF(Y11>=24,"Alta",IF(Y11>=18,"Media","Baja"))) | AA11: =IF(Y11="","",COUNTIF($AC$7:$AC$56,">"&AC11)+1) | AC11: =IF(A11="","",IF(Y11<>"",Y11*10000+Q11*100+R11-ROW()/1000,-ROW()))
O12: =IF(A12="","",IF(COUNTIF(I12:N12,"No")>0,"No",IF(COUNTIF(I12:N12,"Sí")=6,"Sí","Falta información"))) | P12: =TRIM(IF(I12="No","R1 ","")&IF(J12="No","R2 ","")&IF(K12="No","R3 ","")&IF(L12="No","R4 ","")&IF(M12="No","R5 ","")&IF(N12="No","R6 ","")) | Y12: =IF(AND(O12="Sí",COUNT(Q12:X12)=8),2*Q12+2*R12+S12+T12+U12+V12+W12+X12,"") | Z12: =IF(Y12="","",IF(Y12>=24,"Alta",IF(Y12>=18,"Media","Baja"))) | AA12: =IF(Y12="","",COUNTIF($AC$7:$AC$56,">"&AC12)+1) | AC12: =IF(A12="","",IF(Y12<>"",Y12*10000+Q12*100+R12-ROW()/1000,-ROW()))
O13: =IF(A13="","",IF(COUNTIF(I13:N13,"No")>0,"No",IF(COUNTIF(I13:N13,"Sí")=6,"Sí","Falta información"))) | P13: =TRIM(IF(I13="No","R1 ","")&IF(J13="No","R2 ","")&IF(K13="No","R3 ","")&IF(L13="No","R4 ","")&IF(M13="No","R5 ","")&IF(N13="No","R6 ","")) | Y13: =IF(AND(O13="Sí",COUNT(Q13:X13)=8),2*Q13+2*R13+S13+T13+U13+V13+W13+X13,"") | Z13: =IF(Y13="","",IF(Y13>=24,"Alta",IF(Y13>=18,"Media","Baja"))) | AA13: =IF(Y13="","",COUNTIF($AC$7:$AC$56,">"&AC13)+1) | AC13: =IF(A13="","",IF(Y13<>"",Y13*10000+Q13*100+R13-ROW()/1000,-ROW()))
O14: =IF(A14="","",IF(COUNTIF(I14:N14,"No")>0,"No",IF(COUNTIF(I14:N14,"Sí")=6,"Sí","Falta información"))) | P14: =TRIM(IF(I14="No","R1 ","")&IF(J14="No","R2 ","")&IF(K14="No","R3 ","")&IF(L14="No","R4 ","")&IF(M14="No","R5 ","")&IF(N14="No","R6 ","")) | Y14: =IF(AND(O14="Sí",COUNT(Q14:X14)=8),2*Q14+2*R14+S14+T14+U14+V14+W14+X14,"") | Z14: =IF(Y14="","",IF(Y14>=24,"Alta",IF(Y14>=18,"Media","Baja"))) | AA14: =IF(Y14="","",COUNTIF($AC$7:$AC$56,">"&AC14)+1) | AC14: =IF(A14="","",IF(Y14<>"",Y14*10000+Q14*100+R14-ROW()/1000,-ROW()))
O15: =IF(A15="","",IF(COUNTIF(I15:N15,"No")>0,"No",IF(COUNTIF(I15:N15,"Sí")=6,"Sí","Falta información"))) | P15: =TRIM(IF(I15="No","R1 ","")&IF(J15="No","R2 ","")&IF(K15="No","R3 ","")&IF(L15="No","R4 ","")&IF(M15="No","R5 ","")&IF(N15="No","R6 ","")) | Y15: =IF(AND(O15="Sí",COUNT(Q15:X15)=8),2*Q15+2*R15+S15+T15+U15+V15+W15+X15,"") | Z15: =IF(Y15="","",IF(Y15>=24,"Alta",IF(Y15>=18,"Media","Baja"))) | AA15: =IF(Y15="","",COUNTIF($AC$7:$AC$56,">"&AC15)+1) | AC15: =IF(A15="","",IF(Y15<>"",Y15*10000+Q15*100+R15-ROW()/1000,-ROW()))
O16: =IF(A16="","",IF(COUNTIF(I16:N16,"No")>0,"No",IF(COUNTIF(I16:N16,"Sí")=6,"Sí","Falta información"))) | P16: =TRIM(IF(I16="No","R1 ","")&IF(J16="No","R2 ","")&IF(K16="No","R3 ","")&IF(L16="No","R4 ","")&IF(M16="No","R5 ","")&IF(N16="No","R6 ","")) | Y16: =IF(AND(O16="Sí",COUNT(Q16:X16)=8),2*Q16+2*R16+S16+T16+U16+V16+W16+X16,"") | Z16: =IF(Y16="","",IF(Y16>=24,"Alta",IF(Y16>=18,"Media","Baja"))) | AA16: =IF(Y16="","",COUNTIF($AC$7:$AC$56,">"&AC16)+1) | AC16: =IF(A16="","",IF(Y16<>"",Y16*10000+Q16*100+R16-ROW()/1000,-ROW()))
O17: =IF(A17="","",IF(COUNTIF(I17:N17,"No")>0,"No",IF(COUNTIF(I17:N17,"Sí")=6,"Sí","Falta información"))) | P17: =TRIM(IF(I17="No","R1 ","")&IF(J17="No","R2 ","")&IF(K17="No","R3 ","")&IF(L17="No","R4 ","")&IF(M17="No","R5 ","")&IF(N17="No","R6 ","")) | Y17: =IF(AND(O17="Sí",COUNT(Q17:X17)=8),2*Q17+2*R17+S17+T17+U17+V17+W17+X17,"") | Z17: =IF(Y17="","",IF(Y17>=24,"Alta",IF(Y17>=18,"Media","Baja"))) | AA17: =IF(Y17="","",COUNTIF($AC$7:$AC$56,">"&AC17)+1) | AC17: =IF(A17="","",IF(Y17<>"",Y17*10000+Q17*100+R17-ROW()/1000,-ROW()))
O18: =IF(A18="","",IF(COUNTIF(I18:N18,"No")>0,"No",IF(COUNTIF(I18:N18,"Sí")=6,"Sí","Falta información"))) | P18: =TRIM(IF(I18="No","R1 ","")&IF(J18="No","R2 ","")&IF(K18="No","R3 ","")&IF(L18="No","R4 ","")&IF(M18="No","R5 ","")&IF(N18="No","R6 ","")) | Y18: =IF(AND(O18="Sí",COUNT(Q18:X18)=8),2*Q18+2*R18+S18+T18+U18+V18+W18+X18,"") | Z18: =IF(Y18="","",IF(Y18>=24,"Alta",IF(Y18>=18,"Media","Baja"))) | AA18: =IF(Y18="","",COUNTIF($AC$7:$AC$56,">"&AC18)+1) | AC18: =IF(A18="","",IF(Y18<>"",Y18*10000+Q18*100+R18-ROW()/1000,-ROW()))
O19: =IF(A19="","",IF(COUNTIF(I19:N19,"No")>0,"No",IF(COUNTIF(I19:N19,"Sí")=6,"Sí","Falta información"))) | P19: =TRIM(IF(I19="No","R1 ","")&IF(J19="No","R2 ","")&IF(K19="No","R3 ","")&IF(L19="No","R4 ","")&IF(M19="No","R5 ","")&IF(N19="No","R6 ","")) | Y19: =IF(AND(O19="Sí",COUNT(Q19:X19)=8),2*Q19+2*R19+S19+T19+U19+V19+W19+X19,"") | Z19: =IF(Y19="","",IF(Y19>=24,"Alta",IF(Y19>=18,"Media","Baja"))) | AA19: =IF(Y19="","",COUNTIF($AC$7:$AC$56,">"&AC19)+1) | AC19: =IF(A19="","",IF(Y19<>"",Y19*10000+Q19*100+R19-ROW()/1000,-ROW()))
O20: =IF(A20="","",IF(COUNTIF(I20:N20,"No")>0,"No",IF(COUNTIF(I20:N20,"Sí")=6,"Sí","Falta información"))) | P20: =TRIM(IF(I20="No","R1 ","")&IF(J20="No","R2 ","")&IF(K20="No","R3 ","")&IF(L20="No","R4 ","")&IF(M20="No","R5 ","")&IF(N20="No","R6 ","")) | Y20: =IF(AND(O20="Sí",COUNT(Q20:X20)=8),2*Q20+2*R20+S20+T20+U20+V20+W20+X20,"") | Z20: =IF(Y20="","",IF(Y20>=24,"Alta",IF(Y20>=18,"Media","Baja"))) | AA20: =IF(Y20="","",COUNTIF($AC$7:$AC$56,">"&AC20)+1) | AC20: =IF(A20="","",IF(Y20<>"",Y20*10000+Q20*100+R20-ROW()/1000,-ROW()))
O21: =IF(A21="","",IF(COUNTIF(I21:N21,"No")>0,"No",IF(COUNTIF(I21:N21,"Sí")=6,"Sí","Falta información"))) | P21: =TRIM(IF(I21="No","R1 ","")&IF(J21="No","R2 ","")&IF(K21="No","R3 ","")&IF(L21="No","R4 ","")&IF(M21="No","R5 ","")&IF(N21="No","R6 ","")) | Y21: =IF(AND(O21="Sí",COUNT(Q21:X21)=8),2*Q21+2*R21+S21+T21+U21+V21+W21+X21,"") | Z21: =IF(Y21="","",IF(Y21>=24,"Alta",IF(Y21>=18,"Media","Baja"))) | AA21: =IF(Y21="","",COUNTIF($AC$7:$AC$56,">"&AC21)+1) | AC21: =IF(A21="","",IF(Y21<>"",Y21*10000+Q21*100+R21-ROW()/1000,-ROW()))
O22: =IF(A22="","",IF(COUNTIF(I22:N22,"No")>0,"No",IF(COUNTIF(I22:N22,"Sí")=6,"Sí","Falta información"))) | P22: =TRIM(IF(I22="No","R1 ","")&IF(J22="No","R2 ","")&IF(K22="No","R3 ","")&IF(L22="No","R4 ","")&IF(M22="No","R5 ","")&IF(N22="No","R6 ","")) | Y22: =IF(AND(O22="Sí",COUNT(Q22:X22)=8),2*Q22+2*R22+S22+T22+U22+V22+W22+X22,"") | Z22: =IF(Y22="","",IF(Y22>=24,"Alta",IF(Y22>=18,"Media","Baja"))) | AA22: =IF(Y22="","",COUNTIF($AC$7:$AC$56,">"&AC22)+1) | AC22: =IF(A22="","",IF(Y22<>"",Y22*10000+Q22*100+R22-ROW()/1000,-ROW()))
... O56: =IF(A56="","",IF(COUNTIF(I56:N56,"No")>0,"No",IF(COUNTIF(I56:N56,"Sí")=6,"Sí","Falta información"))) | P56: =TRIM(IF(I56="No","R1 ","")&IF(J56="No","R2 ","")&IF(K56="No","R3 ","")&IF(L56="No","R4 ","")&IF(M56="No","R5 ","")&IF(N56="No","R6 ","")) | Y56: =IF(AND(O56="Sí",COUNT(Q56:X56)=8),2*Q56+2*R56+S56+T56+U56+V56+W56+X56,"") | Z56: =IF(Y56="","",IF(Y56>=24,"Alta",IF(Y56>=18,"Media","Baja"))) | AA56: =IF(Y56="","",COUNTIF($AC$7:$AC$56,">"&AC56)+1) | AC56: =IF(A56="","",IF(Y56<>"",Y56*10000+Q56*100+R56-ROW()/1000,-ROW()))

Sheet Ranking
A1: Ranking de proyectos
A2: Se ordena solo: primero los que pueden participar, de más a menos puntos; después los que no pueden participar o a los que les falta información.
A4: Proyectos registrados | C4: =COUNTIF(Evaluación!$A$7:$A$56,"?*") -> 4
A5: Pueden participar | C5: =COUNTIF(Evaluación!$O$7:$O$56,"Sí") -> 3
A6: No pueden participar | C6: =COUNTIF(Evaluación!$O$7:$O$56,"No") -> 1
A7: Les falta información | C7: =COUNTIF(Evaluación!$O$7:$O$56,"Falta información") -> 0
A8: Prioridad alta | C8: =COUNTIF(Evaluación!$Z$7:$Z$56,"Alta") -> 1
A9: Prioridad media | C9: =COUNTIF(Evaluación!$Z$7:$Z$56,"Media") -> 1
A10: Prioridad baja | C10: =COUNTIF(Evaluación!$Z$7:$Z$56,"Baja") -> 1
A11: Monto de los de prioridad alta (MXN) | C11: =SUMIF(Evaluación!$Z$7:$Z$56,"Alta",Evaluación!$H$7:$H$56) -> 2500000
A14: Lugar | B14: Proyecto | C14: Proponente | D14: Tipo | E14: Tema | F14: Monto (MXN) | G14: Puntos | H14: Prioridad | I14: ¿Puede participar? | J14: No cumple requisitos | K14: _fila
A15: =IF(K15="","",IF(INDEX(Evaluación!$AA$7:$AA$56,K15)="","—",INDEX(Evaluación!$AA$7:$AA$56,K15))) -> 1 | B15: =IF($K15="","",IF(INDEX(Evaluación!$B$7:$B$56,$K15)="","",INDEX(Evaluación!$B$7:$B$56,$K15))) -> Restauración de manglar en laguna costera (ejemplo) | C15: =IF($K15="","",IF(INDEX(Evaluación!$C$7:$C$56,$K15)="","",INDEX(Evaluación!$C$7:$C$56,$K15))) -> OSC local (ejemplo) | D15: =IF($K15="","",IF(INDEX(Evaluación!$D$7:$D$56,$K15)="","",INDEX(Evaluación!$D$7:$D$56,$K15))) -> Sociedad civil (OSC) | E15: =IF($K15="","",IF(INDEX(Evaluación!$G$7:$G$56,$K15)="","",INDEX(Evaluación!$G$7:$G$56,$K15))) -> IV | F15: =IF($K15="","",IF(INDEX(Evaluación!$H$7:$H$56,$K15)="","",INDEX(Evaluación!$H$7:$H$56,$K15))) -> 2500000 | G15: =IF($K15="","",IF(INDEX(Evaluación!$Y$7:$Y$56,$K15)="","",INDEX(Evaluación!$Y$7:$Y$56,$K15))) -> 27 | H15: =IF($K15="","",IF(INDEX(Evaluación!$Z$7:$Z$56,$K15)="","",INDEX(Evaluación!$Z$7:$Z$56,$K15))) -> Alta | I15: =IF($K15="","",IF(INDEX(Evaluación!$O$7:$O$56,$K15)="","",INDEX(Evaluación!$O$7:$O$56,$K15))) -> Sí | J15: =IF($K15="","",IF(INDEX(Evaluación!$P$7:$P$56,$K15)="","",INDEX(Evaluación!$P$7:$P$56,$K15))) | K15: =IFERROR(MATCH(LARGE(Evaluación!$AC$7:$AC$56,1),Evaluación!$AC$7:$AC$56,0),"") -> 1
A16: =IF(K16="","",IF(INDEX(Evaluación!$AA$7:$AA$56,K16)="","—",INDEX(Evaluación!$AA$7:$AA$56,K16))) -> 2 | B16: =IF($K16="","",IF(INDEX(Evaluación!$B$7:$B$56,$K16)="","",INDEX(Evaluación!$B$7:$B$56,$K16))) -> Paneles solares en escuelas rurales (ejemplo) | C16: =IF($K16="","",IF(INDEX(Evaluación!$C$7:$C$56,$K16)="","",INDEX(Evaluación!$C$7:$C$56,$K16))) -> Secretaría estatal (ejemplo) | D16: =IF($K16="","",IF(INDEX(Evaluación!$D$7:$D$56,$K16)="","",INDEX(Evaluación!$D$7:$D$56,$K16))) -> Gobierno del Estado (dependencia u órgano desconcentrado) | E16: =IF($K16="","",IF(INDEX(Evaluación!$G$7:$G$56,$K16)="","",INDEX(Evaluación!$G$7:$G$56,$K16))) -> VI | F16: =IF($K16="","",IF(INDEX(Evaluación!$H$7:$H$56,$K16)="","",INDEX(Evaluación!$H$7:$H$56,$K16))) -> 4000000 | G16: =IF($K16="","",IF(INDEX(Evaluación!$Y$7:$Y$56,$K16)="","",INDEX(Evaluación!$Y$7:$Y$56,$K16))) -> 22 | H16: =IF($K16="","",IF(INDEX(Evaluación!$Z$7:$Z$56,$K16)="","",INDEX(Evaluación!$Z$7:$Z$56,$K16))) -> Media | I16: =IF($K16="","",IF(INDEX(Evaluación!$O$7:$O$56,$K16)="","",INDEX(Evaluación!$O$7:$O$56,$K16))) -> Sí | J16: =IF($K16="","",IF(INDEX(Evaluación!$P$7:$P$56,$K16)="","",INDEX(Evaluación!$P$7:$P$56,$K16))) | K16: =IFERROR(MATCH(LARGE(Evaluación!$AC$7:$AC$56,2),Evaluación!$AC$7:$AC$56,0),"") -> 2
A17: =IF(K17="","",IF(INDEX(Evaluación!$AA$7:$AA$56,K17)="","—",INDEX(Evaluación!$AA$7:$AA$56,K17))) -> 3 | B17: =IF($K17="","",IF(INDEX(Evaluación!$B$7:$B$56,$K17)="","",INDEX(Evaluación!$B$7:$B$56,$K17))) -> Planta municipal de composta (ejemplo) | C17: =IF($K17="","",IF(INDEX(Evaluación!$C$7:$C$56,$K17)="","",INDEX(Evaluación!$C$7:$C$56,$K17))) -> Ayuntamiento (ejemplo) | D17: =IF($K17="","",IF(INDEX(Evaluación!$D$7:$D$56,$K17)="","",INDEX(Evaluación!$D$7:$D$56,$K17))) -> Municipio | E17: =IF($K17="","",IF(INDEX(Evaluación!$G$7:$G$56,$K17)="","",INDEX(Evaluación!$G$7:$G$56,$K17))) -> IX | F17: =IF($K17="","",IF(INDEX(Evaluación!$H$7:$H$56,$K17)="","",INDEX(Evaluación!$H$7:$H$56,$K17))) -> 3000000 | G17: =IF($K17="","",IF(INDEX(Evaluación!$Y$7:$Y$56,$K17)="","",INDEX(Evaluación!$Y$7:$Y$56,$K17))) -> 17 | H17: =IF($K17="","",IF(INDEX(Evaluación!$Z$7:$Z$56,$K17)="","",INDEX(Evaluación!$Z$7:$Z$56,$K17))) -> Baja | I17: =IF($K17="","",IF(INDEX(Evaluación!$O$7:$O$56,$K17)="","",INDEX(Evaluación!$O$7:$O$56,$K17))) -> Sí | J17: =IF($K17="","",IF(INDEX(Evaluación!$P$7:$P$56,$K17)="","",INDEX(Evaluación!$P$7:$P$56,$K17))) | K17: =IFERROR(MATCH(LARGE(Evaluación!$AC$7:$AC$56,3),Evaluación!$AC$7:$AC$56,0),"") -> 3
A18: =IF(K18="","",IF(INDEX(Evaluación!$AA$7:$AA$56,K18)="","—",INDEX(Evaluación!$AA$7:$AA$56,K18))) -> — | B18: =IF($K18="","",IF(INDEX(Evaluación!$B$7:$B$56,$K18)="","",INDEX(Evaluación!$B$7:$B$56,$K18))) -> Campaña en redes sociales (ejemplo) | C18: =IF($K18="","",IF(INDEX(Evaluación!$C$7:$C$56,$K18)="","",INDEX(Evaluación!$C$7:$C$56,$K18))) -> OSC (ejemplo) | D18: =IF($K18="","",IF(INDEX(Evaluación!$D$7:$D$56,$K18)="","",INDEX(Evaluación!$D$7:$D$56,$K18))) -> Sociedad civil (OSC) | E18: =IF($K18="","",IF(INDEX(Evaluación!$G$7:$G$56,$K18)="","",INDEX(Evaluación!$G$7:$G$56,$K18))) -> X | F18: =IF($K18="","",IF(INDEX(Evaluación!$H$7:$H$56,$K18)="","",INDEX(Evaluación!$H$7:$H$56,$K18))) -> 600000 | G18: =IF($K18="","",IF(INDEX(Evaluación!$Y$7:$Y$56,$K18)="","",INDEX(Evaluación!$Y$7:$Y$56,$K18))) | H18: =IF($K18="","",IF(INDEX(Evaluación!$Z$7:$Z$56,$K18)="","",INDEX(Evaluación!$Z$7:$Z$56,$K18))) | I18: =IF($K18="","",IF(INDEX(Evaluación!$O$7:$O$56,$K18)="","",INDEX(Evaluación!$O$7:$O$56,$K18))) -> No | J18: =IF($K18="","",IF(INDEX(Evaluación!$P$7:$P$56,$K18)="","",INDEX(Evaluación!$P$7:$P$56,$K18))) -> R2 | K18: =IFERROR(MATCH(LARGE(Evaluación!$AC$7:$AC$56,4),Evaluación!$AC$7:$AC$56,0),"") -> 4
A19: =IF(K19="","",IF(INDEX(Evaluación!$AA$7:$AA$56,K19)="","—",INDEX(Evaluación!$AA$7:$AA$56,K19))) | B19: =IF($K19="","",IF(INDEX(Evaluación!$B$7:$B$56,$K19)="","",INDEX(Evaluación!$B$7:$B$56,$K19))) | C19: =IF($K19="","",IF(INDEX(Evaluación!$C$7:$C$56,$K19)="","",INDEX(Evaluación!$C$7:$C$56,$K19))) | D19: =IF($K19="","",IF(INDEX(Evaluación!$D$7:$D$56,$K19)="","",INDEX(Evaluación!$D$7:$D$56,$K19))) | E19: =IF($K19="","",IF(INDEX(Evaluación!$G$7:$G$56,$K19)="","",INDEX(Evaluación!$G$7:$G$56,$K19))) | F19: =IF($K19="","",IF(INDEX(Evaluación!$H$7:$H$56,$K19)="","",INDEX(Evaluación!$H$7:$H$56,$K19))) | G19: =IF($K19="","",IF(INDEX(Evaluación!$Y$7:$Y$56,$K19)="","",INDEX(Evaluación!$Y$7:$Y$56,$K19))) | H19: =IF($K19="","",IF(INDEX(Evaluación!$Z$7:$Z$56,$K19)="","",INDEX(Evaluación!$Z$7:$Z$56,$K19))) | I19: =IF($K19="","",IF(INDEX(Evaluación!$O$7:$O$56,$K19)="","",INDEX(Evaluación!$O$7:$O$56,$K19))) | J19: =IF($K19="","",IF(INDEX(Evaluación!$P$7:$P$56,$K19)="","",INDEX(Evaluación!$P$7:$P$56,$K19))) | K19: =IFERROR(MATCH(LARGE(Evaluación!$AC$7:$AC$56,5),Evaluación!$AC$7:$AC$56,0),"")
A20: =IF(K20="","",IF(INDEX(Evaluación!$AA$7:$AA$56,K20)="","—",INDEX(Evaluación!$AA$7:$AA$56,K20))) | B20: =IF($K20="","",IF(INDEX(Evaluación!$B$7:$B$56,$K20)="","",INDEX(Evaluación!$B$7:$B$56,$K20))) | C20: =IF($K20="","",IF(INDEX(Evaluación!$C$7:$C$56,$K20)="","",INDEX(Evaluación!$C$7:$C$56,$K20))) | D20: =IF($K20="","",IF(INDEX(Evaluación!$D$7:$D$56,$K20)="","",INDEX(Evaluación!$D$7:$D$56,$K20))) | E20: =IF($K20="","",IF(INDEX(Evaluación!$G$7:$G$56,$K20)="","",INDEX(Evaluación!$G$7:$G$56,$K20))) | F20: =IF($K20="","",IF(INDEX(Evaluación!$H$7:$H$56,$K20)="","",INDEX(Evaluación!$H$7:$H$56,$K20))) | G20: =IF($K20="","",IF(INDEX(Evaluación!$Y$7:$Y$56,$K20)="","",INDEX(Evaluación!$Y$7:$Y$56,$K20))) | H20: =IF($K20="","",IF(INDEX(Evaluación!$Z$7:$Z$56,$K20)="","",INDEX(Evaluación!$Z$7:$Z$56,$K20))) | I20: =IF($K20="","",IF(INDEX(Evaluación!$O$7:$O$56,$K20)="","",INDEX(Evaluación!$O$7:$O$56,$K20))) | J20: =IF($K20="","",IF(INDEX(Evaluación!$P$7:$P$56,$K20)="","",INDEX(Evaluación!$P$7:$P$56,$K20))) | K20: =IFERROR(MATCH(LARGE(Evaluación!$AC$7:$AC$56,6),Evaluación!$AC$7:$AC$56,0),"")
A21: =IF(K21="","",IF(INDEX(Evaluación!$AA$7:$AA$56,K21)="","—",INDEX(Evaluación!$AA$7:$AA$56,K21))) | B21: =IF($K21="","",IF(INDEX(Evaluación!$B$7:$B$56,$K21)="","",INDEX(Evaluación!$B$7:$B$56,$K21))) | C21: =IF($K21="","",IF(INDEX(Evaluación!$C$7:$C$56,$K21)="","",INDEX(Evaluación!$C$7:$C$56,$K21))) | D21: =IF($K21="","",IF(INDEX(Evaluación!$D$7:$D$56,$K21)="","",INDEX(Evaluación!$D$7:$D$56,$K21))) | E21: =IF($K21="","",IF(INDEX(Evaluación!$G$7:$G$56,$K21)="","",INDEX(Evaluación!$G$7:$G$56,$K21))) | F21: =IF($K21="","",IF(INDEX(Evaluación!$H$7:$H$56,$K21)="","",INDEX(Evaluación!$H$7:$H$56,$K21))) | G21: =IF($K21="","",IF(INDEX(Evaluación!$Y$7:$Y$56,$K21)="","",INDEX(Evaluación!$Y$7:$Y$56,$K21))) | H21: =IF($K21="","",IF(INDEX(Evaluación!$Z$7:$Z$56,$K21)="","",INDEX(Evaluación!$Z$7:$Z$56,$K21))) | I21: =IF($K21="","",IF(INDEX(Evaluación!$O$7:$O$56,$K21)="","",INDEX(Evaluación!$O$7:$O$56,$K21))) | J21: =IF($K21="","",IF(INDEX(Evaluación!$P$7:$P$56,$K21)="","",INDEX(Evaluación!$P$7:$P$56,$K21))) | K21: =IFERROR(MATCH(LARGE(Evaluación!$AC$7:$AC$56,7),Evaluación!$AC$7:$AC$56,0),"")
A22: =IF(K22="","",IF(INDEX(Evaluación!$AA$7:$AA$56,K22)="","—",INDEX(Evaluación!$AA$7:$AA$56,K22))) | B22: =IF($K22="","",IF(INDEX(Evaluación!$B$7:$B$56,$K22)="","",INDEX(Evaluación!$B$7:$B$56,$K22))) | C22: =IF($K22="","",IF(INDEX(Evaluación!$C$7:$C$56,$K22)="","",INDEX(Evaluación!$C$7:$C$56,$K22))) | D22: =IF($K22="","",IF(INDEX(Evaluación!$D$7:$D$56,$K22)="","",INDEX(Evaluación!$D$7:$D$56,$K22))) | E22: =IF($K22="","",IF(INDEX(Evaluación!$G$7:$G$56,$K22)="","",INDEX(Evaluación!$G$7:$G$56,$K22))) | F22: =IF($K22="","",IF(INDEX(Evaluación!$H$7:$H$56,$K22)="","",INDEX(Evaluación!$H$7:$H$56,$K22))) | G22: =IF($K22="","",IF(INDEX(Evaluación!$Y$7:$Y$56,$K22)="","",INDEX(Evaluación!$Y$7:$Y$56,$K22))) | H22: =IF($K22="","",IF(INDEX(Evaluación!$Z$7:$Z$56,$K22)="","",INDEX(Evaluación!$Z$7:$Z$56,$K22))) | I22: =IF($K22="","",IF(INDEX(Evaluación!$O$7:$O$56,$K22)="","",INDEX(Evaluación!$O$7:$O$56,$K22))) | J22: =IF($K22="","",IF(INDEX(Evaluación!$P$7:$P$56,$K22)="","",INDEX(Evaluación!$P$7:$P$56,$K22))) | K22: =IFERROR(MATCH(LARGE(Evaluación!$AC$7:$AC$56,8),Evaluación!$AC$7:$AC$56,0),"")
A23: =IF(K23="","",IF(INDEX(Evaluación!$AA$7:$AA$56,K23)="","—",INDEX(Evaluación!$AA$7:$AA$56,K23))) | B23: =IF($K23="","",IF(INDEX(Evaluación!$B$7:$B$56,$K23)="","",INDEX(Evaluación!$B$7:$B$56,$K23))) | C23: =IF($K23="","",IF(INDEX(Evaluación!$C$7:$C$56,$K23)="","",INDEX(Evaluación!$C$7:$C$56,$K23))) | D23: =IF($K23="","",IF(INDEX(Evaluación!$D$7:$D$56,$K23)="","",INDEX(Evaluación!$D$7:$D$56,$K23))) | E23: =IF($K23="","",IF(INDEX(Evaluación!$G$7:$G$56,$K23)="","",INDEX(Evaluación!$G$7:$G$56,$K23))) | F23: =IF($K23="","",IF(INDEX(Evaluación!$H$7:$H$56,$K23)="","",INDEX(Evaluación!$H$7:$H$56,$K23))) | G23: =IF($K23="","",IF(INDEX(Evaluación!$Y$7:$Y$56,$K23)="","",INDEX(Evaluación!$Y$7:$Y$56,$K23))) | H23: =IF($K23="","",IF(INDEX(Evaluación!$Z$7:$Z$56,$K23)="","",INDEX(Evaluación!$Z$7:$Z$56,$K23))) | I23: =IF($K23="","",IF(INDEX(Evaluación!$O$7:$O$56,$K23)="","",INDEX(Evaluación!$O$7:$O$56,$K23))) | J23: =IF($K23="","",IF(INDEX(Evaluación!$P$7:$P$56,$K23)="","",INDEX(Evaluación!$P$7:$P$56,$K23))) | K23: =IFERROR(MATCH(LARGE(Evaluación!$AC$7:$AC$56,9),Evaluación!$AC$7:$AC$56,0),"")
A24: =IF(K24="","",IF(INDEX(Evaluación!$AA$7:$AA$56,K24)="","—",INDEX(Evaluación!$AA$7:$AA$56,K24))) | B24: =IF($K24="","",IF(INDEX(Evaluación!$B$7:$B$56,$K24)="","",INDEX(Evaluación!$B$7:$B$56,$K24))) | C24: =IF($K24="","",IF(INDEX(Evaluación!$C$7:$C$56,$K24)="","",INDEX(Evaluación!$C$7:$C$56,$K24))) | D24: =IF($K24="","",IF(INDEX(Evaluación!$D$7:$D$56,$K24)="","",INDEX(Evaluación!$D$7:$D$56,$K24))) | E24: =IF($K24="","",IF(INDEX(Evaluación!$G$7:$G$56,$K24)="","",INDEX(Evaluación!$G$7:$G$56,$K24))) | F24: =IF($K24="","",IF(INDEX(Evaluación!$H$7:$H$56,$K24)="","",INDEX(Evaluación!$H$7:$H$56,$K24))) | G24: =IF($K24="","",IF(INDEX(Evaluación!$Y$7:$Y$56,$K24)="","",INDEX(Evaluación!$Y$7:$Y$56,$K24))) | H24: =IF($K24="","",IF(INDEX(Evaluación!$Z$7:$Z$56,$K24)="","",INDEX(Evaluación!$Z$7:$Z$56,$K24))) | I24: =IF($K24="","",IF(INDEX(Evaluación!$O$7:$O$56,$K24)="","",INDEX(Evaluación!$O$7:$O$56,$K24))) | J24: =IF($K24="","",IF(INDEX(Evaluación!$P$7:$P$56,$K24)="","",INDEX(Evaluación!$P$7:$P$56,$K24))) | K24: =IFERROR(MATCH(LARGE(Evaluación!$AC$7:$AC$56,10),Evaluación!$AC$7:$AC$56,0),"")
A25: =IF(K25="","",IF(INDEX(Evaluación!$AA$7:$AA$56,K25)="","—",INDEX(Evaluación!$AA$7:$AA$56,K25))) | B25: =IF($K25="","",IF(INDEX(Evaluación!$B$7:$B$56,$K25)="","",INDEX(Evaluación!$B$7:$B$56,$K25))) | C25: =IF($K25="","",IF(INDEX(Evaluación!$C$7:$C$56,$K25)="","",INDEX(Evaluación!$C$7:$C$56,$K25))) | D25: =IF($K25="","",IF(INDEX(Evaluación!$D$7:$D$56,$K25)="","",INDEX(Evaluación!$D$7:$D$56,$K25))) | E25: =IF($K25="","",IF(INDEX(Evaluación!$G$7:$G$56,$K25)="","",INDEX(Evaluación!$G$7:$G$56,$K25))) | F25: =IF($K25="","",IF(INDEX(Evaluación!$H$7:$H$56,$K25)="","",INDEX(Evaluación!$H$7:$H$56,$K25))) | G25: =IF($K25="","",IF(INDEX(Evaluación!$Y$7:$Y$56,$K25)="","",INDEX(Evaluación!$Y$7:$Y$56,$K25))) | H25: =IF($K25="","",IF(INDEX(Evaluación!$Z$7:$Z$56,$K25)="","",INDEX(Evaluación!$Z$7:$Z$56,$K25))) | I25: =IF($K25="","",IF(INDEX(Evaluación!$O$7:$O$56,$K25)="","",INDEX(Evaluación!$O$7:$O$56,$K25))) | J25: =IF($K25="","",IF(INDEX(Evaluación!$P$7:$P$56,$K25)="","",INDEX(Evaluación!$P$7:$P$56,$K25))) | K25: =IFERROR(MATCH(LARGE(Evaluación!$AC$7:$AC$56,11),Evaluación!$AC$7:$AC$56,0),"")
A26: =IF(K26="","",IF(INDEX(Evaluación!$AA$7:$AA$56,K26)="","—",INDEX(Evaluación!$AA$7:$AA$56,K26))) | B26: =IF($K26="","",IF(INDEX(Evaluación!$B$7:$B$56,$K26)="","",INDEX(Evaluación!$B$7:$B$56,$K26))) | C26: =IF($K26="","",IF(INDEX(Evaluación!$C$7:$C$56,$K26)="","",INDEX(Evaluación!$C$7:$C$56,$K26))) | D26: =IF($K26="","",IF(INDEX(Evaluación!$D$7:$D$56,$K26)="","",INDEX(Evaluación!$D$7:$D$56,$K26))) | E26: =IF($K26="","",IF(INDEX(Evaluación!$G$7:$G$56,$K26)="","",INDEX(Evaluación!$G$7:$G$56,$K26))) | F26: =IF($K26="","",IF(INDEX(Evaluación!$H$7:$H$56,$K26)="","",INDEX(Evaluación!$H$7:$H$56,$K26))) | G26: =IF($K26="","",IF(INDEX(Evaluación!$Y$7:$Y$56,$K26)="","",INDEX(Evaluación!$Y$7:$Y$56,$K26))) | H26: =IF($K26="","",IF(INDEX(Evaluación!$Z$7:$Z$56,$K26)="","",INDEX(Evaluación!$Z$7:$Z$56,$K26))) | I26: =IF($K26="","",IF(INDEX(Evaluación!$O$7:$O$56,$K26)="","",INDEX(Evaluación!$O$7:$O$56,$K26))) | J26: =IF($K26="","",IF(INDEX(Evaluación!$P$7:$P$56,$K26)="","",INDEX(Evaluación!$P$7:$P$56,$K26))) | K26: =IFERROR(MATCH(LARGE(Evaluación!$AC$7:$AC$56,12),Evaluación!$AC$7:$AC$56,0),"")
A27: =IF(K27="","",IF(INDEX(Evaluación!$AA$7:$AA$56,K27)="","—",INDEX(Evaluación!$AA$7:$AA$56,K27))) | B27: =IF($K27="","",IF(INDEX(Evaluación!$B$7:$B$56,$K27)="","",INDEX(Evaluación!$B$7:$B$56,$K27))) | C27: =IF($K27="","",IF(INDEX(Evaluación!$C$7:$C$56,$K27)="","",INDEX(Evaluación!$C$7:$C$56,$K27))) | D27: =IF($K27="","",IF(INDEX(Evaluación!$D$7:$D$56,$K27)="","",INDEX(Evaluación!$D$7:$D$56,$K27))) | E27: =IF($K27="","",IF(INDEX(Evaluación!$G$7:$G$56,$K27)="","",INDEX(Evaluación!$G$7:$G$56,$K27))) | F27: =IF($K27="","",IF(INDEX(Evaluación!$H$7:$H$56,$K27)="","",INDEX(Evaluación!$H$7:$H$56,$K27))) | G27: =IF($K27="","",IF(INDEX(Evaluación!$Y$7:$Y$56,$K27)="","",INDEX(Evaluación!$Y$7:$Y$56,$K27))) | H27: =IF($K27="","",IF(INDEX(Evaluación!$Z$7:$Z$56,$K27)="","",INDEX(Evaluación!$Z$7:$Z$56,$K27))) | I27: =IF($K27="","",IF(INDEX(Evaluación!$O$7:$O$56,$K27)="","",INDEX(Evaluación!$O$7:$O$56,$K27))) | J27: =IF($K27="","",IF(INDEX(Evaluación!$P$7:$P$56,$K27)="","",INDEX(Evaluación!$P$7:$P$56,$K27))) | K27: =IFERROR(MATCH(LARGE(Evaluación!$AC$7:$AC$56,13),Evaluación!$AC$7:$AC$56,0),"")
A28: =IF(K28="","",IF(INDEX(Evaluación!$AA$7:$AA$56,K28)="","—",INDEX(Evaluación!$AA$7:$AA$56,K28))) | B28: =IF($K28="","",IF(INDEX(Evaluación!$B$7:$B$56,$K28)="","",INDEX(Evaluación!$B$7:$B$56,$K28))) | C28: =IF($K28="","",IF(INDEX(Evaluación!$C$7:$C$56,$K28)="","",INDEX(Evaluación!$C$7:$C$56,$K28))) | D28: =IF($K28="","",IF(INDEX(Evaluación!$D$7:$D$56,$K28)="","",INDEX(Evaluación!$D$7:$D$56,$K28))) | E28: =IF($K28="","",IF(INDEX(Evaluación!$G$7:$G$56,$K28)="","",INDEX(Evaluación!$G$7:$G$56,$K28))) | F28: =IF($K28="","",IF(INDEX(Evaluación!$H$7:$H$56,$K28)="","",INDEX(Evaluación!$H$7:$H$56,$K28))) | G28: =IF($K28="","",IF(INDEX(Evaluación!$Y$7:$Y$56,$K28)="","",INDEX(Evaluación!$Y$7:$Y$56,$K28))) | H28: =IF($K28="","",IF(INDEX(Evaluación!$Z$7:$Z$56,$K28)="","",INDEX(Evaluación!$Z$7:$Z$56,$K28))) | I28: =IF($K28="","",IF(INDEX(Evaluación!$O$7:$O$56,$K28)="","",INDEX(Evaluación!$O$7:$O$56,$K28))) | J28: =IF($K28="","",IF(INDEX(Evaluación!$P$7:$P$56,$K28)="","",INDEX(Evaluación!$P$7:$P$56,$K28))) | K28: =IFERROR(MATCH(LARGE(Evaluación!$AC$7:$AC$56,14),Evaluación!$AC$7:$AC$56,0),"")
A29: =IF(K29="","",IF(INDEX(Evaluación!$AA$7:$AA$56,K29)="","—",INDEX(Evaluación!$AA$7:$AA$56,K29))) | B29: =IF($K29="","",IF(INDEX(Evaluación!$B$7:$B$56,$K29)="","",INDEX(Evaluación!$B$7:$B$56,$K29))) | C29: =IF($K29="","",IF(INDEX(Evaluación!$C$7:$C$56,$K29)="","",INDEX(Evaluación!$C$7:$C$56,$K29))) | D29: =IF($K29="","",IF(INDEX(Evaluación!$D$7:$D$56,$K29)="","",INDEX(Evaluación!$D$7:$D$56,$K29))) | E29: =IF($K29="","",IF(INDEX(Evaluación!$G$7:$G$56,$K29)="","",INDEX(Evaluación!$G$7:$G$56,$K29))) | F29: =IF($K29="","",IF(INDEX(Evaluación!$H$7:$H$56,$K29)="","",INDEX(Evaluación!$H$7:$H$56,$K29))) | G29: =IF($K29="","",IF(INDEX(Evaluación!$Y$7:$Y$56,$K29)="","",INDEX(Evaluación!$Y$7:$Y$56,$K29))) | H29: =IF($K29="","",IF(INDEX(Evaluación!$Z$7:$Z$56,$K29)="","",INDEX(Evaluación!$Z$7:$Z$56,$K29))) | I29: =IF($K29="","",IF(INDEX(Evaluación!$O$7:$O$56,$K29)="","",INDEX(Evaluación!$O$7:$O$56,$K29))) | J29: =IF($K29="","",IF(INDEX(Evaluación!$P$7:$P$56,$K29)="","",INDEX(Evaluación!$P$7:$P$56,$K29))) | K29: =IFERROR(MATCH(LARGE(Evaluación!$AC$7:$AC$56,15),Evaluación!$AC$7:$AC$56,0),"")
A30: =IF(K30="","",IF(INDEX(Evaluación!$AA$7:$AA$56,K30)="","—",INDEX(Evaluación!$AA$7:$AA$56,K30))) | B30: =IF($K30="","",IF(INDEX(Evaluación!$B$7:$B$56,$K30)="","",INDEX(Evaluación!$B$7:$B$56,$K30))) | C30: =IF($K30="","",IF(INDEX(Evaluación!$C$7:$C$56,$K30)="","",INDEX(Evaluación!$C$7:$C$56,$K30))) | D30: =IF($K30="","",IF(INDEX(Evaluación!$D$7:$D$56,$K30)="","",INDEX(Evaluación!$D$7:$D$56,$K30))) | E30: =IF($K30="","",IF(INDEX(Evaluación!$G$7:$G$56,$K30)="","",INDEX(Evaluación!$G$7:$G$56,$K30))) | F30: =IF($K30="","",IF(INDEX(Evaluación!$H$7:$H$56,$K30)="","",INDEX(Evaluación!$H$7:$H$56,$K30))) | G30: =IF($K30="","",IF(INDEX(Evaluación!$Y$7:$Y$56,$K30)="","",INDEX(Evaluación!$Y$7:$Y$56,$K30))) | H30: =IF($K30="","",IF(INDEX(Evaluación!$Z$7:$Z$56,$K30)="","",INDEX(Evaluación!$Z$7:$Z$56,$K30))) | I30: =IF($K30="","",IF(INDEX(Evaluación!$O$7:$O$56,$K30)="","",INDEX(Evaluación!$O$7:$O$56,$K30))) | J30: =IF($K30="","",IF(INDEX(Evaluación!$P$7:$P$56,$K30)="","",INDEX(Evaluación!$P$7:$P$56,$K30))) | K30: =IFERROR(MATCH(LARGE(Evaluación!$AC$7:$AC$56,16),Evaluación!$AC$7:$AC$56,0),"")
A31: =IF(K31="","",IF(INDEX(Evaluación!$AA$7:$AA$56,K31)="","—",INDEX(Evaluación!$AA$7:$AA$56,K31))) | B31: =IF($K31="","",IF(INDEX(Evaluación!$B$7:$B$56,$K31)="","",INDEX(Evaluación!$B$7:$B$56,$K31))) | C31: =IF($K31="","",IF(INDEX(Evaluación!$C$7:$C$56,$K31)="","",INDEX(Evaluación!$C$7:$C$56,$K31))) | D31: =IF($K31="","",IF(INDEX(Evaluación!$D$7:$D$56,$K31)="","",INDEX(Evaluación!$D$7:$D$56,$K31))) | E31: =IF($K31="","",IF(INDEX(Evaluación!$G$7:$G$56,$K31)="","",INDEX(Evaluación!$G$7:$G$56,$K31))) | F31: =IF($K31="","",IF(INDEX(Evaluación!$H$7:$H$56,$K31)="","",INDEX(Evaluación!$H$7:$H$56,$K31))) | G31: =IF($K31="","",IF(INDEX(Evaluación!$Y$7:$Y$56,$K31)="","",INDEX(Evaluación!$Y$7:$Y$56,$K31))) | H31: =IF($K31="","",IF(INDEX(Evaluación!$Z$7:$Z$56,$K31)="","",INDEX(Evaluación!$Z$7:$Z$56,$K31))) | I31: =IF($K31="","",IF(INDEX(Evaluación!$O$7:$O$56,$K31)="","",INDEX(Evaluación!$O$7:$O$56,$K31))) | J31: =IF($K31="","",IF(INDEX(Evaluación!$P$7:$P$56,$K31)="","",INDEX(Evaluación!$P$7:$P$56,$K31))) | K31: =IFERROR(MATCH(LARGE(Evaluación!$AC$7:$AC$56,17),Evaluación!$AC$7:$AC$56,0),"")
A32: =IF(K32="","",IF(INDEX(Evaluación!$AA$7:$AA$56,K32)="","—",INDEX(Evaluación!$AA$7:$AA$56,K32))) | B32: =IF($K32="","",IF(INDEX(Evaluación!$B$7:$B$56,$K32)="","",INDEX(Evaluación!$B$7:$B$56,$K32))) | C32: =IF($K32="","",IF(INDEX(Evaluación!$C$7:$C$56,$K32)="","",INDEX(Evaluación!$C$7:$C$56,$K32))) | D32: =IF($K32="","",IF(INDEX(Evaluación!$D$7:$D$56,$K32)="","",INDEX(Evaluación!$D$7:$D$56,$K32))) | E32: =IF($K32="","",IF(INDEX(Evaluación!$G$7:$G$56,$K32)="","",INDEX(Evaluación!$G$7:$G$56,$K32))) | F32: =IF($K32="","",IF(INDEX(Evaluación!$H$7:$H$56,$K32)="","",INDEX(Evaluación!$H$7:$H$56,$K32))) | G32: =IF($K32="","",IF(INDEX(Evaluación!$Y$7:$Y$56,$K32)="","",INDEX(Evaluación!$Y$7:$Y$56,$K32))) | H32: =IF($K32="","",IF(INDEX(Evaluación!$Z$7:$Z$56,$K32)="","",INDEX(Evaluación!$Z$7:$Z$56,$K32))) | I32: =IF($K32="","",IF(INDEX(Evaluación!$O$7:$O$56,$K32)="","",INDEX(Evaluación!$O$7:$O$56,$K32))) | J32: =IF($K32="","",IF(INDEX(Evaluación!$P$7:$P$56,$K32)="","",INDEX(Evaluación!$P$7:$P$56,$K32))) | K32: =IFERROR(MATCH(LARGE(Evaluación!$AC$7:$AC$56,18),Evaluación!$AC$7:$AC$56,0),"")
A33: =IF(K33="","",IF(INDEX(Evaluación!$AA$7:$AA$56,K33)="","—",INDEX(Evaluación!$AA$7:$AA$56,K33))) | B33: =IF($K33="","",IF(INDEX(Evaluación!$B$7:$B$56,$K33)="","",INDEX(Evaluación!$B$7:$B$56,$K33))) | C33: =IF($K33="","",IF(INDEX(Evaluación!$C$7:$C$56,$K33)="","",INDEX(Evaluación!$C$7:$C$56,$K33))) | D33: =IF($K33="","",IF(INDEX(Evaluación!$D$7:$D$56,$K33)="","",INDEX(Evaluación!$D$7:$D$56,$K33))) | E33: =IF($K33="","",IF(INDEX(Evaluación!$G$7:$G$56,$K33)="","",INDEX(Evaluación!$G$7:$G$56,$K33))) | F33: =IF($K33="","",IF(INDEX(Evaluación!$H$7:$H$56,$K33)="","",INDEX(Evaluación!$H$7:$H$56,$K33))) | G33: =IF($K33="","",IF(INDEX(Evaluación!$Y$7:$Y$56,$K33)="","",INDEX(Evaluación!$Y$7:$Y$56,$K33))) | H33: =IF($K33="","",IF(INDEX(Evaluación!$Z$7:$Z$56,$K33)="","",INDEX(Evaluación!$Z$7:$Z$56,$K33))) | I33: =IF($K33="","",IF(INDEX(Evaluación!$O$7:$O$56,$K33)="","",INDEX(Evaluación!$O$7:$O$56,$K33))) | J33: =IF($K33="","",IF(INDEX(Evaluación!$P$7:$P$56,$K33)="","",INDEX(Evaluación!$P$7:$P$56,$K33))) | K33: =IFERROR(MATCH(LARGE(Evaluación!$AC$7:$AC$56,19),Evaluación!$AC$7:$AC$56,0),"")
A34: =IF(K34="","",IF(INDEX(Evaluación!$AA$7:$AA$56,K34)="","—",INDEX(Evaluación!$AA$7:$AA$56,K34))) | B34: =IF($K34="","",IF(INDEX(Evaluación!$B$7:$B$56,$K34)="","",INDEX(Evaluación!$B$7:$B$56,$K34))) | C34: =IF($K34="","",IF(INDEX(Evaluación!$C$7:$C$56,$K34)="","",INDEX(Evaluación!$C$7:$C$56,$K34))) | D34: =IF($K34="","",IF(INDEX(Evaluación!$D$7:$D$56,$K34)="","",INDEX(Evaluación!$D$7:$D$56,$K34))) | E34: =IF($K34="","",IF(INDEX(Evaluación!$G$7:$G$56,$K34)="","",INDEX(Evaluación!$G$7:$G$56,$K34))) | F34: =IF($K34="","",IF(INDEX(Evaluación!$H$7:$H$56,$K34)="","",INDEX(Evaluación!$H$7:$H$56,$K34))) | G34: =IF($K34="","",IF(INDEX(Evaluación!$Y$7:$Y$56,$K34)="","",INDEX(Evaluación!$Y$7:$Y$56,$K34))) | H34: =IF($K34="","",IF(INDEX(Evaluación!$Z$7:$Z$56,$K34)="","",INDEX(Evaluación!$Z$7:$Z$56,$K34))) | I34: =IF($K34="","",IF(INDEX(Evaluación!$O$7:$O$56,$K34)="","",INDEX(Evaluación!$O$7:$O$56,$K34))) | J34: =IF($K34="","",IF(INDEX(Evaluación!$P$7:$P$56,$K34)="","",INDEX(Evaluación!$P$7:$P$56,$K34))) | K34: =IFERROR(MATCH(LARGE(Evaluación!$AC$7:$AC$56,20),Evaluación!$AC$7:$AC$56,0),"")
A35: =IF(K35="","",IF(INDEX(Evaluación!$AA$7:$AA$56,K35)="","—",INDEX(Evaluación!$AA$7:$AA$56,K35))) | B35: =IF($K35="","",IF(INDEX(Evaluación!$B$7:$B$56,$K35)="","",INDEX(Evaluación!$B$7:$B$56,$K35))) | C35: =IF($K35="","",IF(INDEX(Evaluación!$C$7:$C$56,$K35)="","",INDEX(Evaluación!$C$7:$C$56,$K35))) | D35: =IF($K35="","",IF(INDEX(Evaluación!$D$7:$D$56,$K35)="","",INDEX(Evaluación!$D$7:$D$56,$K35))) | E35: =IF($K35="","",IF(INDEX(Evaluación!$G$7:$G$56,$K35)="","",INDEX(Evaluación!$G$7:$G$56,$K35))) | F35: =IF($K35="","",IF(INDEX(Evaluación!$H$7:$H$56,$K35)="","",INDEX(Evaluación!$H$7:$H$56,$K35))) | G35: =IF($K35="","",IF(INDEX(Evaluación!$Y$7:$Y$56,$K35)="","",INDEX(Evaluación!$Y$7:$Y$56,$K35))) | H35: =IF($K35="","",IF(INDEX(Evaluación!$Z$7:$Z$56,$K35)="","",INDEX(Evaluación!$Z$7:$Z$56,$K35))) | I35: =IF($K35="","",IF(INDEX(Evaluación!$O$7:$O$56,$K35)="","",INDEX(Evaluación!$O$7:$O$56,$K35))) | J35: =IF($K35="","",IF(INDEX(Evaluación!$P$7:$P$56,$K35)="","",INDEX(Evaluación!$P$7:$P$56,$K35))) | K35: =IFERROR(MATCH(LARGE(Evaluación!$AC$7:$AC$56,21),Evaluación!$AC$7:$AC$56,0),"")
A36: =IF(K36="","",IF(INDEX(Evaluación!$AA$7:$AA$56,K36)="","—",INDEX(Evaluación!$AA$7:$AA$56,K36))) | B36: =IF($K36="","",IF(INDEX(Evaluación!$B$7:$B$56,$K36)="","",INDEX(Evaluación!$B$7:$B$56,$K36))) | C36: =IF($K36="","",IF(INDEX(Evaluación!$C$7:$C$56,$K36)="","",INDEX(Evaluación!$C$7:$C$56,$K36))) | D36: =IF($K36="","",IF(INDEX(Evaluación!$D$7:$D$56,$K36)="","",INDEX(Evaluación!$D$7:$D$56,$K36))) | E36: =IF($K36="","",IF(INDEX(Evaluación!$G$7:$G$56,$K36)="","",INDEX(Evaluación!$G$7:$G$56,$K36))) | F36: =IF($K36="","",IF(INDEX(Evaluación!$H$7:$H$56,$K36)="","",INDEX(Evaluación!$H$7:$H$56,$K36))) | G36: =IF($K36="","",IF(INDEX(Evaluación!$Y$7:$Y$56,$K36)="","",INDEX(Evaluación!$Y$7:$Y$56,$K36))) | H36: =IF($K36="","",IF(INDEX(Evaluación!$Z$7:$Z$56,$K36)="","",INDEX(Evaluación!$Z$7:$Z$56,$K36))) | I36: =IF($K36="","",IF(INDEX(Evaluación!$O$7:$O$56,$K36)="","",INDEX(Evaluación!$O$7:$O$56,$K36))) | J36: =IF($K36="","",IF(INDEX(Evaluación!$P$7:$P$56,$K36)="","",INDEX(Evaluación!$P$7:$P$56,$K36))) | K36: =IFERROR(MATCH(LARGE(Evaluación!$AC$7:$AC$56,22),Evaluación!$AC$7:$AC$56,0),"")
A37: =IF(K37="","",IF(INDEX(Evaluación!$AA$7:$AA$56,K37)="","—",INDEX(Evaluación!$AA$7:$AA$56,K37))) | B37: =IF($K37="","",IF(INDEX(Evaluación!$B$7:$B$56,$K37)="","",INDEX(Evaluación!$B$7:$B$56,$K37))) | C37: =IF($K37="","",IF(INDEX(Evaluación!$C$7:$C$56,$K37)="","",INDEX(Evaluación!$C$7:$C$56,$K37))) | D37: =IF($K37="","",IF(INDEX(Evaluación!$D$7:$D$56,$K37)="","",INDEX(Evaluación!$D$7:$D$56,$K37))) | E37: =IF($K37="","",IF(INDEX(Evaluación!$G$7:$G$56,$K37)="","",INDEX(Evaluación!$G$7:$G$56,$K37))) | F37: =IF($K37="","",IF(INDEX(Evaluación!$H$7:$H$56,$K37)="","",INDEX(Evaluación!$H$7:$H$56,$K37))) | G37: =IF($K37="","",IF(INDEX(Evaluación!$Y$7:$Y$56,$K37)="","",INDEX(Evaluación!$Y$7:$Y$56,$K37))) | H37: =IF($K37="","",IF(INDEX(Evaluación!$Z$7:$Z$56,$K37)="","",INDEX(Evaluación!$Z$7:$Z$56,$K37))) | I37: =IF($K37="","",IF(INDEX(Evaluación!$O$7:$O$56,$K37)="","",INDEX(Evaluación!$O$7:$O$56,$K37))) | J37: =IF($K37="","",IF(INDEX(Evaluación!$P$7:$P$56,$K37)="","",INDEX(Evaluación!$P$7:$P$56,$K37))) | K37: =IFERROR(MATCH(LARGE(Evaluación!$AC$7:$AC$56,23),Evaluación!$AC$7:$AC$56,0),"")
A38: =IF(K38="","",IF(INDEX(Evaluación!$AA$7:$AA$56,K38)="","—",INDEX(Evaluación!$AA$7:$AA$56,K38))) | B38: =IF($K38="","",IF(INDEX(Evaluación!$B$7:$B$56,$K38)="","",INDEX(Evaluación!$B$7:$B$56,$K38))) | C38: =IF($K38="","",IF(INDEX(Evaluación!$C$7:$C$56,$K38)="","",INDEX(Evaluación!$C$7:$C$56,$K38))) | D38: =IF($K38="","",IF(INDEX(Evaluación!$D$7:$D$56,$K38)="","",INDEX(Evaluación!$D$7:$D$56,$K38))) | E38: =IF($K38="","",IF(INDEX(Evaluación!$G$7:$G$56,$K38)="","",INDEX(Evaluación!$G$7:$G$56,$K38))) | F38: =IF($K38="","",IF(INDEX(Evaluación!$H$7:$H$56,$K38)="","",INDEX(Evaluación!$H$7:$H$56,$K38))) | G38: =IF($K38="","",IF(INDEX(Evaluación!$Y$7:$Y$56,$K38)="","",INDEX(Evaluación!$Y$7:$Y$56,$K38))) | H38: =IF($K38="","",IF(INDEX(Evaluación!$Z$7:$Z$56,$K38)="","",INDEX(Evaluación!$Z$7:$Z$56,$K38))) | I38: =IF($K38="","",IF(INDEX(Evaluación!$O$7:$O$56,$K38)="","",INDEX(Evaluación!$O$7:$O$56,$K38))) | J38: =IF($K38="","",IF(INDEX(Evaluación!$P$7:$P$56,$K38)="","",INDEX(Evaluación!$P$7:$P$56,$K38))) | K38: =IFERROR(MATCH(LARGE(Evaluación!$AC$7:$AC$56,24),Evaluación!$AC$7:$AC$56,0),"")
A39: =IF(K39="","",IF(INDEX(Evaluación!$AA$7:$AA$56,K39)="","—",INDEX(Evaluación!$AA$7:$AA$56,K39))) | B39: =IF($K39="","",IF(INDEX(Evaluación!$B$7:$B$56,$K39)="","",INDEX(Evaluación!$B$7:$B$56,$K39))) | C39: =IF($K39="","",IF(INDEX(Evaluación!$C$7:$C$56,$K39)="","",INDEX(Evaluación!$C$7:$C$56,$K39))) | D39: =IF($K39="","",IF(INDEX(Evaluación!$D$7:$D$56,$K39)="","",INDEX(Evaluación!$D$7:$D$56,$K39))) | E39: =IF($K39="","",IF(INDEX(Evaluación!$G$7:$G$56,$K39)="","",INDEX(Evaluación!$G$7:$G$56,$K39))) | F39: =IF($K39="","",IF(INDEX(Evaluación!$H$7:$H$56,$K39)="","",INDEX(Evaluación!$H$7:$H$56,$K39))) | G39: =IF($K39="","",IF(INDEX(Evaluación!$Y$7:$Y$56,$K39)="","",INDEX(Evaluación!$Y$7:$Y$56,$K39))) | H39: =IF($K39="","",IF(INDEX(Evaluación!$Z$7:$Z$56,$K39)="","",INDEX(Evaluación!$Z$7:$Z$56,$K39))) | I39: =IF($K39="","",IF(INDEX(Evaluación!$O$7:$O$56,$K39)="","",INDEX(Evaluación!$O$7:$O$56,$K39))) | J39: =IF($K39="","",IF(INDEX(Evaluación!$P$7:$P$56,$K39)="","",INDEX(Evaluación!$P$7:$P$56,$K39))) | K39: =IFERROR(MATCH(LARGE(Evaluación!$AC$7:$AC$56,25),Evaluación!$AC$7:$AC$56,0),"")
A40: =IF(K40="","",IF(INDEX(Evaluación!$AA$7:$AA$56,K40)="","—",INDEX(Evaluación!$AA$7:$AA$56,K40))) | B40: =IF($K40="","",IF(INDEX(Evaluación!$B$7:$B$56,$K40)="","",INDEX(Evaluación!$B$7:$B$56,$K40))) | C40: =IF($K40="","",IF(INDEX(Evaluación!$C$7:$C$56,$K40)="","",INDEX(Evaluación!$C$7:$C$56,$K40))) | D40: =IF($K40="","",IF(INDEX(Evaluación!$D$7:$D$56,$K40)="","",INDEX(Evaluación!$D$7:$D$56,$K40))) | E40: =IF($K40="","",IF(INDEX(Evaluación!$G$7:$G$56,$K40)="","",INDEX(Evaluación!$G$7:$G$56,$K40))) | F40: =IF($K40="","",IF(INDEX(Evaluación!$H$7:$H$56,$K40)="","",INDEX(Evaluación!$H$7:$H$56,$K40))) | G40: =IF($K40="","",IF(INDEX(Evaluación!$Y$7:$Y$56,$K40)="","",INDEX(Evaluación!$Y$7:$Y$56,$K40))) | H40: =IF($K40="","",IF(INDEX(Evaluación!$Z$7:$Z$56,$K40)="","",INDEX(Evaluación!$Z$7:$Z$56,$K40))) | I40: =IF($K40="","",IF(INDEX(Evaluación!$O$7:$O$56,$K40)="","",INDEX(Evaluación!$O$7:$O$56,$K40))) | J40: =IF($K40="","",IF(INDEX(Evaluación!$P$7:$P$56,$K40)="","",INDEX(Evaluación!$P$7:$P$56,$K40))) | K40: =IFERROR(MATCH(LARGE(Evaluación!$AC$7:$AC$56,26),Evaluación!$AC$7:$AC$56,0),"")
A41: =IF(K41="","",IF(INDEX(Evaluación!$AA$7:$AA$56,K41)="","—",INDEX(Evaluación!$AA$7:$AA$56,K41))) | B41: =IF($K41="","",IF(INDEX(Evaluación!$B$7:$B$56,$K41)="","",INDEX(Evaluación!$B$7:$B$56,$K41))) | C41: =IF($K41="","",IF(INDEX(Evaluación!$C$7:$C$56,$K41)="","",INDEX(Evaluación!$C$7:$C$56,$K41))) | D41: =IF($K41="","",IF(INDEX(Evaluación!$D$7:$D$56,$K41)="","",INDEX(Evaluación!$D$7:$D$56,$K41))) | E41: =IF($K41="","",IF(INDEX(Evaluación!$G$7:$G$56,$K41)="","",INDEX(Evaluación!$G$7:$G$56,$K41))) | F41: =IF($K41="","",IF(INDEX(Evaluación!$H$7:$H$56,$K41)="","",INDEX(Evaluación!$H$7:$H$56,$K41))) | G41: =IF($K41="","",IF(INDEX(Evaluación!$Y$7:$Y$56,$K41)="","",INDEX(Evaluación!$Y$7:$Y$56,$K41))) | H41: =IF($K41="","",IF(INDEX(Evaluación!$Z$7:$Z$56,$K41)="","",INDEX(Evaluación!$Z$7:$Z$56,$K41))) | I41: =IF($K41="","",IF(INDEX(Evaluación!$O$7:$O$56,$K41)="","",INDEX(Evaluación!$O$7:$O$56,$K41))) | J41: =IF($K41="","",IF(INDEX(Evaluación!$P$7:$P$56,$K41)="","",INDEX(Evaluación!$P$7:$P$56,$K41))) | K41: =IFERROR(MATCH(LARGE(Evaluación!$AC$7:$AC$56,27),Evaluación!$AC$7:$AC$56,0),"")
A42: =IF(K42="","",IF(INDEX(Evaluación!$AA$7:$AA$56,K42)="","—",INDEX(Evaluación!$AA$7:$AA$56,K42))) | B42: =IF($K42="","",IF(INDEX(Evaluación!$B$7:$B$56,$K42)="","",INDEX(Evaluación!$B$7:$B$56,$K42))) | C42: =IF($K42="","",IF(INDEX(Evaluación!$C$7:$C$56,$K42)="","",INDEX(Evaluación!$C$7:$C$56,$K42))) | D42: =IF($K42="","",IF(INDEX(Evaluación!$D$7:$D$56,$K42)="","",INDEX(Evaluación!$D$7:$D$56,$K42))) | E42: =IF($K42="","",IF(INDEX(Evaluación!$G$7:$G$56,$K42)="","",INDEX(Evaluación!$G$7:$G$56,$K42))) | F42: =IF($K42="","",IF(INDEX(Evaluación!$H$7:$H$56,$K42)="","",INDEX(Evaluación!$H$7:$H$56,$K42))) | G42: =IF($K42="","",IF(INDEX(Evaluación!$Y$7:$Y$56,$K42)="","",INDEX(Evaluación!$Y$7:$Y$56,$K42))) | H42: =IF($K42="","",IF(INDEX(Evaluación!$Z$7:$Z$56,$K42)="","",INDEX(Evaluación!$Z$7:$Z$56,$K42))) | I42: =IF($K42="","",IF(INDEX(Evaluación!$O$7:$O$56,$K42)="","",INDEX(Evaluación!$O$7:$O$56,$K42))) | J42: =IF($K42="","",IF(INDEX(Evaluación!$P$7:$P$56,$K42)="","",INDEX(Evaluación!$P$7:$P$56,$K42))) | K42: =IFERROR(MATCH(LARGE(Evaluación!$AC$7:$AC$56,28),Evaluación!$AC$7:$AC$56,0),"")
A43: =IF(K43="","",IF(INDEX(Evaluación!$AA$7:$AA$56,K43)="","—",INDEX(Evaluación!$AA$7:$AA$56,K43))) | B43: =IF($K43="","",IF(INDEX(Evaluación!$B$7:$B$56,$K43)="","",INDEX(Evaluación!$B$7:$B$56,$K43))) | C43: =IF($K43="","",IF(INDEX(Evaluación!$C$7:$C$56,$K43)="","",INDEX(Evaluación!$C$7:$C$56,$K43))) | D43: =IF($K43="","",IF(INDEX(Evaluación!$D$7:$D$56,$K43)="","",INDEX(Evaluación!$D$7:$D$56,$K43))) | E43: =IF($K43="","",IF(INDEX(Evaluación!$G$7:$G$56,$K43)="","",INDEX(Evaluación!$G$7:$G$56,$K43))) | F43: =IF($K43="","",IF(INDEX(Evaluación!$H$7:$H$56,$K43)="","",INDEX(Evaluación!$H$7:$H$56,$K43))) | G43: =IF($K43="","",IF(INDEX(Evaluación!$Y$7:$Y$56,$K43)="","",INDEX(Evaluación!$Y$7:$Y$56,$K43))) | H43: =IF($K43="","",IF(INDEX(Evaluación!$Z$7:$Z$56,$K43)="","",INDEX(Evaluación!$Z$7:$Z$56,$K43))) | I43: =IF($K43="","",IF(INDEX(Evaluación!$O$7:$O$56,$K43)="","",INDEX(Evaluación!$O$7:$O$56,$K43))) | J43: =IF($K43="","",IF(INDEX(Evaluación!$P$7:$P$56,$K43)="","",INDEX(Evaluación!$P$7:$P$56,$K43))) | K43: =IFERROR(MATCH(LARGE(Evaluación!$AC$7:$AC$56,29),Evaluación!$AC$7:$AC$56,0),"")
...
