Workbook

Sheet Criterios
A1: Criterios de priorización
A2: Prioritario | B2: Se reporta siempre. Cumple los cuatro criterios: (1) mide un resultado central de LAPIS para la primera infancia y sus personas cuidadoras; (2) es sensible a la intervención, es decir, se espera que cambie entre la medición antes y después; (3) no repite lo que mide otro indicador prioritario; (4) es robusto con el tamaño de muestra previsto.
A3: Complementario | B3: Se levanta y se usa para explicar o triangular resultados, pero no es obligatorio reportarlo. Incluye indicadores redundantes, de detalle técnico, sobre población fuera de la primera infancia (6 a 12 años o personas adultas) o con conteos muy bajos.
A4: Contexto | B4: No mide impacto. Sirve para describir la muestra y verificar que las mediciones antes y después sean comparables (perfil, número de niñas y niños, motivo, modo de llegada).
A5: Ajuste por intervención | B5: Algunos complementarios pasan a prioritarios si la intervención incluye ese componente (por ejemplo, lactario, juegos inclusivos, captación de agua, iluminación o techumbre para lluvia). Lo indica la justificación.
A6: Equilibrio | B6: Dentro de cada dimensión se buscó al menos un indicador de condición del espacio y uno de uso o percepción, para poder contar la cadena de cambio completa.

Sheet Indicadores
A1: # | B1: Instrumento | C1: Dimensión | D1: Temática | E1: Tipo de indicador | F1: Nombre del indicador | G1: Priorización | H1: Justificación | I1: Observación de clasificación
A2: 1 | B2: Calidad de las interacciones | C2: Juego e interacción | D2: Diversidad y adecuación del juego ofrecido | E2: Cambio de comportamiento observado | F2: Distribución de las actividades lúdicas durante la interacción entre personas cuidadoras e infancias | G2: Complementario | H2: Detalle del tipo de juego en la interacción; útil para el análisis a profundidad.
A3: 2 | B3: Calidad de las interacciones | C3: Juego e interacción | D3: Interacción cuidador - infancia | E3: Cambio de comportamiento observado | F3: Nivel de interacción entre personas cuidadoras e infancias | G3: Prioritario | H3: Medición directa (observada) de la interacción persona cuidadora–infancia, objetivo central de LAPIS.
A4: 3 | B4: Calidad de las interacciones | C4: Juego e interacción | D4: Interacción cuidador - infancia | E4: Cambio de comportamiento observado | F4: Uso compartido de los juegos entre personas cuidadoras e infancias | G4: Complementario | H4: Redundante con el nivel de interacción (2); aporta detalle.
A5: 4 | B5: Conteo de personas usuarias y usos | C5: Inclusión y cuidado | D5: Accesibilidad para diversidad de edades y PcD | E5: Cambio de comportamiento observado | F5: Promedio por hora de infancias menores de 6 años con alguna discapacidad percibida. | G5: Complementario | H5: Conteos muy bajos y difíciles de observar de forma confiable; reportar como contexto de inclusión.
A6: 5 | B6: Conteo de personas usuarias y usos | C6: Inclusión y cuidado | D6: Accesibilidad para diversidad de edades y PcD | E6: Cambio de comportamiento observado | F6: Promedio por hora de personas de 6 años o más con alguna discapacidad percibida | G6: Complementario | H6: Fuera de la población objetivo y con conteos bajos.
A7: 6 | B7: Conteo de personas usuarias y usos | C7: Usos y actividades | D7: Beneficiarios directos | E7: Cambio de comportamiento observado | F7: Promedio por hora de personas observadas | G7: Complementario | H7: Total de personas; menos específico que el indicador de menores de 6 años (8).
A8: 7 | B8: Conteo de personas usuarias y usos | C8: Usos y actividades | D8: Beneficiarios directos | E8: Cambio de comportamiento observado | F8: Promedio por hora de personas observadas de 6 años o más | G8: Complementario | H8: Personas de 6 años o más; secundario para el objetivo de primera infancia.
A9: 8 | B9: Conteo de personas usuarias y usos | C9: Usos y actividades | D9: Beneficiarios directos | E9: Cambio de comportamiento observado | F9: Promedio por hora de niñas y niños menores de 6 años observados | G9: Prioritario | H9: Indicador base de uso: cuántas niñas y niños menores de 6 años usan el espacio. Muy sensible a la intervención.
A10: 9 | B10: Conteo de personas usuarias y usos | C10: Usos y actividades | D10: Beneficiarios directos | E10: Cambio de comportamiento observado | F10: Distribución porcentual por grupo de edad de personas de 6 años en adelante. | G10: Complementario | H10: Composición por edad; descriptivo.
A11: 10 | B11: Conteo de personas usuarias y usos | C11: Usos y actividades | D11: Beneficiarios directos | E11: Cambio de comportamiento observado | F11: Distribución porcentual por grupo de edad de niñas y niños menores de 6 años. | G11: Complementario | H11: Composición por edad de menores de 6; descriptivo, complementa al 8.
A12: 11 | B12: Conteo de personas usuarias y usos | C12: Usos y actividades | D12: Beneficiarios directos | E12: Cambio de comportamiento observado | F12: Distribución porcentual de niñas o niños menores de 6 años y personas de 6 años o más | G12: Complementario | H12: Proporción menores/mayores; derivable del 6 y 8.
A13: 12 | B13: Conteo de personas usuarias y usos | C13: Usos y actividades | D13: Beneficiarios indirectos | E13: Cambio de comportamiento observado | F13: Porcentaje de personas de 6 años o más que no son cuidadoras | G13: Complementario | H13: Beneficiarios indirectos; secundario para el objetivo de primera infancia.
... A19: 18 | B19: Conteo de personas usuarias y usos | C19: Juego e interacción | D19: Interacción entre pares | E19: Cambio de comportamiento observado | F19: Porcentaje de niñas y niños menores de 6 años interactuando con otra niña o niño | G19: Prioritario | H19: Interacción entre pares observada en menores de 6 años; resultado esperado del diseño de juego.
A20: 19 | B20: Conteo de personas usuarias y usos | C20: Juego e interacción | D20: Interacción entre pares | E20: Cambio de comportamiento observado | F20: Porcentaje de personas cuidadoras interactuando con la niña o el niño | G20: Complementario | H20: Mide lo mismo que el 2 desde la persona cuidadora; usar para triangular. | I20: Revisar temática: mide interacción cuidador–infancia, no entre pares.
A21: 20 | B21: Conteo de personas usuarias y usos | C21: Juego e interacción | D21: Interacción entre pares | E21: Cambio de comportamiento observado | F21: Porcentaje de personas cuidadoras supervisando el juego de la niña o niño | G21: Complementario | H21: Supervisión del juego; complementa la interacción cuidador–infancia. | I21: Revisar temática: mide supervisión cuidador–infancia, no entre pares.
A22: 21 | B22: Conteo de personas usuarias y usos | C22: Calidad y funcionalidad del espacio | D22: Mobiliario de juego | E22: Cambio de comportamiento observado | F22: Porcentaje de personas de 6 años o más que usan los juegos | G22: Complementario | H22: Uso de juegos por personas de 6 años o más; secundario.
A23: 22 | B23: Conteo de personas usuarias y usos | C23: Calidad y funcionalidad del espacio | D23: Mobiliario de juego | E23: Cambio de comportamiento observado | F23: Porcentaje de infancias menores de 6 años que usan los juegos | G23: Prioritario | H23: Uso efectivo del mobiliario de juego por la población objetivo; vincula condición física con uso.
A24: 23 | B24: Conteo de personas usuarias y usos | C24: Calidad y funcionalidad del espacio | D24: Mobiliario urbano | E24: Cambio de comportamiento observado | F24: Porcentaje de personas de 6 años o más que usan las bancas | G24: Complementario | H24: Uso de bancas por personas de 6 años o más; secundario.
A25: 24 | B25: Conteo de personas usuarias y usos | C25: Calidad y funcionalidad del espacio | D25: Mobiliario urbano | E25: Cambio de comportamiento observado | F25: Porcentaje de infancias menores de 6 años que usan las bancas | G25: Complementario | H25: Poco relevante para menores de 6 años.
A26: 25 | B26: Dinámica en movimiento con infancias | C26: Inclusión y cuidado | D26: Acompañamiento y redes de cuidado | E26: Cambio en la percepción | F26: Distribución de las personas acompañantes de infancias de 3 a 5 años | G26: Complementario | H26: Redes de cuidado desde la voz infantil; detalle.
A27: 26 | B27: Dinámica en movimiento con infancias | C27: Inclusión y cuidado | D27: Acompañamiento y redes de cuidado | E27: Cambio en la percepción | F27: Distribución de las personas acompañantes de infancias de 6 a 12 años | G27: Complementario | H27: Infancias de 6 a 12 años: fuera de la población objetivo de primera infancia.
A28: 27 | B28: Dinámica en movimiento con infancias | C28: Inclusión y cuidado | D28: Acompañamiento y redes de cuidado | E28: Cambio en la percepción | F28: Distribución de las personas con quienes juegan las infancias de 3 a 5 años | G28: Complementario | H28: Con quién juegan las infancias de 3 a 5 años; detalle.
A29: 28 | B29: Dinámica en movimiento con infancias | C29: Inclusión y cuidado | D29: Acompañamiento y redes de cuidado | E29: Cambio en la percepción | F29: Distribución de las personas con quienes juegan las infancias de 6 a 12 años | G29: Complementario | H29: Infancias de 6 a 12 años: fuera de la población objetivo de primera infancia.
A30: 29 | B30: Dinámica en movimiento con infancias | C30: Medio ambiente y resiliencia climática | D30: Percepción infantil de resiliencia climática | E30: Cambio en la percepción | F30: Distribución de los lugares identificados como más frescos por infancias de 6 a 12 años | G30: Complementario | H30: Infancias de 6 a 12 años: fuera de la población objetivo de primera infancia.
A31: 30 | B31: Dinámica en movimiento con infancias | C31: Medio ambiente y resiliencia climática | D31: Percepción infantil de resiliencia climática | E31: Cambio en la percepción | F31: Distribución de los lugares identificados como refugio de lluvia por infancias de 3 a 5 años | G31: Complementario | H31: Percepción infantil de lluvia; complementa la condición física (100).
A32: 31 | B32: Dinámica en movimiento con infancias | C32: Medio ambiente y resiliencia climática | D32: Percepción infantil de resiliencia climática | E32: Cambio en la percepción | F32: Distribución de los lugares identificados como refugio de lluvia por infancias de 6 a 12 años | G32: Complementario | H32: Infancias de 6 a 12 años: fuera de la población objetivo de primera infancia.
A33: 32 | B33: Dinámica en movimiento con infancias | C33: Seguridad y protección | D33: Percepción infantil de seguridad | E33: Cambio en la percepción | F33: Distribución de los lugares percibidos como desagradables o inseguros por infancias de 3 a 5 años | G33: Prioritario | H33: Voz de las propias infancias (3 a 5 años) sobre seguridad; único indicador de seguridad desde su perspectiva.
... A39: 38 | B39: Encuesta a personas cuidadoras | C39: Inclusión y cuidado | D39: Accesibilidad para diversidad de edades y PcD | E39: Cambio en la percepción | F39: Inclusión en edad y capacidades percibida en el espacio | G39: Prioritario | H39: Percepción de inclusión por edad y capacidades; cubre la dimensión de inclusión desde la persona cuidadora.
A40: 39 | B40: Encuesta a personas cuidadoras | C40: Inclusión y cuidado | D40: Accesibilidad para diversidad de edades y PcD | E40: Cambio en la percepción | F40: Facilidad percibida para el juego autónomo de niñas y niños menores de 6 años | G40: Complementario | H40: Juego autónomo percibido; complementa el 57. | I40: Revisar temática: es juego autónomo (Juego e interacción), no accesibilidad.
A41: 40 | B41: Encuesta a personas cuidadoras | C41: Usos y actividades | D41: Beneficiarios directos | E41: Cambio de comportamiento reportado | F41: Número de niñas y niños menores de 6 años que acompañan a la persona cuidadora | G41: Contexto | H41: Contexto: caracteriza la muestra y permite verificar que antes y después sean comparables.
A42: 41 | B42: Encuesta a personas cuidadoras | C42: Usos y actividades | D42: Beneficiarios directos | E42: Cambio de comportamiento reportado | F42: Perfil de las personas cuidadoras | G42: Contexto | H42: Contexto: caracteriza la muestra y permite verificar que antes y después sean comparables.
A43: 42 | B43: Encuesta a personas cuidadoras | C43: Inclusión y cuidado | D43: Bienestar general | E43: Cambio en la percepción | F43: Valoración del impacto personal percibido por la persona cuidadora | G43: Prioritario | H43: Impacto en el bienestar de la persona cuidadora: resultado final del programa.
A44: 43 | B44: Encuesta a personas cuidadoras | C44: Inclusión y cuidado | D44: Bienestar general | E44: Cambio en la percepción | F44: Valoración del impacto percibido por la persona cuidadora para la niña o niño que le acompaña | G44: Prioritario | H44: Impacto percibido en la niña o niño: resultado final del programa.
A45: 44 | B45: Encuesta a personas cuidadoras | C45: Accesibilidad y conectividad | D45: Caminabilidad | E45: Cambio en la percepción | F45: Facilidad de desplazamiento percibida con carriola y/o niñas y niños menores de 6 años | G45: Prioritario | H45: Accesibilidad vivida por quien cuida (carriola, de la mano); muy sensible a obras de caminabilidad.
A46: 45 | B46: Encuesta a personas cuidadoras | C46: Calidad y funcionalidad del espacio | D46: Caminabilidad | E46: Cambio en la percepción | F46: Valoración percibida de los caminos, banquetas y accesos | G46: Complementario | H46: Similar al 44; usar para triangular. | I46: Revisar dimensión: los demás de caminabilidad están en Accesibilidad y conectividad.
A47: 46 | B47: Encuesta a personas cuidadoras | C47: Medio ambiente y resiliencia climática | D47: Cobertura vegetal y arbolado | E47: Cambio en la percepción | F47: Valoración percibida de la vegetación y arbolado | G47: Complementario | H47: Percepción de vegetación; complementa la condición física (74).
A48: 47 | B48: Encuesta a personas cuidadoras | C48: Inclusión y cuidado | D48: Comodidad e infraestructura de apoyo al cuidado | E48: Cambio en la percepción | F48: Facilidad de cuidado percibida | G48: Prioritario | H48: Facilidad de cuidado percibida: núcleo del enfoque de cuidado de LAPIS.
A49: 48 | B49: Encuesta a personas cuidadoras | C49: Medio ambiente y resiliencia climática | D49: Confort térmico | E49: Cambio en la percepción | F49: Valoración percibida de los espacios con sombra | G49: Prioritario | H49: Percepción de sombra; el confort térmico es determinante para el uso por menores de 6 años.
A50: 49 | B50: Encuesta a personas cuidadoras | C50: Juego e interacción | D50: Contacto con la naturaleza | E50: Cambio en la percepción | F50: Facilidad de interacción percibida de niñas y niños menores de 6 años con la naturaleza | G50: Complementario | H50: Contacto con naturaleza percibido; complementa el 74.
...

Sheet Resumen por dimensión
A1: Resumen de la priorización por dimensión
A2: Se calcula con fórmulas a partir de la hoja Indicadores: si cambias la priorización ahí, el resumen se actualiza.
A4: Dimensión | B4: Total | C4: Prioritario | D4: Complementario | E4: Contexto | F4: % prioritario
A5: Juego e interacción | B5: =COUNTIF(Indicadores!$C$2:$C$105,A5) -> 16 | C5: =COUNTIFS(Indicadores!$C$2:$C$105,$A5,Indicadores!$G$2:$G$105,"Prioritario") -> 5 | D5: =COUNTIFS(Indicadores!$C$2:$C$105,$A5,Indicadores!$G$2:$G$105,"Complementario") -> 11 | E5: =COUNTIFS(Indicadores!$C$2:$C$105,$A5,Indicadores!$G$2:$G$105,"Contexto") -> 0 | F5: =IF(B5=0,0,C5/B5) -> 0.3125
A6: Inclusión y cuidado | B6: =COUNTIF(Indicadores!$C$2:$C$105,A6) -> 20 | C6: =COUNTIFS(Indicadores!$C$2:$C$105,$A6,Indicadores!$G$2:$G$105,"Prioritario") -> 7 | D6: =COUNTIFS(Indicadores!$C$2:$C$105,$A6,Indicadores!$G$2:$G$105,"Complementario") -> 13 | E6: =COUNTIFS(Indicadores!$C$2:$C$105,$A6,Indicadores!$G$2:$G$105,"Contexto") -> 0 | F6: =IF(B6=0,0,C6/B6) -> 0.35
A7: Usos y actividades | B7: =COUNTIF(Indicadores!$C$2:$C$105,A7) -> 15 | C7: =COUNTIFS(Indicadores!$C$2:$C$105,$A7,Indicadores!$G$2:$G$105,"Prioritario") -> 3 | D7: =COUNTIFS(Indicadores!$C$2:$C$105,$A7,Indicadores!$G$2:$G$105,"Complementario") -> 9 | E7: =COUNTIFS(Indicadores!$C$2:$C$105,$A7,Indicadores!$G$2:$G$105,"Contexto") -> 3 | F7: =IF(B7=0,0,C7/B7) -> 0.2
A8: Calidad y funcionalidad del espacio | B8: =COUNTIF(Indicadores!$C$2:$C$105,A8) -> 24 | C8: =COUNTIFS(Indicadores!$C$2:$C$105,$A8,Indicadores!$G$2:$G$105,"Prioritario") -> 6 | D8: =COUNTIFS(Indicadores!$C$2:$C$105,$A8,Indicadores!$G$2:$G$105,"Complementario") -> 18 | E8: =COUNTIFS(Indicadores!$C$2:$C$105,$A8,Indicadores!$G$2:$G$105,"Contexto") -> 0 | F8: =IF(B8=0,0,C8/B8) -> 0.25
A9: Medio ambiente y resiliencia climática | B9: =COUNTIF(Indicadores!$C$2:$C$105,A9) -> 15 | C9: =COUNTIFS(Indicadores!$C$2:$C$105,$A9,Indicadores!$G$2:$G$105,"Prioritario") -> 3 | D9: =COUNTIFS(Indicadores!$C$2:$C$105,$A9,Indicadores!$G$2:$G$105,"Complementario") -> 12 | E9: =COUNTIFS(Indicadores!$C$2:$C$105,$A9,Indicadores!$G$2:$G$105,"Contexto") -> 0 | F9: =IF(B9=0,0,C9/B9) -> 0.2
A10: Seguridad y protección | B10: =COUNTIF(Indicadores!$C$2:$C$105,A10) -> 9 | C10: =COUNTIFS(Indicadores!$C$2:$C$105,$A10,Indicadores!$G$2:$G$105,"Prioritario") -> 4 | D10: =COUNTIFS(Indicadores!$C$2:$C$105,$A10,Indicadores!$G$2:$G$105,"Complementario") -> 5 | E10: =COUNTIFS(Indicadores!$C$2:$C$105,$A10,Indicadores!$G$2:$G$105,"Contexto") -> 0 | F10: =IF(B10=0,0,C10/B10) -> 0.44444444
A11: Accesibilidad y conectividad | B11: =COUNTIF(Indicadores!$C$2:$C$105,A11) -> 5 | C11: =COUNTIFS(Indicadores!$C$2:$C$105,$A11,Indicadores!$G$2:$G$105,"Prioritario") -> 2 | D11: =COUNTIFS(Indicadores!$C$2:$C$105,$A11,Indicadores!$G$2:$G$105,"Complementario") -> 2 | E11: =COUNTIFS(Indicadores!$C$2:$C$105,$A11,Indicadores!$G$2:$G$105,"Contexto") -> 1 | F11: =IF(B11=0,0,C11/B11) -> 0.4
A12: Total | B12: =SUM(B5:B11) -> 104 | C12: =SUM(C5:C11) -> 30 | D12: =SUM(D5:D11) -> 70 | E12: =SUM(E5:E11) -> 4 | F12: =IF(B12=0,0,C12/B12) -> 0.28846154
A14: Indicadores prioritarios por dimensión y tipo de evidencia
A15: Dimensión | B15: Condiciones del espacio | C15: Comportamiento observado | D15: Comportamiento reportado | E15: Percepción
A16: Juego e interacción | B16: =COUNTIFS(Indicadores!$C$2:$C$105,$A16,Indicadores!$E$2:$E$105,"Cambio en las condiciones del espacio",Indicadores!$G$2:$G$105,"Prioritario") -> 1 | C16: =COUNTIFS(Indicadores!$C$2:$C$105,$A16,Indicadores!$E$2:$E$105,"Cambio de comportamiento observado",Indicadores!$G$2:$G$105,"Prioritario") -> 3 | D16: =COUNTIFS(Indicadores!$C$2:$C$105,$A16,Indicadores!$E$2:$E$105,"Cambio de comportamiento reportado",Indicadores!$G$2:$G$105,"Prioritario") -> 0 | E16: =COUNTIFS(Indicadores!$C$2:$C$105,$A16,Indicadores!$E$2:$E$105,"Cambio en la percepción",Indicadores!$G$2:$G$105,"Prioritario") -> 1
A17: Inclusión y cuidado | B17: =COUNTIFS(Indicadores!$C$2:$C$105,$A17,Indicadores!$E$2:$E$105,"Cambio en las condiciones del espacio",Indicadores!$G$2:$G$105,"Prioritario") -> 2 | C17: =COUNTIFS(Indicadores!$C$2:$C$105,$A17,Indicadores!$E$2:$E$105,"Cambio de comportamiento observado",Indicadores!$G$2:$G$105,"Prioritario") -> 1 | D17: =COUNTIFS(Indicadores!$C$2:$C$105,$A17,Indicadores!$E$2:$E$105,"Cambio de comportamiento reportado",Indicadores!$G$2:$G$105,"Prioritario") -> 0 | E17: =COUNTIFS(Indicadores!$C$2:$C$105,$A17,Indicadores!$E$2:$E$105,"Cambio en la percepción",Indicadores!$G$2:$G$105,"Prioritario") -> 4
A18: Usos y actividades | B18: =COUNTIFS(Indicadores!$C$2:$C$105,$A18,Indicadores!$E$2:$E$105,"Cambio en las condiciones del espacio",Indicadores!$G$2:$G$105,"Prioritario") -> 0 | C18: =COUNTIFS(Indicadores!$C$2:$C$105,$A18,Indicadores!$E$2:$E$105,"Cambio de comportamiento observado",Indicadores!$G$2:$G$105,"Prioritario") -> 1 | D18: =COUNTIFS(Indicadores!$C$2:$C$105,$A18,Indicadores!$E$2:$E$105,"Cambio de comportamiento reportado",Indicadores!$G$2:$G$105,"Prioritario") -> 2 | E18: =COUNTIFS(Indicadores!$C$2:$C$105,$A18,Indicadores!$E$2:$E$105,"Cambio en la percepción",Indicadores!$G$2:$G$105,"Prioritario") -> 0
A19: Calidad y funcionalidad del espacio | B19: =COUNTIFS(Indicadores!$C$2:$C$105,$A19,Indicadores!$E$2:$E$105,"Cambio en las condiciones del espacio",Indicadores!$G$2:$G$105,"Prioritario") -> 3 | C19: =COUNTIFS(Indicadores!$C$2:$C$105,$A19,Indicadores!$E$2:$E$105,"Cambio de comportamiento observado",Indicadores!$G$2:$G$105,"Prioritario") -> 1 | D19: =COUNTIFS(Indicadores!$C$2:$C$105,$A19,Indicadores!$E$2:$E$105,"Cambio de comportamiento reportado",Indicadores!$G$2:$G$105,"Prioritario") -> 0 | E19: =COUNTIFS(Indicadores!$C$2:$C$105,$A19,Indicadores!$E$2:$E$105,"Cambio en la percepción",Indicadores!$G$2:$G$105,"Prioritario") -> 2
A20: Medio ambiente y resiliencia climática | B20: =COUNTIFS(Indicadores!$C$2:$C$105,$A20,Indicadores!$E$2:$E$105,"Cambio en las condiciones del espacio",Indicadores!$G$2:$G$105,"Prioritario") -> 2 | C20: =COUNTIFS(Indicadores!$C$2:$C$105,$A20,Indicadores!$E$2:$E$105,"Cambio de comportamiento observado",Indicadores!$G$2:$G$105,"Prioritario") -> 0 | D20: =COUNTIFS(Indicadores!$C$2:$C$105,$A20,Indicadores!$E$2:$E$105,"Cambio de comportamiento reportado",Indicadores!$G$2:$G$105,"Prioritario") -> 0 | E20: =COUNTIFS(Indicadores!$C$2:$C$105,$A20,Indicadores!$E$2:$E$105,"Cambio en la percepción",Indicadores!$G$2:$G$105,"Prioritario") -> 1
A21: Seguridad y protección | B21: =COUNTIFS(Indicadores!$C$2:$C$105,$A21,Indicadores!$E$2:$E$105,"Cambio en las condiciones del espacio",Indicadores!$G$2:$G$105,"Prioritario") -> 2 | C21: =COUNTIFS(Indicadores!$C$2:$C$105,$A21,Indicadores!$E$2:$E$105,"Cambio de comportamiento observado",Indicadores!$G$2:$G$105,"Prioritario") -> 0 | D21: =COUNTIFS(Indicadores!$C$2:$C$105,$A21,Indicadores!$E$2:$E$105,"Cambio de comportamiento reportado",Indicadores!$G$2:$G$105,"Prioritario") -> 0 | E21: =COUNTIFS(Indicadores!$C$2:$C$105,$A21,Indicadores!$E$2:$E$105,"Cambio en la percepción",Indicadores!$G$2:$G$105,"Prioritario") -> 2
A22: Accesibilidad y conectividad | B22: =COUNTIFS(Indicadores!$C$2:$C$105,$A22,Indicadores!$E$2:$E$105,"Cambio en las condiciones del espacio",Indicadores!$G$2:$G$105,"Prioritario") -> 1 | C22: =COUNTIFS(Indicadores!$C$2:$C$105,$A22,Indicadores!$E$2:$E$105,"Cambio de comportamiento observado",Indicadores!$G$2:$G$105,"Prioritario") -> 0 | D22: =COUNTIFS(Indicadores!$C$2:$C$105,$A22,Indicadores!$E$2:$E$105,"Cambio de comportamiento reportado",Indicadores!$G$2:$G$105,"Prioritario") -> 0 | E22: =COUNTIFS(Indicadores!$C$2:$C$105,$A22,Indicadores!$E$2:$E$105,"Cambio en la percepción",Indicadores!$G$2:$G$105,"Prioritario") -> 1
A24: Lectura: cada dimensión debería tener al menos una condición del espacio y un uso o percepción, para poder explicar el cambio (se modificó el espacio → cambió el uso → cambió la percepción).
