Workbook

Sheet Instrucciones
A1: Registro de asistencia y actividades
A2: Control diario de asistencia, reporte hora por hora y alineación con las metas generales
A4: Cómo usar este archivo
A5: 1. Metas | B5: Captura una vez las metas generales del equipo (ID + nombre). Cada actividad se ligará a una de ellas.
A6: 2. Personal | B6: Da de alta a cada colaborador con su área y horario programado. Los nombres aparecen en las listas desplegables.
A7: 3. Asistencia | B7: Una fila por persona por día: estado, hora de entrada, hora de salida y resumen del día. Si NO trabajó (o trabajó medio día), es obligatorio elegir el motivo y escribir la explicación.
A8: 4. Registro por hora | B8: Una fila por cada hora (o bloque) trabajado (no registres la comida): qué hizo, a qué meta contribuye y qué resultado obtuvo. La suma de bloques debe cubrir las horas trabajadas del día.
A9: 5. Resumen | B9: Elige el rango de fechas y revisa asistencia, horas reportadas por persona y horas dedicadas a cada meta.
A10: Código de colores
A11: Celda amarilla | B11: Captura (tú escribes aquí).
A12: Celda gris | B12: Fórmula automática. No escribir.
A13: ⚠ en columna Alerta | B13: Falta información: motivo de ausencia, explicación, horas de entrada/salida u horas sin reportar.
A14: Ejemplos
A15: Filas en gris cursiva | B15: Son ejemplos para mostrar el formato. Bórralos (solo las celdas amarillas) antes de empezar a usar el archivo. Las metas y el personal de ejemplo también se deben reemplazar.
A16: Formato de hora | B16: Escribe horas en formato 24 h, p. ej. 09:00, 13:30, 18:00. Fechas como 07/10/2026.

Sheet Asistencia
A1: Asistencia diaria
A2: Una fila por persona por día. Si no trabajó: elige el motivo y escribe la explicación (obligatorio).
A4: Fecha | B4: Colaborador | C4: Área | D4: Estado | E4: Hora entrada | F4: Hora salida | G4: Comida / descanso (h) | H4: Horas trabajadas | I4: Motivo (si no trabajó o medio día) | J4: Explicación del motivo | K4: Resumen de lo que hizo en el día | L4: Horas reportadas hora por hora | M4: Alerta
A5: 46301 | B5: Ana López | C5: =IF(B5="","",IFERROR(INDEX(Personal!$C$5:$C$104,MATCH(B5,Personal!$B$5:$B$104,0)),"")) -> Ventas | D5: Asistió | E5: 0.375 | F5: 0.75 | G5: 1 | H5: =IF(OR(E5="",F5=""),"",ROUND(MOD(F5-E5,1)*24-N(G5),2)) -> 8 | K5: Llamadas de prospección, 2 reuniones con clientes, propuesta para cliente nuevo y cierre de pedido. | L5: =IF(OR(A5="",B5=""),"",SUMIFS('Registro por hora'!$H$5:$H$2004,'Registro por hora'!$A$5:$A$2004,A5,'Registro por hora'!$B$5:$B$2004,B5)) -> 8 | M5: =IF(B5="","",IF(D5="","⚠ Falta estado",IF(AND(OR(D5="Ausente",D5="Medio día"),I5=""),"⚠ Falta motivo",IF(AND(OR(D5="Ausente",D5="Medio día"),J5=""),"⚠ Falta explicación",IF(D5="Ausente","✔ Ausencia justificada",IF(OR(E5="",F5=""),"⚠ Falta hora de entrada/salida",IF(K5="","⚠ Falta resumen del día",IF(N(L5)<N(H5)-0.01,"⚠ Faltan "&TEXT(N(H5)-N(L5),"0.0")&" h por reportar","✔ OK")))))))) -> ✔ OK
A6: 46301 | B6: Carlos Ruiz | C6: =IF(B6="","",IFERROR(INDEX(Personal!$C$5:$C$104,MATCH(B6,Personal!$B$5:$B$104,0)),"")) -> Atención a clientes | D6: Ausente | H6: =IF(OR(E6="",F6=""),"",ROUND(MOD(F6-E6,1)*24-N(G6),2)) | I6: Enfermedad | J6: Infección estomacal; presenta receta médica el miércoles. | L6: =IF(OR(A6="",B6=""),"",SUMIFS('Registro por hora'!$H$5:$H$2004,'Registro por hora'!$A$5:$A$2004,A6,'Registro por hora'!$B$5:$B$2004,B6)) -> 0 | M6: =IF(B6="","",IF(D6="","⚠ Falta estado",IF(AND(OR(D6="Ausente",D6="Medio día"),I6=""),"⚠ Falta motivo",IF(AND(OR(D6="Ausente",D6="Medio día"),J6=""),"⚠ Falta explicación",IF(D6="Ausente","✔ Ausencia justificada",IF(OR(E6="",F6=""),"⚠ Falta hora de entrada/salida",IF(K6="","⚠ Falta resumen del día",IF(N(L6)<N(H6)-0.01,"⚠ Faltan "&TEXT(N(H6)-N(L6),"0.0")&" h por reportar","✔ OK")))))))) -> ✔ Ausencia justificada
C7: =IF(B7="","",IFERROR(INDEX(Personal!$C$5:$C$104,MATCH(B7,Personal!$B$5:$B$104,0)),"")) | H7: =IF(OR(E7="",F7=""),"",ROUND(MOD(F7-E7,1)*24-N(G7),2)) | L7: =IF(OR(A7="",B7=""),"",SUMIFS('Registro por hora'!$H$5:$H$2004,'Registro por hora'!$A$5:$A$2004,A7,'Registro por hora'!$B$5:$B$2004,B7)) | M7: =IF(B7="","",IF(D7="","⚠ Falta estado",IF(AND(OR(D7="Ausente",D7="Medio día"),I7=""),"⚠ Falta motivo",IF(AND(OR(D7="Ausente",D7="Medio día"),J7=""),"⚠ Falta explicación",IF(D7="Ausente","✔ Ausencia justificada",IF(OR(E7="",F7=""),"⚠ Falta hora de entrada/salida",IF(K7="","⚠ Falta resumen del día",IF(N(L7)<N(H7)-0.01,"⚠ Faltan "&TEXT(N(H7)-N(L7),"0.0")&" h por reportar","✔ OK"))))))))
C8: =IF(B8="","",IFERROR(INDEX(Personal!$C$5:$C$104,MATCH(B8,Personal!$B$5:$B$104,0)),"")) | H8: =IF(OR(E8="",F8=""),"",ROUND(MOD(F8-E8,1)*24-N(G8),2)) | L8: =IF(OR(A8="",B8=""),"",SUMIFS('Registro por hora'!$H$5:$H$2004,'Registro por hora'!$A$5:$A$2004,A8,'Registro por hora'!$B$5:$B$2004,B8)) | M8: =IF(B8="","",IF(D8="","⚠ Falta estado",IF(AND(OR(D8="Ausente",D8="Medio día"),I8=""),"⚠ Falta motivo",IF(AND(OR(D8="Ausente",D8="Medio día"),J8=""),"⚠ Falta explicación",IF(D8="Ausente","✔ Ausencia justificada",IF(OR(E8="",F8=""),"⚠ Falta hora de entrada/salida",IF(K8="","⚠ Falta resumen del día",IF(N(L8)<N(H8)-0.01,"⚠ Faltan "&TEXT(N(H8)-N(L8),"0.0")&" h por reportar","✔ OK"))))))))
C9: =IF(B9="","",IFERROR(INDEX(Personal!$C$5:$C$104,MATCH(B9,Personal!$B$5:$B$104,0)),"")) | H9: =IF(OR(E9="",F9=""),"",ROUND(MOD(F9-E9,1)*24-N(G9),2)) | L9: =IF(OR(A9="",B9=""),"",SUMIFS('Registro por hora'!$H$5:$H$2004,'Registro por hora'!$A$5:$A$2004,A9,'Registro por hora'!$B$5:$B$2004,B9)) | M9: =IF(B9="","",IF(D9="","⚠ Falta estado",IF(AND(OR(D9="Ausente",D9="Medio día"),I9=""),"⚠ Falta motivo",IF(AND(OR(D9="Ausente",D9="Medio día"),J9=""),"⚠ Falta explicación",IF(D9="Ausente","✔ Ausencia justificada",IF(OR(E9="",F9=""),"⚠ Falta hora de entrada/salida",IF(K9="","⚠ Falta resumen del día",IF(N(L9)<N(H9)-0.01,"⚠ Faltan "&TEXT(N(H9)-N(L9),"0.0")&" h por reportar","✔ OK"))))))))
C10: =IF(B10="","",IFERROR(INDEX(Personal!$C$5:$C$104,MATCH(B10,Personal!$B$5:$B$104,0)),"")) | H10: =IF(OR(E10="",F10=""),"",ROUND(MOD(F10-E10,1)*24-N(G10),2)) | L10: =IF(OR(A10="",B10=""),"",SUMIFS('Registro por hora'!$H$5:$H$2004,'Registro por hora'!$A$5:$A$2004,A10,'Registro por hora'!$B$5:$B$2004,B10)) | M10: =IF(B10="","",IF(D10="","⚠ Falta estado",IF(AND(OR(D10="Ausente",D10="Medio día"),I10=""),"⚠ Falta motivo",IF(AND(OR(D10="Ausente",D10="Medio día"),J10=""),"⚠ Falta explicación",IF(D10="Ausente","✔ Ausencia justificada",IF(OR(E10="",F10=""),"⚠ Falta hora de entrada/salida",IF(K10="","⚠ Falta resumen del día",IF(N(L10)<N(H10)-0.01,"⚠ Faltan "&TEXT(N(H10)-N(L10),"0.0")&" h por reportar","✔ OK"))))))))
C11: =IF(B11="","",IFERROR(INDEX(Personal!$C$5:$C$104,MATCH(B11,Personal!$B$5:$B$104,0)),"")) | H11: =IF(OR(E11="",F11=""),"",ROUND(MOD(F11-E11,1)*24-N(G11),2)) | L11: =IF(OR(A11="",B11=""),"",SUMIFS('Registro por hora'!$H$5:$H$2004,'Registro por hora'!$A$5:$A$2004,A11,'Registro por hora'!$B$5:$B$2004,B11)) | M11: =IF(B11="","",IF(D11="","⚠ Falta estado",IF(AND(OR(D11="Ausente",D11="Medio día"),I11=""),"⚠ Falta motivo",IF(AND(OR(D11="Ausente",D11="Medio día"),J11=""),"⚠ Falta explicación",IF(D11="Ausente","✔ Ausencia justificada",IF(OR(E11="",F11=""),"⚠ Falta hora de entrada/salida",IF(K11="","⚠ Falta resumen del día",IF(N(L11)<N(H11)-0.01,"⚠ Faltan "&TEXT(N(H11)-N(L11),"0.0")&" h por reportar","✔ OK"))))))))
C12: =IF(B12="","",IFERROR(INDEX(Personal!$C$5:$C$104,MATCH(B12,Personal!$B$5:$B$104,0)),"")) | H12: =IF(OR(E12="",F12=""),"",ROUND(MOD(F12-E12,1)*24-N(G12),2)) | L12: =IF(OR(A12="",B12=""),"",SUMIFS('Registro por hora'!$H$5:$H$2004,'Registro por hora'!$A$5:$A$2004,A12,'Registro por hora'!$B$5:$B$2004,B12)) | M12: =IF(B12="","",IF(D12="","⚠ Falta estado",IF(AND(OR(D12="Ausente",D12="Medio día"),I12=""),"⚠ Falta motivo",IF(AND(OR(D12="Ausente",D12="Medio día"),J12=""),"⚠ Falta explicación",IF(D12="Ausente","✔ Ausencia justificada",IF(OR(E12="",F12=""),"⚠ Falta hora de entrada/salida",IF(K12="","⚠ Falta resumen del día",IF(N(L12)<N(H12)-0.01,"⚠ Faltan "&TEXT(N(H12)-N(L12),"0.0")&" h por reportar","✔ OK"))))))))
C13: =IF(B13="","",IFERROR(INDEX(Personal!$C$5:$C$104,MATCH(B13,Personal!$B$5:$B$104,0)),"")) | H13: =IF(OR(E13="",F13=""),"",ROUND(MOD(F13-E13,1)*24-N(G13),2)) | L13: =IF(OR(A13="",B13=""),"",SUMIFS('Registro por hora'!$H$5:$H$2004,'Registro por hora'!$A$5:$A$2004,A13,'Registro por hora'!$B$5:$B$2004,B13)) | M13: =IF(B13="","",IF(D13="","⚠ Falta estado",IF(AND(OR(D13="Ausente",D13="Medio día"),I13=""),"⚠ Falta motivo",IF(AND(OR(D13="Ausente",D13="Medio día"),J13=""),"⚠ Falta explicación",IF(D13="Ausente","✔ Ausencia justificada",IF(OR(E13="",F13=""),"⚠ Falta hora de entrada/salida",IF(K13="","⚠ Falta resumen del día",IF(N(L13)<N(H13)-0.01,"⚠ Faltan "&TEXT(N(H13)-N(L13),"0.0")&" h por reportar","✔ OK"))))))))
C14: =IF(B14="","",IFERROR(INDEX(Personal!$C$5:$C$104,MATCH(B14,Personal!$B$5:$B$104,0)),"")) | H14: =IF(OR(E14="",F14=""),"",ROUND(MOD(F14-E14,1)*24-N(G14),2)) | L14: =IF(OR(A14="",B14=""),"",SUMIFS('Registro por hora'!$H$5:$H$2004,'Registro por hora'!$A$5:$A$2004,A14,'Registro por hora'!$B$5:$B$2004,B14)) | M14: =IF(B14="","",IF(D14="","⚠ Falta estado",IF(AND(OR(D14="Ausente",D14="Medio día"),I14=""),"⚠ Falta motivo",IF(AND(OR(D14="Ausente",D14="Medio día"),J14=""),"⚠ Falta explicación",IF(D14="Ausente","✔ Ausencia justificada",IF(OR(E14="",F14=""),"⚠ Falta hora de entrada/salida",IF(K14="","⚠ Falta resumen del día",IF(N(L14)<N(H14)-0.01,"⚠ Faltan "&TEXT(N(H14)-N(L14),"0.0")&" h por reportar","✔ OK"))))))))
C15: =IF(B15="","",IFERROR(INDEX(Personal!$C$5:$C$104,MATCH(B15,Personal!$B$5:$B$104,0)),"")) | H15: =IF(OR(E15="",F15=""),"",ROUND(MOD(F15-E15,1)*24-N(G15),2)) | L15: =IF(OR(A15="",B15=""),"",SUMIFS('Registro por hora'!$H$5:$H$2004,'Registro por hora'!$A$5:$A$2004,A15,'Registro por hora'!$B$5:$B$2004,B15)) | M15: =IF(B15="","",IF(D15="","⚠ Falta estado",IF(AND(OR(D15="Ausente",D15="Medio día"),I15=""),"⚠ Falta motivo",IF(AND(OR(D15="Ausente",D15="Medio día"),J15=""),"⚠ Falta explicación",IF(D15="Ausente","✔ Ausencia justificada",IF(OR(E15="",F15=""),"⚠ Falta hora de entrada/salida",IF(K15="","⚠ Falta resumen del día",IF(N(L15)<N(H15)-0.01,"⚠ Faltan "&TEXT(N(H15)-N(L15),"0.0")&" h por reportar","✔ OK"))))))))
C16: =IF(B16="","",IFERROR(INDEX(Personal!$C$5:$C$104,MATCH(B16,Personal!$B$5:$B$104,0)),"")) | H16: =IF(OR(E16="",F16=""),"",ROUND(MOD(F16-E16,1)*24-N(G16),2)) | L16: =IF(OR(A16="",B16=""),"",SUMIFS('Registro por hora'!$H$5:$H$2004,'Registro por hora'!$A$5:$A$2004,A16,'Registro por hora'!$B$5:$B$2004,B16)) | M16: =IF(B16="","",IF(D16="","⚠ Falta estado",IF(AND(OR(D16="Ausente",D16="Medio día"),I16=""),"⚠ Falta motivo",IF(AND(OR(D16="Ausente",D16="Medio día"),J16=""),"⚠ Falta explicación",IF(D16="Ausente","✔ Ausencia justificada",IF(OR(E16="",F16=""),"⚠ Falta hora de entrada/salida",IF(K16="","⚠ Falta resumen del día",IF(N(L16)<N(H16)-0.01,"⚠ Faltan "&TEXT(N(H16)-N(L16),"0.0")&" h por reportar","✔ OK"))))))))
C17: =IF(B17="","",IFERROR(INDEX(Personal!$C$5:$C$104,MATCH(B17,Personal!$B$5:$B$104,0)),"")) | H17: =IF(OR(E17="",F17=""),"",ROUND(MOD(F17-E17,1)*24-N(G17),2)) | L17: =IF(OR(A17="",B17=""),"",SUMIFS('Registro por hora'!$H$5:$H$2004,'Registro por hora'!$A$5:$A$2004,A17,'Registro por hora'!$B$5:$B$2004,B17)) | M17: =IF(B17="","",IF(D17="","⚠ Falta estado",IF(AND(OR(D17="Ausente",D17="Medio día"),I17=""),"⚠ Falta motivo",IF(AND(OR(D17="Ausente",D17="Medio día"),J17=""),"⚠ Falta explicación",IF(D17="Ausente","✔ Ausencia justificada",IF(OR(E17="",F17=""),"⚠ Falta hora de entrada/salida",IF(K17="","⚠ Falta resumen del día",IF(N(L17)<N(H17)-0.01,"⚠ Faltan "&TEXT(N(H17)-N(L17),"0.0")&" h por reportar","✔ OK"))))))))
C18: =IF(B18="","",IFERROR(INDEX(Personal!$C$5:$C$104,MATCH(B18,Personal!$B$5:$B$104,0)),"")) | H18: =IF(OR(E18="",F18=""),"",ROUND(MOD(F18-E18,1)*24-N(G18),2)) | L18: =IF(OR(A18="",B18=""),"",SUMIFS('Registro por hora'!$H$5:$H$2004,'Registro por hora'!$A$5:$A$2004,A18,'Registro por hora'!$B$5:$B$2004,B18)) | M18: =IF(B18="","",IF(D18="","⚠ Falta estado",IF(AND(OR(D18="Ausente",D18="Medio día"),I18=""),"⚠ Falta motivo",IF(AND(OR(D18="Ausente",D18="Medio día"),J18=""),"⚠ Falta explicación",IF(D18="Ausente","✔ Ausencia justificada",IF(OR(E18="",F18=""),"⚠ Falta hora de entrada/salida",IF(K18="","⚠ Falta resumen del día",IF(N(L18)<N(H18)-0.01,"⚠ Faltan "&TEXT(N(H18)-N(L18),"0.0")&" h por reportar","✔ OK"))))))))
... C504: =IF(B504="","",IFERROR(INDEX(Personal!$C$5:$C$104,MATCH(B504,Personal!$B$5:$B$104,0)),"")) | H504: =IF(OR(E504="",F504=""),"",ROUND(MOD(F504-E504,1)*24-N(G504),2)) | L504: =IF(OR(A504="",B504=""),"",SUMIFS('Registro por hora'!$H$5:$H$2004,'Registro por hora'!$A$5:$A$2004,A504,'Registro por hora'!$B$5:$B$2004,B504)) | M504: =IF(B504="","",IF(D504="","⚠ Falta estado",IF(AND(OR(D504="Ausente",D504="Medio día"),I504=""),"⚠ Falta motivo",IF(AND(OR(D504="Ausente",D504="Medio día"),J504=""),"⚠ Falta explicación",IF(D504="Ausente","✔ Ausencia justificada",IF(OR(E504="",F504=""),"⚠ Falta hora de entrada/salida",IF(K504="","⚠ Falta resumen del día",IF(N(L504)<N(H504)-0.01,"⚠ Faltan "&TEXT(N(H504)-N(L504),"0.0")&" h por reportar","✔ OK"))))))))

Sheet Registro por hora
A1: Registro hora por hora
A2: Una fila por cada hora (o bloque) trabajado. Liga cada actividad a una meta (ID de la pestaña Metas).
A4: Fecha | B4: Colaborador | C4: Hora inicio | D4: Hora fin | E4: Actividad realizada | F4: Meta (ID) | G4: Meta relacionada | H4: Duración (h) | I4: Resultado / entregable | J4: Estatus | K4: Comentarios / bloqueos
A5: 46301 | B5: Ana López | C5: 0.375 | D5: 0.41666667 | E5: Revisión de correos y agenda; seguimiento a 8 prospectos | F5: M1 | G5: =IF(F5="","",IFERROR(INDEX(Metas!$B$5:$B$54,MATCH(F5,Metas!$A$5:$A$54,0)),"⚠ ID de meta no existe")) -> Incrementar ventas 15% en el año | H5: =IF(OR(C5="",D5=""),"",ROUND(MOD(D5-C5,1)*24,2)) -> 1 | I5: 8 prospectos contactados | J5: Completada
A6: 46301 | B6: Ana López | C6: 0.41666667 | D6: 0.45833333 | E6: Llamadas de prospección en frío | F6: M1 | G6: =IF(F6="","",IFERROR(INDEX(Metas!$B$5:$B$54,MATCH(F6,Metas!$A$5:$A$54,0)),"⚠ ID de meta no existe")) -> Incrementar ventas 15% en el año | H6: =IF(OR(C6="",D6=""),"",ROUND(MOD(D6-C6,1)*24,2)) -> 1 | I6: 12 llamadas, 3 citas agendadas | J6: Completada
A7: 46301 | B7: Ana López | C7: 0.45833333 | D7: 0.5 | E7: Reunión con cliente Grupo Alfa | F7: M1 | G7: =IF(F7="","",IFERROR(INDEX(Metas!$B$5:$B$54,MATCH(F7,Metas!$A$5:$A$54,0)),"⚠ ID de meta no existe")) -> Incrementar ventas 15% en el año | H7: =IF(OR(C7="",D7=""),"",ROUND(MOD(D7-C7,1)*24,2)) -> 1 | I7: Requerimientos levantados | J7: Completada
A8: 46301 | B8: Ana López | C8: 0.5 | D8: 0.54166667 | E8: Elaboración de propuesta comercial Grupo Alfa | F8: M1 | G8: =IF(F8="","",IFERROR(INDEX(Metas!$B$5:$B$54,MATCH(F8,Metas!$A$5:$A$54,0)),"⚠ ID de meta no existe")) -> Incrementar ventas 15% en el año | H8: =IF(OR(C8="",D8=""),"",ROUND(MOD(D8-C8,1)*24,2)) -> 1 | I8: Borrador de propuesta | J8: En progreso | K8: Falta validar precios con Dirección
A9: 46301 | B9: Ana López | C9: 0.58333333 | D9: 0.625 | E9: Atención de queja de cliente Beta | F9: M2 | G9: =IF(F9="","",IFERROR(INDEX(Metas!$B$5:$B$54,MATCH(F9,Metas!$A$5:$A$54,0)),"⚠ ID de meta no existe")) -> Mejorar satisfacción del cliente | H9: =IF(OR(C9="",D9=""),"",ROUND(MOD(D9-C9,1)*24,2)) -> 1 | I9: Queja resuelta, cliente notificado | J9: Completada
A10: 46301 | B10: Ana López | C10: 0.625 | D10: 0.66666667 | E10: Junta semanal del equipo comercial | F10: M0 | G10: =IF(F10="","",IFERROR(INDEX(Metas!$B$5:$B$54,MATCH(F10,Metas!$A$5:$A$54,0)),"⚠ ID de meta no existe")) -> Administrativo / soporte general | H10: =IF(OR(C10="",D10=""),"",ROUND(MOD(D10-C10,1)*24,2)) -> 1 | I10: Acuerdos registrados en minuta | J10: Completada
A11: 46301 | B11: Ana López | C11: 0.66666667 | D11: 0.70833333 | E11: Curso en línea de negociación (módulo 2) | F11: M5 | G11: =IF(F11="","",IFERROR(INDEX(Metas!$B$5:$B$54,MATCH(F11,Metas!$A$5:$A$54,0)),"⚠ ID de meta no existe")) -> Capacitación y desarrollo del equipo | H11: =IF(OR(C11="",D11=""),"",ROUND(MOD(D11-C11,1)*24,2)) -> 1 | I11: Módulo 2 terminado | J11: Completada
A12: 46301 | B12: Ana López | C12: 0.70833333 | D12: 0.75 | E12: Cierre de pedido cliente Gamma y registro en CRM | F12: M1 | G12: =IF(F12="","",IFERROR(INDEX(Metas!$B$5:$B$54,MATCH(F12,Metas!$A$5:$A$54,0)),"⚠ ID de meta no existe")) -> Incrementar ventas 15% en el año | H12: =IF(OR(C12="",D12=""),"",ROUND(MOD(D12-C12,1)*24,2)) -> 1 | I12: Pedido por $45,000 cerrado | J12: Completada
G13: =IF(F13="","",IFERROR(INDEX(Metas!$B$5:$B$54,MATCH(F13,Metas!$A$5:$A$54,0)),"⚠ ID de meta no existe")) | H13: =IF(OR(C13="",D13=""),"",ROUND(MOD(D13-C13,1)*24,2))
G14: =IF(F14="","",IFERROR(INDEX(Metas!$B$5:$B$54,MATCH(F14,Metas!$A$5:$A$54,0)),"⚠ ID de meta no existe")) | H14: =IF(OR(C14="",D14=""),"",ROUND(MOD(D14-C14,1)*24,2))
G15: =IF(F15="","",IFERROR(INDEX(Metas!$B$5:$B$54,MATCH(F15,Metas!$A$5:$A$54,0)),"⚠ ID de meta no existe")) | H15: =IF(OR(C15="",D15=""),"",ROUND(MOD(D15-C15,1)*24,2))
G16: =IF(F16="","",IFERROR(INDEX(Metas!$B$5:$B$54,MATCH(F16,Metas!$A$5:$A$54,0)),"⚠ ID de meta no existe")) | H16: =IF(OR(C16="",D16=""),"",ROUND(MOD(D16-C16,1)*24,2))
G17: =IF(F17="","",IFERROR(INDEX(Metas!$B$5:$B$54,MATCH(F17,Metas!$A$5:$A$54,0)),"⚠ ID de meta no existe")) | H17: =IF(OR(C17="",D17=""),"",ROUND(MOD(D17-C17,1)*24,2))
G18: =IF(F18="","",IFERROR(INDEX(Metas!$B$5:$B$54,MATCH(F18,Metas!$A$5:$A$54,0)),"⚠ ID de meta no existe")) | H18: =IF(OR(C18="",D18=""),"",ROUND(MOD(D18-C18,1)*24,2))
G19: =IF(F19="","",IFERROR(INDEX(Metas!$B$5:$B$54,MATCH(F19,Metas!$A$5:$A$54,0)),"⚠ ID de meta no existe")) | H19: =IF(OR(C19="",D19=""),"",ROUND(MOD(D19-C19,1)*24,2))
G20: =IF(F20="","",IFERROR(INDEX(Metas!$B$5:$B$54,MATCH(F20,Metas!$A$5:$A$54,0)),"⚠ ID de meta no existe")) | H20: =IF(OR(C20="",D20=""),"",ROUND(MOD(D20-C20,1)*24,2))
G21: =IF(F21="","",IFERROR(INDEX(Metas!$B$5:$B$54,MATCH(F21,Metas!$A$5:$A$54,0)),"⚠ ID de meta no existe")) | H21: =IF(OR(C21="",D21=""),"",ROUND(MOD(D21-C21,1)*24,2))
G22: =IF(F22="","",IFERROR(INDEX(Metas!$B$5:$B$54,MATCH(F22,Metas!$A$5:$A$54,0)),"⚠ ID de meta no existe")) | H22: =IF(OR(C22="",D22=""),"",ROUND(MOD(D22-C22,1)*24,2))
G23: =IF(F23="","",IFERROR(INDEX(Metas!$B$5:$B$54,MATCH(F23,Metas!$A$5:$A$54,0)),"⚠ ID de meta no existe")) | H23: =IF(OR(C23="",D23=""),"",ROUND(MOD(D23-C23,1)*24,2))
G24: =IF(F24="","",IFERROR(INDEX(Metas!$B$5:$B$54,MATCH(F24,Metas!$A$5:$A$54,0)),"⚠ ID de meta no existe")) | H24: =IF(OR(C24="",D24=""),"",ROUND(MOD(D24-C24,1)*24,2))
... G2004: =IF(F2004="","",IFERROR(INDEX(Metas!$B$5:$B$54,MATCH(F2004,Metas!$A$5:$A$54,0)),"⚠ ID de meta no existe")) | H2004: =IF(OR(C2004="",D2004=""),"",ROUND(MOD(D2004-C2004,1)*24,2))

Sheet Metas
A1: Metas generales
A2: Cada actividad del registro por hora se liga a un ID de esta tabla. Reemplaza los ejemplos por las metas reales.
A4: ID | B4: Meta | C4: Descripción / alcance | D4: Indicador (KPI) | E4: Responsable | F4: Fecha límite | G4: Horas dedicadas (total) | H4: % del tiempo reportado
A5: M1 | B5: Incrementar ventas 15% en el año | C5: Prospección, seguimiento y cierre de clientes nuevos | D5: Ventas mensuales vs. meta | E5: Dirección comercial | F5: 46387 | G5: =IF(A5="","",SUMIF('Registro por hora'!$F$5:$F$2004,A5,'Registro por hora'!$H$5:$H$2004)) -> 5 | H5: =IF(OR(A5="",SUM('Registro por hora'!$H$5:$H$2004)=0),"",G5/SUM('Registro por hora'!$H$5:$H$2004)) -> 0.625
A6: M2 | B6: Mejorar satisfacción del cliente | C6: Atención de tickets, quejas y seguimiento postventa | D6: NPS ≥ 60 | E6: Atención a clientes | F6: 46387 | G6: =IF(A6="","",SUMIF('Registro por hora'!$F$5:$F$2004,A6,'Registro por hora'!$H$5:$H$2004)) -> 1 | H6: =IF(OR(A6="",SUM('Registro por hora'!$H$5:$H$2004)=0),"",G6/SUM('Registro por hora'!$H$5:$H$2004)) -> 0.125
A7: M3 | B7: Lanzar nuevo producto / servicio | C7: Desarrollo, pruebas y lanzamiento | D7: Lanzamiento antes de fecha límite | E7: Producto | F7: 46356 | G7: =IF(A7="","",SUMIF('Registro por hora'!$F$5:$F$2004,A7,'Registro por hora'!$H$5:$H$2004)) -> 0 | H7: =IF(OR(A7="",SUM('Registro por hora'!$H$5:$H$2004)=0),"",G7/SUM('Registro por hora'!$H$5:$H$2004)) -> 0
A8: M4 | B8: Optimizar procesos internos | C8: Automatización, documentación y reducción de tiempos | D8: -20% tiempo de proceso | E8: Operaciones | F8: 46371 | G8: =IF(A8="","",SUMIF('Registro por hora'!$F$5:$F$2004,A8,'Registro por hora'!$H$5:$H$2004)) -> 0 | H8: =IF(OR(A8="",SUM('Registro por hora'!$H$5:$H$2004)=0),"",G8/SUM('Registro por hora'!$H$5:$H$2004)) -> 0
A9: M5 | B9: Capacitación y desarrollo del equipo | C9: Cursos, mentorías y certificaciones | D9: 20 h de capacitación por persona | E9: Recursos Humanos | F9: 46387 | G9: =IF(A9="","",SUMIF('Registro por hora'!$F$5:$F$2004,A9,'Registro por hora'!$H$5:$H$2004)) -> 1 | H9: =IF(OR(A9="",SUM('Registro por hora'!$H$5:$H$2004)=0),"",G9/SUM('Registro por hora'!$H$5:$H$2004)) -> 0.125
A10: M0 | B10: Administrativo / soporte general | C10: Juntas, correos y tareas que no corresponden a una meta específica | D10: — | E10: Todos | G10: =IF(A10="","",SUMIF('Registro por hora'!$F$5:$F$2004,A10,'Registro por hora'!$H$5:$H$2004)) -> 1 | H10: =IF(OR(A10="",SUM('Registro por hora'!$H$5:$H$2004)=0),"",G10/SUM('Registro por hora'!$H$5:$H$2004)) -> 0.125
G11: =IF(A11="","",SUMIF('Registro por hora'!$F$5:$F$2004,A11,'Registro por hora'!$H$5:$H$2004)) | H11: =IF(OR(A11="",SUM('Registro por hora'!$H$5:$H$2004)=0),"",G11/SUM('Registro por hora'!$H$5:$H$2004))
G12: =IF(A12="","",SUMIF('Registro por hora'!$F$5:$F$2004,A12,'Registro por hora'!$H$5:$H$2004)) | H12: =IF(OR(A12="",SUM('Registro por hora'!$H$5:$H$2004)=0),"",G12/SUM('Registro por hora'!$H$5:$H$2004))
G13: =IF(A13="","",SUMIF('Registro por hora'!$F$5:$F$2004,A13,'Registro por hora'!$H$5:$H$2004)) | H13: =IF(OR(A13="",SUM('Registro por hora'!$H$5:$H$2004)=0),"",G13/SUM('Registro por hora'!$H$5:$H$2004))
G14: =IF(A14="","",SUMIF('Registro por hora'!$F$5:$F$2004,A14,'Registro por hora'!$H$5:$H$2004)) | H14: =IF(OR(A14="",SUM('Registro por hora'!$H$5:$H$2004)=0),"",G14/SUM('Registro por hora'!$H$5:$H$2004))
G15: =IF(A15="","",SUMIF('Registro por hora'!$F$5:$F$2004,A15,'Registro por hora'!$H$5:$H$2004)) | H15: =IF(OR(A15="",SUM('Registro por hora'!$H$5:$H$2004)=0),"",G15/SUM('Registro por hora'!$H$5:$H$2004))
G16: =IF(A16="","",SUMIF('Registro por hora'!$F$5:$F$2004,A16,'Registro por hora'!$H$5:$H$2004)) | H16: =IF(OR(A16="",SUM('Registro por hora'!$H$5:$H$2004)=0),"",G16/SUM('Registro por hora'!$H$5:$H$2004))
G17: =IF(A17="","",SUMIF('Registro por hora'!$F$5:$F$2004,A17,'Registro por hora'!$H$5:$H$2004)) | H17: =IF(OR(A17="",SUM('Registro por hora'!$H$5:$H$2004)=0),"",G17/SUM('Registro por hora'!$H$5:$H$2004))
G18: =IF(A18="","",SUMIF('Registro por hora'!$F$5:$F$2004,A18,'Registro por hora'!$H$5:$H$2004)) | H18: =IF(OR(A18="",SUM('Registro por hora'!$H$5:$H$2004)=0),"",G18/SUM('Registro por hora'!$H$5:$H$2004))
G19: =IF(A19="","",SUMIF('Registro por hora'!$F$5:$F$2004,A19,'Registro por hora'!$H$5:$H$2004)) | H19: =IF(OR(A19="",SUM('Registro por hora'!$H$5:$H$2004)=0),"",G19/SUM('Registro por hora'!$H$5:$H$2004))
G20: =IF(A20="","",SUMIF('Registro por hora'!$F$5:$F$2004,A20,'Registro por hora'!$H$5:$H$2004)) | H20: =IF(OR(A20="",SUM('Registro por hora'!$H$5:$H$2004)=0),"",G20/SUM('Registro por hora'!$H$5:$H$2004))
G21: =IF(A21="","",SUMIF('Registro por hora'!$F$5:$F$2004,A21,'Registro por hora'!$H$5:$H$2004)) | H21: =IF(OR(A21="",SUM('Registro por hora'!$H$5:$H$2004)=0),"",G21/SUM('Registro por hora'!$H$5:$H$2004))
G22: =IF(A22="","",SUMIF('Registro por hora'!$F$5:$F$2004,A22,'Registro por hora'!$H$5:$H$2004)) | H22: =IF(OR(A22="",SUM('Registro por hora'!$H$5:$H$2004)=0),"",G22/SUM('Registro por hora'!$H$5:$H$2004))
... G54: =IF(A54="","",SUMIF('Registro por hora'!$F$5:$F$2004,A54,'Registro por hora'!$H$5:$H$2004)) | H54: =IF(OR(A54="",SUM('Registro por hora'!$H$5:$H$2004)=0),"",G54/SUM('Registro por hora'!$H$5:$H$2004))

Sheet Personal
A1: Personal
A2: Lista de colaboradores. Los nombres aparecen en los menús de Asistencia y Registro por hora.
A4: ID | B4: Nombre completo | C4: Área | D4: Puesto | E4: Entrada programada | F4: Salida programada
A5: E01 | B5: Ana López | C5: Ventas | D5: Ejecutiva comercial | E5: 0.375 | F5: 0.75
A6: E02 | B6: Carlos Ruiz | C6: Atención a clientes | D6: Analista de soporte | E6: 0.375 | F6: 0.75
A7: E03 | B7: María Hernández | C7: Operaciones | D7: Coordinadora | E7: 0.33333333 | F7: 0.70833333

Sheet Resumen
A1: Resumen
A2: Cambia el rango de fechas (celdas amarillas) para ver el periodo que quieras.
A4: Desde | B4: 46023
A5: Hasta | B5: 46387
A7: Por colaborador | J7: Horas dedicadas por meta
A8: Colaborador | B8: Días trabajados | C8: Ausencias | D8: Ausencias sin motivo | E8: Horas trabajadas | F8: Horas reportadas hora x hora | G8: % de horas reportadas | H8: Promedio horas/día | J8: ID | K8: Meta | L8: Horas | M8: % del total
A9: =IF(Personal!B5="","",Personal!B5) -> Ana López | B9: =IF($A9="","",COUNTIFS(Asistencia!$B$5:$B$504,$A9,Asistencia!$A$5:$A$504,">="&$B$4,Asistencia!$A$5:$A$504,"<="&$B$5)-COUNTIFS(Asistencia!$B$5:$B$504,$A9,Asistencia!$D$5:$D$504,"Ausente",Asistencia!$A$5:$A$504,">="&$B$4,Asistencia!$A$5:$A$504,"<="&$B$5)) -> 1 | C9: =IF($A9="","",COUNTIFS(Asistencia!$B$5:$B$504,$A9,Asistencia!$D$5:$D$504,"Ausente",Asistencia!$A$5:$A$504,">="&$B$4,Asistencia!$A$5:$A$504,"<="&$B$5)) -> 0 | D9: =IF($A9="","",COUNTIFS(Asistencia!$B$5:$B$504,$A9,Asistencia!$D$5:$D$504,"Ausente",Asistencia!$I$5:$I$504,"",Asistencia!$A$5:$A$504,">="&$B$4,Asistencia!$A$5:$A$504,"<="&$B$5)) -> 0 | E9: =IF($A9="","",SUMIFS(Asistencia!$H$5:$H$504,Asistencia!$B$5:$B$504,$A9,Asistencia!$A$5:$A$504,">="&$B$4,Asistencia!$A$5:$A$504,"<="&$B$5)) -> 8 | F9: =IF($A9="","",SUMIFS('Registro por hora'!$H$5:$H$2004,'Registro por hora'!$B$5:$B$2004,$A9,'Registro por hora'!$A$5:$A$2004,">="&$B$4,'Registro por hora'!$A$5:$A$2004,"<="&$B$5)) -> 8 | G9: =IF(OR($A9="",N(E9)=0),"",F9/E9) -> 1 | H9: =IF(OR($A9="",N(B9)=0),"",E9/B9) -> 8 | J9: =IF(Metas!A5="","",Metas!A5) -> M1 | K9: =IF(Metas!A5="","",Metas!B5) -> Incrementar ventas 15% en el año | L9: =IF(J9="","",SUMIFS('Registro por hora'!$H$5:$H$2004,'Registro por hora'!$F$5:$F$2004,J9,'Registro por hora'!$A$5:$A$2004,">="&$B$4,'Registro por hora'!$A$5:$A$2004,"<="&$B$5)) -> 5 | M9: =IF(OR(J9="",SUM($L$9:$L$58)=0),"",L9/SUM($L$9:$L$58)) -> 0.625
A10: =IF(Personal!B6="","",Personal!B6) -> Carlos Ruiz | B10: =IF($A10="","",COUNTIFS(Asistencia!$B$5:$B$504,$A10,Asistencia!$A$5:$A$504,">="&$B$4,Asistencia!$A$5:$A$504,"<="&$B$5)-COUNTIFS(Asistencia!$B$5:$B$504,$A10,Asistencia!$D$5:$D$504,"Ausente",Asistencia!$A$5:$A$504,">="&$B$4,Asistencia!$A$5:$A$504,"<="&$B$5)) -> 0 | C10: =IF($A10="","",COUNTIFS(Asistencia!$B$5:$B$504,$A10,Asistencia!$D$5:$D$504,"Ausente",Asistencia!$A$5:$A$504,">="&$B$4,Asistencia!$A$5:$A$504,"<="&$B$5)) -> 1 | D10: =IF($A10="","",COUNTIFS(Asistencia!$B$5:$B$504,$A10,Asistencia!$D$5:$D$504,"Ausente",Asistencia!$I$5:$I$504,"",Asistencia!$A$5:$A$504,">="&$B$4,Asistencia!$A$5:$A$504,"<="&$B$5)) -> 0 | E10: =IF($A10="","",SUMIFS(Asistencia!$H$5:$H$504,Asistencia!$B$5:$B$504,$A10,Asistencia!$A$5:$A$504,">="&$B$4,Asistencia!$A$5:$A$504,"<="&$B$5)) -> 0 | F10: =IF($A10="","",SUMIFS('Registro por hora'!$H$5:$H$2004,'Registro por hora'!$B$5:$B$2004,$A10,'Registro por hora'!$A$5:$A$2004,">="&$B$4,'Registro por hora'!$A$5:$A$2004,"<="&$B$5)) -> 0 | G10: =IF(OR($A10="",N(E10)=0),"",F10/E10) | H10: =IF(OR($A10="",N(B10)=0),"",E10/B10) | J10: =IF(Metas!A6="","",Metas!A6) -> M2 | K10: =IF(Metas!A6="","",Metas!B6) -> Mejorar satisfacción del cliente | L10: =IF(J10="","",SUMIFS('Registro por hora'!$H$5:$H$2004,'Registro por hora'!$F$5:$F$2004,J10,'Registro por hora'!$A$5:$A$2004,">="&$B$4,'Registro por hora'!$A$5:$A$2004,"<="&$B$5)) -> 1 | M10: =IF(OR(J10="",SUM($L$9:$L$58)=0),"",L10/SUM($L$9:$L$58)) -> 0.125
A11: =IF(Personal!B7="","",Personal!B7) -> María Hernández | B11: =IF($A11="","",COUNTIFS(Asistencia!$B$5:$B$504,$A11,Asistencia!$A$5:$A$504,">="&$B$4,Asistencia!$A$5:$A$504,"<="&$B$5)-COUNTIFS(Asistencia!$B$5:$B$504,$A11,Asistencia!$D$5:$D$504,"Ausente",Asistencia!$A$5:$A$504,">="&$B$4,Asistencia!$A$5:$A$504,"<="&$B$5)) -> 0 | C11: =IF($A11="","",COUNTIFS(Asistencia!$B$5:$B$504,$A11,Asistencia!$D$5:$D$504,"Ausente",Asistencia!$A$5:$A$504,">="&$B$4,Asistencia!$A$5:$A$504,"<="&$B$5)) -> 0 | D11: =IF($A11="","",COUNTIFS(Asistencia!$B$5:$B$504,$A11,Asistencia!$D$5:$D$504,"Ausente",Asistencia!$I$5:$I$504,"",Asistencia!$A$5:$A$504,">="&$B$4,Asistencia!$A$5:$A$504,"<="&$B$5)) -> 0 | E11: =IF($A11="","",SUMIFS(Asistencia!$H$5:$H$504,Asistencia!$B$5:$B$504,$A11,Asistencia!$A$5:$A$504,">="&$B$4,Asistencia!$A$5:$A$504,"<="&$B$5)) -> 0 | F11: =IF($A11="","",SUMIFS('Registro por hora'!$H$5:$H$2004,'Registro por hora'!$B$5:$B$2004,$A11,'Registro por hora'!$A$5:$A$2004,">="&$B$4,'Registro por hora'!$A$5:$A$2004,"<="&$B$5)) -> 0 | G11: =IF(OR($A11="",N(E11)=0),"",F11/E11) | H11: =IF(OR($A11="",N(B11)=0),"",E11/B11) | J11: =IF(Metas!A7="","",Metas!A7) -> M3 | K11: =IF(Metas!A7="","",Metas!B7) -> Lanzar nuevo producto / servicio | L11: =IF(J11="","",SUMIFS('Registro por hora'!$H$5:$H$2004,'Registro por hora'!$F$5:$F$2004,J11,'Registro por hora'!$A$5:$A$2004,">="&$B$4,'Registro por hora'!$A$5:$A$2004,"<="&$B$5)) -> 0 | M11: =IF(OR(J11="",SUM($L$9:$L$58)=0),"",L11/SUM($L$9:$L$58)) -> 0
A12: =IF(Personal!B8="","",Personal!B8) | B12: =IF($A12="","",COUNTIFS(Asistencia!$B$5:$B$504,$A12,Asistencia!$A$5:$A$504,">="&$B$4,Asistencia!$A$5:$A$504,"<="&$B$5)-COUNTIFS(Asistencia!$B$5:$B$504,$A12,Asistencia!$D$5:$D$504,"Ausente",Asistencia!$A$5:$A$504,">="&$B$4,Asistencia!$A$5:$A$504,"<="&$B$5)) | C12: =IF($A12="","",COUNTIFS(Asistencia!$B$5:$B$504,$A12,Asistencia!$D$5:$D$504,"Ausente",Asistencia!$A$5:$A$504,">="&$B$4,Asistencia!$A$5:$A$504,"<="&$B$5)) | D12: =IF($A12="","",COUNTIFS(Asistencia!$B$5:$B$504,$A12,Asistencia!$D$5:$D$504,"Ausente",Asistencia!$I$5:$I$504,"",Asistencia!$A$5:$A$504,">="&$B$4,Asistencia!$A$5:$A$504,"<="&$B$5)) | E12: =IF($A12="","",SUMIFS(Asistencia!$H$5:$H$504,Asistencia!$B$5:$B$504,$A12,Asistencia!$A$5:$A$504,">="&$B$4,Asistencia!$A$5:$A$504,"<="&$B$5)) | F12: =IF($A12="","",SUMIFS('Registro por hora'!$H$5:$H$2004,'Registro por hora'!$B$5:$B$2004,$A12,'Registro por hora'!$A$5:$A$2004,">="&$B$4,'Registro por hora'!$A$5:$A$2004,"<="&$B$5)) | G12: =IF(OR($A12="",N(E12)=0),"",F12/E12) | H12: =IF(OR($A12="",N(B12)=0),"",E12/B12) | J12: =IF(Metas!A8="","",Metas!A8) -> M4 | K12: =IF(Metas!A8="","",Metas!B8) -> Optimizar procesos internos | L12: =IF(J12="","",SUMIFS('Registro por hora'!$H$5:$H$2004,'Registro por hora'!$F$5:$F$2004,J12,'Registro por hora'!$A$5:$A$2004,">="&$B$4,'Registro por hora'!$A$5:$A$2004,"<="&$B$5)) -> 0 | M12: =IF(OR(J12="",SUM($L$9:$L$58)=0),"",L12/SUM($L$9:$L$58)) -> 0
A13: =IF(Personal!B9="","",Personal!B9) | B13: =IF($A13="","",COUNTIFS(Asistencia!$B$5:$B$504,$A13,Asistencia!$A$5:$A$504,">="&$B$4,Asistencia!$A$5:$A$504,"<="&$B$5)-COUNTIFS(Asistencia!$B$5:$B$504,$A13,Asistencia!$D$5:$D$504,"Ausente",Asistencia!$A$5:$A$504,">="&$B$4,Asistencia!$A$5:$A$504,"<="&$B$5)) | C13: =IF($A13="","",COUNTIFS(Asistencia!$B$5:$B$504,$A13,Asistencia!$D$5:$D$504,"Ausente",Asistencia!$A$5:$A$504,">="&$B$4,Asistencia!$A$5:$A$504,"<="&$B$5)) | D13: =IF($A13="","",COUNTIFS(Asistencia!$B$5:$B$504,$A13,Asistencia!$D$5:$D$504,"Ausente",Asistencia!$I$5:$I$504,"",Asistencia!$A$5:$A$504,">="&$B$4,Asistencia!$A$5:$A$504,"<="&$B$5)) | E13: =IF($A13="","",SUMIFS(Asistencia!$H$5:$H$504,Asistencia!$B$5:$B$504,$A13,Asistencia!$A$5:$A$504,">="&$B$4,Asistencia!$A$5:$A$504,"<="&$B$5)) | F13: =IF($A13="","",SUMIFS('Registro por hora'!$H$5:$H$2004,'Registro por hora'!$B$5:$B$2004,$A13,'Registro por hora'!$A$5:$A$2004,">="&$B$4,'Registro por hora'!$A$5:$A$2004,"<="&$B$5)) | G13: =IF(OR($A13="",N(E13)=0),"",F13/E13) | H13: =IF(OR($A13="",N(B13)=0),"",E13/B13) | J13: =IF(Metas!A9="","",Metas!A9) -> M5 | K13: =IF(Metas!A9="","",Metas!B9) -> Capacitación y desarrollo del equipo | L13: =IF(J13="","",SUMIFS('Registro por hora'!$H$5:$H$2004,'Registro por hora'!$F$5:$F$2004,J13,'Registro por hora'!$A$5:$A$2004,">="&$B$4,'Registro por hora'!$A$5:$A$2004,"<="&$B$5)) -> 1 | M13: =IF(OR(J13="",SUM($L$9:$L$58)=0),"",L13/SUM($L$9:$L$58)) -> 0.125
A14: =IF(Personal!B10="","",Personal!B10) | B14: =IF($A14="","",COUNTIFS(Asistencia!$B$5:$B$504,$A14,Asistencia!$A$5:$A$504,">="&$B$4,Asistencia!$A$5:$A$504,"<="&$B$5)-COUNTIFS(Asistencia!$B$5:$B$504,$A14,Asistencia!$D$5:$D$504,"Ausente",Asistencia!$A$5:$A$504,">="&$B$4,Asistencia!$A$5:$A$504,"<="&$B$5)) | C14: =IF($A14="","",COUNTIFS(Asistencia!$B$5:$B$504,$A14,Asistencia!$D$5:$D$504,"Ausente",Asistencia!$A$5:$A$504,">="&$B$4,Asistencia!$A$5:$A$504,"<="&$B$5)) | D14: =IF($A14="","",COUNTIFS(Asistencia!$B$5:$B$504,$A14,Asistencia!$D$5:$D$504,"Ausente",Asistencia!$I$5:$I$504,"",Asistencia!$A$5:$A$504,">="&$B$4,Asistencia!$A$5:$A$504,"<="&$B$5)) | E14: =IF($A14="","",SUMIFS(Asistencia!$H$5:$H$504,Asistencia!$B$5:$B$504,$A14,Asistencia!$A$5:$A$504,">="&$B$4,Asistencia!$A$5:$A$504,"<="&$B$5)) | F14: =IF($A14="","",SUMIFS('Registro por hora'!$H$5:$H$2004,'Registro por hora'!$B$5:$B$2004,$A14,'Registro por hora'!$A$5:$A$2004,">="&$B$4,'Registro por hora'!$A$5:$A$2004,"<="&$B$5)) | G14: =IF(OR($A14="",N(E14)=0),"",F14/E14) | H14: =IF(OR($A14="",N(B14)=0),"",E14/B14) | J14: =IF(Metas!A10="","",Metas!A10) -> M0 | K14: =IF(Metas!A10="","",Metas!B10) -> Administrativo / soporte general | L14: =IF(J14="","",SUMIFS('Registro por hora'!$H$5:$H$2004,'Registro por hora'!$F$5:$F$2004,J14,'Registro por hora'!$A$5:$A$2004,">="&$B$4,'Registro por hora'!$A$5:$A$2004,"<="&$B$5)) -> 1 | M14: =IF(OR(J14="",SUM($L$9:$L$58)=0),"",L14/SUM($L$9:$L$58)) -> 0.125
A15: =IF(Personal!B11="","",Personal!B11) | B15: =IF($A15="","",COUNTIFS(Asistencia!$B$5:$B$504,$A15,Asistencia!$A$5:$A$504,">="&$B$4,Asistencia!$A$5:$A$504,"<="&$B$5)-COUNTIFS(Asistencia!$B$5:$B$504,$A15,Asistencia!$D$5:$D$504,"Ausente",Asistencia!$A$5:$A$504,">="&$B$4,Asistencia!$A$5:$A$504,"<="&$B$5)) | C15: =IF($A15="","",COUNTIFS(Asistencia!$B$5:$B$504,$A15,Asistencia!$D$5:$D$504,"Ausente",Asistencia!$A$5:$A$504,">="&$B$4,Asistencia!$A$5:$A$504,"<="&$B$5)) | D15: =IF($A15="","",COUNTIFS(Asistencia!$B$5:$B$504,$A15,Asistencia!$D$5:$D$504,"Ausente",Asistencia!$I$5:$I$504,"",Asistencia!$A$5:$A$504,">="&$B$4,Asistencia!$A$5:$A$504,"<="&$B$5)) | E15: =IF($A15="","",SUMIFS(Asistencia!$H$5:$H$504,Asistencia!$B$5:$B$504,$A15,Asistencia!$A$5:$A$504,">="&$B$4,Asistencia!$A$5:$A$504,"<="&$B$5)) | F15: =IF($A15="","",SUMIFS('Registro por hora'!$H$5:$H$2004,'Registro por hora'!$B$5:$B$2004,$A15,'Registro por hora'!$A$5:$A$2004,">="&$B$4,'Registro por hora'!$A$5:$A$2004,"<="&$B$5)) | G15: =IF(OR($A15="",N(E15)=0),"",F15/E15) | H15: =IF(OR($A15="",N(B15)=0),"",E15/B15) | J15: =IF(Metas!A11="","",Metas!A11) | K15: =IF(Metas!A11="","",Metas!B11) | L15: =IF(J15="","",SUMIFS('Registro por hora'!$H$5:$H$2004,'Registro por hora'!$F$5:$F$2004,J15,'Registro por hora'!$A$5:$A$2004,">="&$B$4,'Registro por hora'!$A$5:$A$2004,"<="&$B$5)) | M15: =IF(OR(J15="",SUM($L$9:$L$58)=0),"",L15/SUM($L$9:$L$58))
A16: =IF(Personal!B12="","",Personal!B12) | B16: =IF($A16="","",COUNTIFS(Asistencia!$B$5:$B$504,$A16,Asistencia!$A$5:$A$504,">="&$B$4,Asistencia!$A$5:$A$504,"<="&$B$5)-COUNTIFS(Asistencia!$B$5:$B$504,$A16,Asistencia!$D$5:$D$504,"Ausente",Asistencia!$A$5:$A$504,">="&$B$4,Asistencia!$A$5:$A$504,"<="&$B$5)) | C16: =IF($A16="","",COUNTIFS(Asistencia!$B$5:$B$504,$A16,Asistencia!$D$5:$D$504,"Ausente",Asistencia!$A$5:$A$504,">="&$B$4,Asistencia!$A$5:$A$504,"<="&$B$5)) | D16: =IF($A16="","",COUNTIFS(Asistencia!$B$5:$B$504,$A16,Asistencia!$D$5:$D$504,"Ausente",Asistencia!$I$5:$I$504,"",Asistencia!$A$5:$A$504,">="&$B$4,Asistencia!$A$5:$A$504,"<="&$B$5)) | E16: =IF($A16="","",SUMIFS(Asistencia!$H$5:$H$504,Asistencia!$B$5:$B$504,$A16,Asistencia!$A$5:$A$504,">="&$B$4,Asistencia!$A$5:$A$504,"<="&$B$5)) | F16: =IF($A16="","",SUMIFS('Registro por hora'!$H$5:$H$2004,'Registro por hora'!$B$5:$B$2004,$A16,'Registro por hora'!$A$5:$A$2004,">="&$B$4,'Registro por hora'!$A$5:$A$2004,"<="&$B$5)) | G16: =IF(OR($A16="",N(E16)=0),"",F16/E16) | H16: =IF(OR($A16="",N(B16)=0),"",E16/B16) | J16: =IF(Metas!A12="","",Metas!A12) | K16: =IF(Metas!A12="","",Metas!B12) | L16: =IF(J16="","",SUMIFS('Registro por hora'!$H$5:$H$2004,'Registro por hora'!$F$5:$F$2004,J16,'Registro por hora'!$A$5:$A$2004,">="&$B$4,'Registro por hora'!$A$5:$A$2004,"<="&$B$5)) | M16: =IF(OR(J16="",SUM($L$9:$L$58)=0),"",L16/SUM($L$9:$L$58))
A17: =IF(Personal!B13="","",Personal!B13) | B17: =IF($A17="","",COUNTIFS(Asistencia!$B$5:$B$504,$A17,Asistencia!$A$5:$A$504,">="&$B$4,Asistencia!$A$5:$A$504,"<="&$B$5)-COUNTIFS(Asistencia!$B$5:$B$504,$A17,Asistencia!$D$5:$D$504,"Ausente",Asistencia!$A$5:$A$504,">="&$B$4,Asistencia!$A$5:$A$504,"<="&$B$5)) | C17: =IF($A17="","",COUNTIFS(Asistencia!$B$5:$B$504,$A17,Asistencia!$D$5:$D$504,"Ausente",Asistencia!$A$5:$A$504,">="&$B$4,Asistencia!$A$5:$A$504,"<="&$B$5)) | D17: =IF($A17="","",COUNTIFS(Asistencia!$B$5:$B$504,$A17,Asistencia!$D$5:$D$504,"Ausente",Asistencia!$I$5:$I$504,"",Asistencia!$A$5:$A$504,">="&$B$4,Asistencia!$A$5:$A$504,"<="&$B$5)) | E17: =IF($A17="","",SUMIFS(Asistencia!$H$5:$H$504,Asistencia!$B$5:$B$504,$A17,Asistencia!$A$5:$A$504,">="&$B$4,Asistencia!$A$5:$A$504,"<="&$B$5)) | F17: =IF($A17="","",SUMIFS('Registro por hora'!$H$5:$H$2004,'Registro por hora'!$B$5:$B$2004,$A17,'Registro por hora'!$A$5:$A$2004,">="&$B$4,'Registro por hora'!$A$5:$A$2004,"<="&$B$5)) | G17: =IF(OR($A17="",N(E17)=0),"",F17/E17) | H17: =IF(OR($A17="",N(B17)=0),"",E17/B17) | J17: =IF(Metas!A13="","",Metas!A13) | K17: =IF(Metas!A13="","",Metas!B13) | L17: =IF(J17="","",SUMIFS('Registro por hora'!$H$5:$H$2004,'Registro por hora'!$F$5:$F$2004,J17,'Registro por hora'!$A$5:$A$2004,">="&$B$4,'Registro por hora'!$A$5:$A$2004,"<="&$B$5)) | M17: =IF(OR(J17="",SUM($L$9:$L$58)=0),"",L17/SUM($L$9:$L$58))
A18: =IF(Personal!B14="","",Personal!B14) | B18: =IF($A18="","",COUNTIFS(Asistencia!$B$5:$B$504,$A18,Asistencia!$A$5:$A$504,">="&$B$4,Asistencia!$A$5:$A$504,"<="&$B$5)-COUNTIFS(Asistencia!$B$5:$B$504,$A18,Asistencia!$D$5:$D$504,"Ausente",Asistencia!$A$5:$A$504,">="&$B$4,Asistencia!$A$5:$A$504,"<="&$B$5)) | C18: =IF($A18="","",COUNTIFS(Asistencia!$B$5:$B$504,$A18,Asistencia!$D$5:$D$504,"Ausente",Asistencia!$A$5:$A$504,">="&$B$4,Asistencia!$A$5:$A$504,"<="&$B$5)) | D18: =IF($A18="","",COUNTIFS(Asistencia!$B$5:$B$504,$A18,Asistencia!$D$5:$D$504,"Ausente",Asistencia!$I$5:$I$504,"",Asistencia!$A$5:$A$504,">="&$B$4,Asistencia!$A$5:$A$504,"<="&$B$5)) | E18: =IF($A18="","",SUMIFS(Asistencia!$H$5:$H$504,Asistencia!$B$5:$B$504,$A18,Asistencia!$A$5:$A$504,">="&$B$4,Asistencia!$A$5:$A$504,"<="&$B$5)) | F18: =IF($A18="","",SUMIFS('Registro por hora'!$H$5:$H$2004,'Registro por hora'!$B$5:$B$2004,$A18,'Registro por hora'!$A$5:$A$2004,">="&$B$4,'Registro por hora'!$A$5:$A$2004,"<="&$B$5)) | G18: =IF(OR($A18="",N(E18)=0),"",F18/E18) | H18: =IF(OR($A18="",N(B18)=0),"",E18/B18) | J18: =IF(Metas!A14="","",Metas!A14) | K18: =IF(Metas!A14="","",Metas!B14) | L18: =IF(J18="","",SUMIFS('Registro por hora'!$H$5:$H$2004,'Registro por hora'!$F$5:$F$2004,J18,'Registro por hora'!$A$5:$A$2004,">="&$B$4,'Registro por hora'!$A$5:$A$2004,"<="&$B$5)) | M18: =IF(OR(J18="",SUM($L$9:$L$58)=0),"",L18/SUM($L$9:$L$58))
A19: =IF(Personal!B15="","",Personal!B15) | B19: =IF($A19="","",COUNTIFS(Asistencia!$B$5:$B$504,$A19,Asistencia!$A$5:$A$504,">="&$B$4,Asistencia!$A$5:$A$504,"<="&$B$5)-COUNTIFS(Asistencia!$B$5:$B$504,$A19,Asistencia!$D$5:$D$504,"Ausente",Asistencia!$A$5:$A$504,">="&$B$4,Asistencia!$A$5:$A$504,"<="&$B$5)) | C19: =IF($A19="","",COUNTIFS(Asistencia!$B$5:$B$504,$A19,Asistencia!$D$5:$D$504,"Ausente",Asistencia!$A$5:$A$504,">="&$B$4,Asistencia!$A$5:$A$504,"<="&$B$5)) | D19: =IF($A19="","",COUNTIFS(Asistencia!$B$5:$B$504,$A19,Asistencia!$D$5:$D$504,"Ausente",Asistencia!$I$5:$I$504,"",Asistencia!$A$5:$A$504,">="&$B$4,Asistencia!$A$5:$A$504,"<="&$B$5)) | E19: =IF($A19="","",SUMIFS(Asistencia!$H$5:$H$504,Asistencia!$B$5:$B$504,$A19,Asistencia!$A$5:$A$504,">="&$B$4,Asistencia!$A$5:$A$504,"<="&$B$5)) | F19: =IF($A19="","",SUMIFS('Registro por hora'!$H$5:$H$2004,'Registro por hora'!$B$5:$B$2004,$A19,'Registro por hora'!$A$5:$A$2004,">="&$B$4,'Registro por hora'!$A$5:$A$2004,"<="&$B$5)) | G19: =IF(OR($A19="",N(E19)=0),"",F19/E19) | H19: =IF(OR($A19="",N(B19)=0),"",E19/B19) | J19: =IF(Metas!A15="","",Metas!A15) | K19: =IF(Metas!A15="","",Metas!B15) | L19: =IF(J19="","",SUMIFS('Registro por hora'!$H$5:$H$2004,'Registro por hora'!$F$5:$F$2004,J19,'Registro por hora'!$A$5:$A$2004,">="&$B$4,'Registro por hora'!$A$5:$A$2004,"<="&$B$5)) | M19: =IF(OR(J19="",SUM($L$9:$L$58)=0),"",L19/SUM($L$9:$L$58))
A20: =IF(Personal!B16="","",Personal!B16) | B20: =IF($A20="","",COUNTIFS(Asistencia!$B$5:$B$504,$A20,Asistencia!$A$5:$A$504,">="&$B$4,Asistencia!$A$5:$A$504,"<="&$B$5)-COUNTIFS(Asistencia!$B$5:$B$504,$A20,Asistencia!$D$5:$D$504,"Ausente",Asistencia!$A$5:$A$504,">="&$B$4,Asistencia!$A$5:$A$504,"<="&$B$5)) | C20: =IF($A20="","",COUNTIFS(Asistencia!$B$5:$B$504,$A20,Asistencia!$D$5:$D$504,"Ausente",Asistencia!$A$5:$A$504,">="&$B$4,Asistencia!$A$5:$A$504,"<="&$B$5)) | D20: =IF($A20="","",COUNTIFS(Asistencia!$B$5:$B$504,$A20,Asistencia!$D$5:$D$504,"Ausente",Asistencia!$I$5:$I$504,"",Asistencia!$A$5:$A$504,">="&$B$4,Asistencia!$A$5:$A$504,"<="&$B$5)) | E20: =IF($A20="","",SUMIFS(Asistencia!$H$5:$H$504,Asistencia!$B$5:$B$504,$A20,Asistencia!$A$5:$A$504,">="&$B$4,Asistencia!$A$5:$A$504,"<="&$B$5)) | F20: =IF($A20="","",SUMIFS('Registro por hora'!$H$5:$H$2004,'Registro por hora'!$B$5:$B$2004,$A20,'Registro por hora'!$A$5:$A$2004,">="&$B$4,'Registro por hora'!$A$5:$A$2004,"<="&$B$5)) | G20: =IF(OR($A20="",N(E20)=0),"",F20/E20) | H20: =IF(OR($A20="",N(B20)=0),"",E20/B20) | J20: =IF(Metas!A16="","",Metas!A16) | K20: =IF(Metas!A16="","",Metas!B16) | L20: =IF(J20="","",SUMIFS('Registro por hora'!$H$5:$H$2004,'Registro por hora'!$F$5:$F$2004,J20,'Registro por hora'!$A$5:$A$2004,">="&$B$4,'Registro por hora'!$A$5:$A$2004,"<="&$B$5)) | M20: =IF(OR(J20="",SUM($L$9:$L$58)=0),"",L20/SUM($L$9:$L$58))
... A58: =IF(Personal!B54="","",Personal!B54) | B58: =IF($A58="","",COUNTIFS(Asistencia!$B$5:$B$504,$A58,Asistencia!$A$5:$A$504,">="&$B$4,Asistencia!$A$5:$A$504,"<="&$B$5)-COUNTIFS(Asistencia!$B$5:$B$504,$A58,Asistencia!$D$5:$D$504,"Ausente",Asistencia!$A$5:$A$504,">="&$B$4,Asistencia!$A$5:$A$504,"<="&$B$5)) | C58: =IF($A58="","",COUNTIFS(Asistencia!$B$5:$B$504,$A58,Asistencia!$D$5:$D$504,"Ausente",Asistencia!$A$5:$A$504,">="&$B$4,Asistencia!$A$5:$A$504,"<="&$B$5)) | D58: =IF($A58="","",COUNTIFS(Asistencia!$B$5:$B$504,$A58,Asistencia!$D$5:$D$504,"Ausente",Asistencia!$I$5:$I$504,"",Asistencia!$A$5:$A$504,">="&$B$4,Asistencia!$A$5:$A$504,"<="&$B$5)) | E58: =IF($A58="","",SUMIFS(Asistencia!$H$5:$H$504,Asistencia!$B$5:$B$504,$A58,Asistencia!$A$5:$A$504,">="&$B$4,Asistencia!$A$5:$A$504,"<="&$B$5)) | F58: =IF($A58="","",SUMIFS('Registro por hora'!$H$5:$H$2004,'Registro por hora'!$B$5:$B$2004,$A58,'Registro por hora'!$A$5:$A$2004,">="&$B$4,'Registro por hora'!$A$5:$A$2004,"<="&$B$5)) | G58: =IF(OR($A58="",N(E58)=0),"",F58/E58) | H58: =IF(OR($A58="",N(B58)=0),"",E58/B58) | J58: =IF(Metas!A54="","",Metas!A54) | K58: =IF(Metas!A54="","",Metas!B54) | L58: =IF(J58="","",SUMIFS('Registro por hora'!$H$5:$H$2004,'Registro por hora'!$F$5:$F$2004,J58,'Registro por hora'!$A$5:$A$2004,">="&$B$4,'Registro por hora'!$A$5:$A$2004,"<="&$B$5)) | M58: =IF(OR(J58="",SUM($L$9:$L$58)=0),"",L58/SUM($L$9:$L$58))
A59: =IF(Personal!B55="","",Personal!B55) | B59: =IF($A59="","",COUNTIFS(Asistencia!$B$5:$B$504,$A59,Asistencia!$A$5:$A$504,">="&$B$4,Asistencia!$A$5:$A$504,"<="&$B$5)-COUNTIFS(Asistencia!$B$5:$B$504,$A59,Asistencia!$D$5:$D$504,"Ausente",Asistencia!$A$5:$A$504,">="&$B$4,Asistencia!$A$5:$A$504,"<="&$B$5)) | C59: =IF($A59="","",COUNTIFS(Asistencia!$B$5:$B$504,$A59,Asistencia!$D$5:$D$504,"Ausente",Asistencia!$A$5:$A$504,">="&$B$4,Asistencia!$A$5:$A$504,"<="&$B$5)) | D59: =IF($A59="","",COUNTIFS(Asistencia!$B$5:$B$504,$A59,Asistencia!$D$5:$D$504,"Ausente",Asistencia!$I$5:$I$504,"",Asistencia!$A$5:$A$504,">="&$B$4,Asistencia!$A$5:$A$504,"<="&$B$5)) | E59: =IF($A59="","",SUMIFS(Asistencia!$H$5:$H$504,Asistencia!$B$5:$B$504,$A59,Asistencia!$A$5:$A$504,">="&$B$4,Asistencia!$A$5:$A$504,"<="&$B$5)) | F59: =IF($A59="","",SUMIFS('Registro por hora'!$H$5:$H$2004,'Registro por hora'!$B$5:$B$2004,$A59,'Registro por hora'!$A$5:$A$2004,">="&$B$4,'Registro por hora'!$A$5:$A$2004,"<="&$B$5)) | G59: =IF(OR($A59="",N(E59)=0),"",F59/E59) | H59: =IF(OR($A59="",N(B59)=0),"",E59/B59)
A60: =IF(Personal!B56="","",Personal!B56) | B60: =IF($A60="","",COUNTIFS(Asistencia!$B$5:$B$504,$A60,Asistencia!$A$5:$A$504,">="&$B$4,Asistencia!$A$5:$A$504,"<="&$B$5)-COUNTIFS(Asistencia!$B$5:$B$504,$A60,Asistencia!$D$5:$D$504,"Ausente",Asistencia!$A$5:$A$504,">="&$B$4,Asistencia!$A$5:$A$504,"<="&$B$5)) | C60: =IF($A60="","",COUNTIFS(Asistencia!$B$5:$B$504,$A60,Asistencia!$D$5:$D$504,"Ausente",Asistencia!$A$5:$A$504,">="&$B$4,Asistencia!$A$5:$A$504,"<="&$B$5)) | D60: =IF($A60="","",COUNTIFS(Asistencia!$B$5:$B$504,$A60,Asistencia!$D$5:$D$504,"Ausente",Asistencia!$I$5:$I$504,"",Asistencia!$A$5:$A$504,">="&$B$4,Asistencia!$A$5:$A$504,"<="&$B$5)) | E60: =IF($A60="","",SUMIFS(Asistencia!$H$5:$H$504,Asistencia!$B$5:$B$504,$A60,Asistencia!$A$5:$A$504,">="&$B$4,Asistencia!$A$5:$A$504,"<="&$B$5)) | F60: =IF($A60="","",SUMIFS('Registro por hora'!$H$5:$H$2004,'Registro por hora'!$B$5:$B$2004,$A60,'Registro por hora'!$A$5:$A$2004,">="&$B$4,'Registro por hora'!$A$5:$A$2004,"<="&$B$5)) | G60: =IF(OR($A60="",N(E60)=0),"",F60/E60) | H60: =IF(OR($A60="",N(B60)=0),"",E60/B60) | J60: Sin meta asignada | L60: =SUMIFS('Registro por hora'!$H$5:$H$2004,'Registro por hora'!$F$5:$F$2004,"",'Registro por hora'!$A$5:$A$2004,">="&$B$4,'Registro por hora'!$A$5:$A$2004,"<="&$B$5) -> 0
A61: =IF(Personal!B57="","",Personal!B57) | B61: =IF($A61="","",COUNTIFS(Asistencia!$B$5:$B$504,$A61,Asistencia!$A$5:$A$504,">="&$B$4,Asistencia!$A$5:$A$504,"<="&$B$5)-COUNTIFS(Asistencia!$B$5:$B$504,$A61,Asistencia!$D$5:$D$504,"Ausente",Asistencia!$A$5:$A$504,">="&$B$4,Asistencia!$A$5:$A$504,"<="&$B$5)) | C61: =IF($A61="","",COUNTIFS(Asistencia!$B$5:$B$504,$A61,Asistencia!$D$5:$D$504,"Ausente",Asistencia!$A$5:$A$504,">="&$B$4,Asistencia!$A$5:$A$504,"<="&$B$5)) | D61: =IF($A61="","",COUNTIFS(Asistencia!$B$5:$B$504,$A61,Asistencia!$D$5:$D$504,"Ausente",Asistencia!$I$5:$I$504,"",Asistencia!$A$5:$A$504,">="&$B$4,Asistencia!$A$5:$A$504,"<="&$B$5)) | E61: =IF($A61="","",SUMIFS(Asistencia!$H$5:$H$504,Asistencia!$B$5:$B$504,$A61,Asistencia!$A$5:$A$504,">="&$B$4,Asistencia!$A$5:$A$504,"<="&$B$5)) | F61: =IF($A61="","",SUMIFS('Registro por hora'!$H$5:$H$2004,'Registro por hora'!$B$5:$B$2004,$A61,'Registro por hora'!$A$5:$A$2004,">="&$B$4,'Registro por hora'!$A$5:$A$2004,"<="&$B$5)) | G61: =IF(OR($A61="",N(E61)=0),"",F61/E61) | H61: =IF(OR($A61="",N(B61)=0),"",E61/B61)
A62: =IF(Personal!B58="","",Personal!B58) | B62: =IF($A62="","",COUNTIFS(Asistencia!$B$5:$B$504,$A62,Asistencia!$A$5:$A$504,">="&$B$4,Asistencia!$A$5:$A$504,"<="&$B$5)-COUNTIFS(Asistencia!$B$5:$B$504,$A62,Asistencia!$D$5:$D$504,"Ausente",Asistencia!$A$5:$A$504,">="&$B$4,Asistencia!$A$5:$A$504,"<="&$B$5)) | C62: =IF($A62="","",COUNTIFS(Asistencia!$B$5:$B$504,$A62,Asistencia!$D$5:$D$504,"Ausente",Asistencia!$A$5:$A$504,">="&$B$4,Asistencia!$A$5:$A$504,"<="&$B$5)) | D62: =IF($A62="","",COUNTIFS(Asistencia!$B$5:$B$504,$A62,Asistencia!$D$5:$D$504,"Ausente",Asistencia!$I$5:$I$504,"",Asistencia!$A$5:$A$504,">="&$B$4,Asistencia!$A$5:$A$504,"<="&$B$5)) | E62: =IF($A62="","",SUMIFS(Asistencia!$H$5:$H$504,Asistencia!$B$5:$B$504,$A62,Asistencia!$A$5:$A$504,">="&$B$4,Asistencia!$A$5:$A$504,"<="&$B$5)) | F62: =IF($A62="","",SUMIFS('Registro por hora'!$H$5:$H$2004,'Registro por hora'!$B$5:$B$2004,$A62,'Registro por hora'!$A$5:$A$2004,">="&$B$4,'Registro por hora'!$A$5:$A$2004,"<="&$B$5)) | G62: =IF(OR($A62="",N(E62)=0),"",F62/E62) | H62: =IF(OR($A62="",N(B62)=0),"",E62/B62)
A63: =IF(Personal!B59="","",Personal!B59) | B63: =IF($A63="","",COUNTIFS(Asistencia!$B$5:$B$504,$A63,Asistencia!$A$5:$A$504,">="&$B$4,Asistencia!$A$5:$A$504,"<="&$B$5)-COUNTIFS(Asistencia!$B$5:$B$504,$A63,Asistencia!$D$5:$D$504,"Ausente",Asistencia!$A$5:$A$504,">="&$B$4,Asistencia!$A$5:$A$504,"<="&$B$5)) | C63: =IF($A63="","",COUNTIFS(Asistencia!$B$5:$B$504,$A63,Asistencia!$D$5:$D$504,"Ausente",Asistencia!$A$5:$A$504,">="&$B$4,Asistencia!$A$5:$A$504,"<="&$B$5)) | D63: =IF($A63="","",COUNTIFS(Asistencia!$B$5:$B$504,$A63,Asistencia!$D$5:$D$504,"Ausente",Asistencia!$I$5:$I$504,"",Asistencia!$A$5:$A$504,">="&$B$4,Asistencia!$A$5:$A$504,"<="&$B$5)) | E63: =IF($A63="","",SUMIFS(Asistencia!$H$5:$H$504,Asistencia!$B$5:$B$504,$A63,Asistencia!$A$5:$A$504,">="&$B$4,Asistencia!$A$5:$A$504,"<="&$B$5)) | F63: =IF($A63="","",SUMIFS('Registro por hora'!$H$5:$H$2004,'Registro por hora'!$B$5:$B$2004,$A63,'Registro por hora'!$A$5:$A$2004,">="&$B$4,'Registro por hora'!$A$5:$A$2004,"<="&$B$5)) | G63: =IF(OR($A63="",N(E63)=0),"",F63/E63) | H63: =IF(OR($A63="",N(B63)=0),"",E63/B63)
A64: =IF(Personal!B60="","",Personal!B60) | B64: =IF($A64="","",COUNTIFS(Asistencia!$B$5:$B$504,$A64,Asistencia!$A$5:$A$504,">="&$B$4,Asistencia!$A$5:$A$504,"<="&$B$5)-COUNTIFS(Asistencia!$B$5:$B$504,$A64,Asistencia!$D$5:$D$504,"Ausente",Asistencia!$A$5:$A$504,">="&$B$4,Asistencia!$A$5:$A$504,"<="&$B$5)) | C64: =IF($A64="","",COUNTIFS(Asistencia!$B$5:$B$504,$A64,Asistencia!$D$5:$D$504,"Ausente",Asistencia!$A$5:$A$504,">="&$B$4,Asistencia!$A$5:$A$504,"<="&$B$5)) | D64: =IF($A64="","",COUNTIFS(Asistencia!$B$5:$B$504,$A64,Asistencia!$D$5:$D$504,"Ausente",Asistencia!$I$5:$I$504,"",Asistencia!$A$5:$A$504,">="&$B$4,Asistencia!$A$5:$A$504,"<="&$B$5)) | E64: =IF($A64="","",SUMIFS(Asistencia!$H$5:$H$504,Asistencia!$B$5:$B$504,$A64,Asistencia!$A$5:$A$504,">="&$B$4,Asistencia!$A$5:$A$504,"<="&$B$5)) | F64: =IF($A64="","",SUMIFS('Registro por hora'!$H$5:$H$2004,'Registro por hora'!$B$5:$B$2004,$A64,'Registro por hora'!$A$5:$A$2004,">="&$B$4,'Registro por hora'!$A$5:$A$2004,"<="&$B$5)) | G64: =IF(OR($A64="",N(E64)=0),"",F64/E64) | H64: =IF(OR($A64="",N(B64)=0),"",E64/B64)
A65: =IF(Personal!B61="","",Personal!B61) | B65: =IF($A65="","",COUNTIFS(Asistencia!$B$5:$B$504,$A65,Asistencia!$A$5:$A$504,">="&$B$4,Asistencia!$A$5:$A$504,"<="&$B$5)-COUNTIFS(Asistencia!$B$5:$B$504,$A65,Asistencia!$D$5:$D$504,"Ausente",Asistencia!$A$5:$A$504,">="&$B$4,Asistencia!$A$5:$A$504,"<="&$B$5)) | C65: =IF($A65="","",COUNTIFS(Asistencia!$B$5:$B$504,$A65,Asistencia!$D$5:$D$504,"Ausente",Asistencia!$A$5:$A$504,">="&$B$4,Asistencia!$A$5:$A$504,"<="&$B$5)) | D65: =IF($A65="","",COUNTIFS(Asistencia!$B$5:$B$504,$A65,Asistencia!$D$5:$D$504,"Ausente",Asistencia!$I$5:$I$504,"",Asistencia!$A$5:$A$504,">="&$B$4,Asistencia!$A$5:$A$504,"<="&$B$5)) | E65: =IF($A65="","",SUMIFS(Asistencia!$H$5:$H$504,Asistencia!$B$5:$B$504,$A65,Asistencia!$A$5:$A$504,">="&$B$4,Asistencia!$A$5:$A$504,"<="&$B$5)) | F65: =IF($A65="","",SUMIFS('Registro por hora'!$H$5:$H$2004,'Registro por hora'!$B$5:$B$2004,$A65,'Registro por hora'!$A$5:$A$2004,">="&$B$4,'Registro por hora'!$A$5:$A$2004,"<="&$B$5)) | G65: =IF(OR($A65="",N(E65)=0),"",F65/E65) | H65: =IF(OR($A65="",N(B65)=0),"",E65/B65)
A66: =IF(Personal!B62="","",Personal!B62) | B66: =IF($A66="","",COUNTIFS(Asistencia!$B$5:$B$504,$A66,Asistencia!$A$5:$A$504,">="&$B$4,Asistencia!$A$5:$A$504,"<="&$B$5)-COUNTIFS(Asistencia!$B$5:$B$504,$A66,Asistencia!$D$5:$D$504,"Ausente",Asistencia!$A$5:$A$504,">="&$B$4,Asistencia!$A$5:$A$504,"<="&$B$5)) | C66: =IF($A66="","",COUNTIFS(Asistencia!$B$5:$B$504,$A66,Asistencia!$D$5:$D$504,"Ausente",Asistencia!$A$5:$A$504,">="&$B$4,Asistencia!$A$5:$A$504,"<="&$B$5)) | D66: =IF($A66="","",COUNTIFS(Asistencia!$B$5:$B$504,$A66,Asistencia!$D$5:$D$504,"Ausente",Asistencia!$I$5:$I$504,"",Asistencia!$A$5:$A$504,">="&$B$4,Asistencia!$A$5:$A$504,"<="&$B$5)) | E66: =IF($A66="","",SUMIFS(Asistencia!$H$5:$H$504,Asistencia!$B$5:$B$504,$A66,Asistencia!$A$5:$A$504,">="&$B$4,Asistencia!$A$5:$A$504,"<="&$B$5)) | F66: =IF($A66="","",SUMIFS('Registro por hora'!$H$5:$H$2004,'Registro por hora'!$B$5:$B$2004,$A66,'Registro por hora'!$A$5:$A$2004,">="&$B$4,'Registro por hora'!$A$5:$A$2004,"<="&$B$5)) | G66: =IF(OR($A66="",N(E66)=0),"",F66/E66) | H66: =IF(OR($A66="",N(B66)=0),"",E66/B66)
A67: =IF(Personal!B63="","",Personal!B63) | B67: =IF($A67="","",COUNTIFS(Asistencia!$B$5:$B$504,$A67,Asistencia!$A$5:$A$504,">="&$B$4,Asistencia!$A$5:$A$504,"<="&$B$5)-COUNTIFS(Asistencia!$B$5:$B$504,$A67,Asistencia!$D$5:$D$504,"Ausente",Asistencia!$A$5:$A$504,">="&$B$4,Asistencia!$A$5:$A$504,"<="&$B$5)) | C67: =IF($A67="","",COUNTIFS(Asistencia!$B$5:$B$504,$A67,Asistencia!$D$5:$D$504,"Ausente",Asistencia!$A$5:$A$504,">="&$B$4,Asistencia!$A$5:$A$504,"<="&$B$5)) | D67: =IF($A67="","",COUNTIFS(Asistencia!$B$5:$B$504,$A67,Asistencia!$D$5:$D$504,"Ausente",Asistencia!$I$5:$I$504,"",Asistencia!$A$5:$A$504,">="&$B$4,Asistencia!$A$5:$A$504,"<="&$B$5)) | E67: =IF($A67="","",SUMIFS(Asistencia!$H$5:$H$504,Asistencia!$B$5:$B$504,$A67,Asistencia!$A$5:$A$504,">="&$B$4,Asistencia!$A$5:$A$504,"<="&$B$5)) | F67: =IF($A67="","",SUMIFS('Registro por hora'!$H$5:$H$2004,'Registro por hora'!$B$5:$B$2004,$A67,'Registro por hora'!$A$5:$A$2004,">="&$B$4,'Registro por hora'!$A$5:$A$2004,"<="&$B$5)) | G67: =IF(OR($A67="",N(E67)=0),"",F67/E67) | H67: =IF(OR($A67="",N(B67)=0),"",E67/B67)
A68: =IF(Personal!B64="","",Personal!B64) | B68: =IF($A68="","",COUNTIFS(Asistencia!$B$5:$B$504,$A68,Asistencia!$A$5:$A$504,">="&$B$4,Asistencia!$A$5:$A$504,"<="&$B$5)-COUNTIFS(Asistencia!$B$5:$B$504,$A68,Asistencia!$D$5:$D$504,"Ausente",Asistencia!$A$5:$A$504,">="&$B$4,Asistencia!$A$5:$A$504,"<="&$B$5)) | C68: =IF($A68="","",COUNTIFS(Asistencia!$B$5:$B$504,$A68,Asistencia!$D$5:$D$504,"Ausente",Asistencia!$A$5:$A$504,">="&$B$4,Asistencia!$A$5:$A$504,"<="&$B$5)) | D68: =IF($A68="","",COUNTIFS(Asistencia!$B$5:$B$504,$A68,Asistencia!$D$5:$D$504,"Ausente",Asistencia!$I$5:$I$504,"",Asistencia!$A$5:$A$504,">="&$B$4,Asistencia!$A$5:$A$504,"<="&$B$5)) | E68: =IF($A68="","",SUMIFS(Asistencia!$H$5:$H$504,Asistencia!$B$5:$B$504,$A68,Asistencia!$A$5:$A$504,">="&$B$4,Asistencia!$A$5:$A$504,"<="&$B$5)) | F68: =IF($A68="","",SUMIFS('Registro por hora'!$H$5:$H$2004,'Registro por hora'!$B$5:$B$2004,$A68,'Registro por hora'!$A$5:$A$2004,">="&$B$4,'Registro por hora'!$A$5:$A$2004,"<="&$B$5)) | G68: =IF(OR($A68="",N(E68)=0),"",F68/E68) | H68: =IF(OR($A68="",N(B68)=0),"",E68/B68)
A69: =IF(Personal!B65="","",Personal!B65) | B69: =IF($A69="","",COUNTIFS(Asistencia!$B$5:$B$504,$A69,Asistencia!$A$5:$A$504,">="&$B$4,Asistencia!$A$5:$A$504,"<="&$B$5)-COUNTIFS(Asistencia!$B$5:$B$504,$A69,Asistencia!$D$5:$D$504,"Ausente",Asistencia!$A$5:$A$504,">="&$B$4,Asistencia!$A$5:$A$504,"<="&$B$5)) | C69: =IF($A69="","",COUNTIFS(Asistencia!$B$5:$B$504,$A69,Asistencia!$D$5:$D$504,"Ausente",Asistencia!$A$5:$A$504,">="&$B$4,Asistencia!$A$5:$A$504,"<="&$B$5)) | D69: =IF($A69="","",COUNTIFS(Asistencia!$B$5:$B$504,$A69,Asistencia!$D$5:$D$504,"Ausente",Asistencia!$I$5:$I$504,"",Asistencia!$A$5:$A$504,">="&$B$4,Asistencia!$A$5:$A$504,"<="&$B$5)) | E69: =IF($A69="","",SUMIFS(Asistencia!$H$5:$H$504,Asistencia!$B$5:$B$504,$A69,Asistencia!$A$5:$A$504,">="&$B$4,Asistencia!$A$5:$A$504,"<="&$B$5)) | F69: =IF($A69="","",SUMIFS('Registro por hora'!$H$5:$H$2004,'Registro por hora'!$B$5:$B$2004,$A69,'Registro por hora'!$A$5:$A$2004,">="&$B$4,'Registro por hora'!$A$5:$A$2004,"<="&$B$5)) | G69: =IF(OR($A69="",N(E69)=0),"",F69/E69) | H69: =IF(OR($A69="",N(B69)=0),"",E69/B69)
A70: =IF(Personal!B66="","",Personal!B66) | B70: =IF($A70="","",COUNTIFS(Asistencia!$B$5:$B$504,$A70,Asistencia!$A$5:$A$504,">="&$B$4,Asistencia!$A$5:$A$504,"<="&$B$5)-COUNTIFS(Asistencia!$B$5:$B$504,$A70,Asistencia!$D$5:$D$504,"Ausente",Asistencia!$A$5:$A$504,">="&$B$4,Asistencia!$A$5:$A$504,"<="&$B$5)) | C70: =IF($A70="","",COUNTIFS(Asistencia!$B$5:$B$504,$A70,Asistencia!$D$5:$D$504,"Ausente",Asistencia!$A$5:$A$504,">="&$B$4,Asistencia!$A$5:$A$504,"<="&$B$5)) | D70: =IF($A70="","",COUNTIFS(Asistencia!$B$5:$B$504,$A70,Asistencia!$D$5:$D$504,"Ausente",Asistencia!$I$5:$I$504,"",Asistencia!$A$5:$A$504,">="&$B$4,Asistencia!$A$5:$A$504,"<="&$B$5)) | E70: =IF($A70="","",SUMIFS(Asistencia!$H$5:$H$504,Asistencia!$B$5:$B$504,$A70,Asistencia!$A$5:$A$504,">="&$B$4,Asistencia!$A$5:$A$504,"<="&$B$5)) | F70: =IF($A70="","",SUMIFS('Registro por hora'!$H$5:$H$2004,'Registro por hora'!$B$5:$B$2004,$A70,'Registro por hora'!$A$5:$A$2004,">="&$B$4,'Registro por hora'!$A$5:$A$2004,"<="&$B$5)) | G70: =IF(OR($A70="",N(E70)=0),"",F70/E70) | H70: =IF(OR($A70="",N(B70)=0),"",E70/B70)
A71: =IF(Personal!B67="","",Personal!B67) | B71: =IF($A71="","",COUNTIFS(Asistencia!$B$5:$B$504,$A71,Asistencia!$A$5:$A$504,">="&$B$4,Asistencia!$A$5:$A$504,"<="&$B$5)-COUNTIFS(Asistencia!$B$5:$B$504,$A71,Asistencia!$D$5:$D$504,"Ausente",Asistencia!$A$5:$A$504,">="&$B$4,Asistencia!$A$5:$A$504,"<="&$B$5)) | C71: =IF($A71="","",COUNTIFS(Asistencia!$B$5:$B$504,$A71,Asistencia!$D$5:$D$504,"Ausente",Asistencia!$A$5:$A$504,">="&$B$4,Asistencia!$A$5:$A$504,"<="&$B$5)) | D71: =IF($A71="","",COUNTIFS(Asistencia!$B$5:$B$504,$A71,Asistencia!$D$5:$D$504,"Ausente",Asistencia!$I$5:$I$504,"",Asistencia!$A$5:$A$504,">="&$B$4,Asistencia!$A$5:$A$504,"<="&$B$5)) | E71: =IF($A71="","",SUMIFS(Asistencia!$H$5:$H$504,Asistencia!$B$5:$B$504,$A71,Asistencia!$A$5:$A$504,">="&$B$4,Asistencia!$A$5:$A$504,"<="&$B$5)) | F71: =IF($A71="","",SUMIFS('Registro por hora'!$H$5:$H$2004,'Registro por hora'!$B$5:$B$2004,$A71,'Registro por hora'!$A$5:$A$2004,">="&$B$4,'Registro por hora'!$A$5:$A$2004,"<="&$B$5)) | G71: =IF(OR($A71="",N(E71)=0),"",F71/E71) | H71: =IF(OR($A71="",N(B71)=0),"",E71/B71)
A72: =IF(Personal!B68="","",Personal!B68) | B72: =IF($A72="","",COUNTIFS(Asistencia!$B$5:$B$504,$A72,Asistencia!$A$5:$A$504,">="&$B$4,Asistencia!$A$5:$A$504,"<="&$B$5)-COUNTIFS(Asistencia!$B$5:$B$504,$A72,Asistencia!$D$5:$D$504,"Ausente",Asistencia!$A$5:$A$504,">="&$B$4,Asistencia!$A$5:$A$504,"<="&$B$5)) | C72: =IF($A72="","",COUNTIFS(Asistencia!$B$5:$B$504,$A72,Asistencia!$D$5:$D$504,"Ausente",Asistencia!$A$5:$A$504,">="&$B$4,Asistencia!$A$5:$A$504,"<="&$B$5)) | D72: =IF($A72="","",COUNTIFS(Asistencia!$B$5:$B$504,$A72,Asistencia!$D$5:$D$504,"Ausente",Asistencia!$I$5:$I$504,"",Asistencia!$A$5:$A$504,">="&$B$4,Asistencia!$A$5:$A$504,"<="&$B$5)) | E72: =IF($A72="","",SUMIFS(Asistencia!$H$5:$H$504,Asistencia!$B$5:$B$504,$A72,Asistencia!$A$5:$A$504,">="&$B$4,Asistencia!$A$5:$A$504,"<="&$B$5)) | F72: =IF($A72="","",SUMIFS('Registro por hora'!$H$5:$H$2004,'Registro por hora'!$B$5:$B$2004,$A72,'Registro por hora'!$A$5:$A$2004,">="&$B$4,'Registro por hora'!$A$5:$A$2004,"<="&$B$5)) | G72: =IF(OR($A72="",N(E72)=0),"",F72/E72) | H72: =IF(OR($A72="",N(B72)=0),"",E72/B72)
... A108: =IF(Personal!B104="","",Personal!B104) | B108: =IF($A108="","",COUNTIFS(Asistencia!$B$5:$B$504,$A108,Asistencia!$A$5:$A$504,">="&$B$4,Asistencia!$A$5:$A$504,"<="&$B$5)-COUNTIFS(Asistencia!$B$5:$B$504,$A108,Asistencia!$D$5:$D$504,"Ausente",Asistencia!$A$5:$A$504,">="&$B$4,Asistencia!$A$5:$A$504,"<="&$B$5)) | C108: =IF($A108="","",COUNTIFS(Asistencia!$B$5:$B$504,$A108,Asistencia!$D$5:$D$504,"Ausente",Asistencia!$A$5:$A$504,">="&$B$4,Asistencia!$A$5:$A$504,"<="&$B$5)) | D108: =IF($A108="","",COUNTIFS(Asistencia!$B$5:$B$504,$A108,Asistencia!$D$5:$D$504,"Ausente",Asistencia!$I$5:$I$504,"",Asistencia!$A$5:$A$504,">="&$B$4,Asistencia!$A$5:$A$504,"<="&$B$5)) | E108: =IF($A108="","",SUMIFS(Asistencia!$H$5:$H$504,Asistencia!$B$5:$B$504,$A108,Asistencia!$A$5:$A$504,">="&$B$4,Asistencia!$A$5:$A$504,"<="&$B$5)) | F108: =IF($A108="","",SUMIFS('Registro por hora'!$H$5:$H$2004,'Registro por hora'!$B$5:$B$2004,$A108,'Registro por hora'!$A$5:$A$2004,">="&$B$4,'Registro por hora'!$A$5:$A$2004,"<="&$B$5)) | G108: =IF(OR($A108="",N(E108)=0),"",F108/E108) | H108: =IF(OR($A108="",N(B108)=0),"",E108/B108)

Sheet Catálogos
A1: Catálogos
A2: Listas que alimentan los menús desplegables. Puedes agregar opciones al final de cada lista.
